Workbook
Name ENE: NOVIEMBRE!$A$3
Name ENE: MAYO!$A$3
Name ENE: DICIEMBRE!$A$3
Name ENE: JUNIO!$A$3
Name ENE: SETIEMBRE!$A$3
Name MAR: #REF!
Name ENE: FEBRERO!$A$3
Name ENE: AGOSTO!$A$3
Name JUL: #REF!
Name FormPublisherTimestamp1644iBvh7dgShC41NDWj1Nu8ry_S21pGmBtmB1ZHD8: #REF!
Name ENE: OCTUBRE!$A$3
Name FEB: #REF!
Name ENE: ENERO!$A$3
Name MAY: #REF!
Name ENE: JULIO!$A$3
Name ABR: #REF!
Name JUN: #REF!
Name ENE: MARZO!$A$3
Name ENE: ABRIL!$A$3

Sheet ENERO
A1: SERVICIO RELACIONADO | C1: TIQUETS POR CANAL | L1: TIPO | O1: ROL USUARIO | AB1: PRIORIDAD
A3: =IF((B51+K51+N51+AA51+AF51)/5=B51,"Todo Bien :D","Algo esta Mal :c") -> Todo Bien :D | B3: Cantidad x Servicio | C3: Chat | D3: Correo | E3: Formulario Web | F3: Facebook | G3: Memorandum | H3: Presencial | I3: Teléfono | J3: Twitter | K3: TOTAL | L3: Solicitud | M3: Incidente | N3: TOTAL | O3: Estudiante | P3: Estudiante FundaTEC | Q3: Estudiante Colegio Científico | R3: Profesor | S3: Profesor FundaTEC | T3: Profesor Colegio Científico | U3: Administrativo | V3: Administrativo FundaTEC | W3: Director/Coordinador | X3: Director/Coordinador FundaTEC | Y3: Director/Coordinador Colegio Ciencífico | Z3: Externo | AA3: TOTAL | AB3: Normal | AC3: Baja | AD3: Alta | AE3: Urgente | AF3: TOTAL | AG3: TOTALES
A4: Acceso a la plataforma TEC Digital | B4: 303 | C4: 1 | D4: 283 | E4: 0 | F4: 0 | G4: 0 | H4: 0 | I4: 19 | J4: 0 | K4: =SUM(C4:J4) -> 303 | L4: 88 | M4: 215 | N4: =SUM(L4:M4) -> 303 | O4: 240 | P4: 12 | Q4: 0 | R4: 32 | S4: 1 | T4: 0 | U4: 11 | V4: 5 | W4: 2 | X4: 0 | Y4: 0 | Z4: 0 | AA4: =SUM(O4:Z4) -> 303 | AB4: 116 | AC4: 4 | AD4: 133 | AE4: 47 | AF4: =SUM(AB4:AE4) -> 300 | AG4: =IF((B4+K4+N4+AA4+AF4)/5=B4,"Todo Bien :D","Algo esta Mal :c") -> Algo esta Mal :c | AI4: Faltan 3 tickets en prioridad
A5: Acreditación | B5: 0 | C5: 0 | D5: 0 | E5: 0 | F5: 0 | G5: 0 | H5: 0 | I5: 0 | J5: 0 | K5: =SUM(C5:J5) -> 0 | L5: 0 | M5: 0 | N5: =SUM(L5:M5) -> 0 | O5: 0 | P5: 0 | Q5: 0 | R5: 0 | S5: 0 | T5: 0 | U5: 0 | V5: 0 | W5: 0 | X5: 0 | Y5: 0 | Z5: 0 | AA5: =SUM(O5:Z5) -> 0 | AB5: 0 | AC5: 0 | AD5: 0 | AE5: 0 | AF5: =SUM(AB5:AE5) -> 0 | AG5: =IF((B5+K5+N5+AA5+AF5)/5=B5,"Todo Bien :D","Algo esta Mal :c") -> Todo Bien :D
A6: Activar cuentas de usuario | B6: 22 | C6: 5 | D6: 10 | E6: 0 | F6: 0 | G6: 0 | H6: 0 | I6: 7 | J6: 0 | K6: =SUM(C6:J6) -> 22 | L6: 0 | M6: 22 | N6: =SUM(L6:M6) -> 22 | O6: 1 | P6: 0 | Q6: 0 | R6: 3 | S6: 0 | T6: 0 | U6: 16 | V6: 0 | W6: 2 | X6: 0 | Y6: 0 | Z6: 0 | AA6: =SUM(O6:Z6) -> 22 | AB6: 19 | AC6: 0 | AD6: 2 | AE6: 1 | AF6: =SUM(AB6:AE6) -> 22 | AG6: =IF((B6+K6+N6+AA6+AF6)/5=B6,"Todo Bien :D","Algo esta Mal :c") -> Todo Bien :D
A7: Activar curso | B7: 3 | C7: 0 | D7: 3 | E7: 0 | F7: 0 | G7: 0 | H7: 0 | I7: 0 | J7: 0 | K7: =SUM(C7:J7) -> 3 | L7: 0 | M7: 3 | N7: =SUM(L7:M7) -> 3 | O7: 1 | P7: 0 | Q7: 0 | R7: 2 | S7: 0 | T7: 0 | U7: 0 | V7: 0 | W7: 0 | X7: 0 | Y7: 0 | Z7: 0 | AA7: =SUM(O7:Z7) -> 3 | AB7: 0 | AC7: 0 | AD7: 3 | AE7: 0 | AF7: =SUM(AB7:AE7) -> 3 | AG7: =IF((B7+K7+N7+AA7+AF7)/5=B7,"Todo Bien :D","Algo esta Mal :c") -> Todo Bien :D
A8: Actualizar cursos a estudiantes | B8: 7 | C8: 0 | D8: 7 | E8: 0 | F8: 0 | G8: 0 | H8: 0 | I8: 0 | J8: 0 | K8: =SUM(C8:J8) -> 7 | L8: 0 | M8: 7 | N8: =SUM(L8:M8) -> 7 | O8: 6 | P8: 0 | Q8: 0 | R8: 1 | S8: 0 | T8: 0 | U8: 0 | V8: 0 | W8: 0 | X8: 0 | Y8: 0 | Z8: 0 | AA8: =SUM(O8:Z8) -> 7 | AB8: 3 | AC8: 0 | AD8: 4 | AE8: 0 | AF8: =SUM(AB8:AE8) -> 7 | AG8: =IF((B8+K8+N8+AA8+AF8)/5=B8,"Todo Bien :D","Algo esta Mal :c") -> Todo Bien :D
A9: Actualizar miembros de comunidades | B9: 4 | C9: 0 | D9: 4 | E9: 0 | F9: 0 | G9: 0 | H9: 0 | I9: 0 | J9: 0 | K9: =SUM(C9:J9) -> 4 | L9: 4 | M9: 0 | N9: =SUM(L9:M9) -> 4 | O9: 2 | P9: 0 | Q9: 0 | R9: 0 | S9: 0 | T9: 0 | U9: 0 | V9: 0 | W9: 0 | X9: 0 | Y9: 0 | Z9: 2 | AA9: =SUM(O9:Z9) -> 4 | AB9: 2 | AC9: 0 | AD9: 2 | AE9: 0 | AF9: =SUM(AB9:AE9) -> 4 | AG9: =IF((B9+K9+N9+AA9+AF9)/5=B9,"Todo Bien :D","Algo esta Mal :c") -> Todo Bien :D
A10: Administrador de asistencia | B10: 0 | C10: 0 | D10: 0 | E10: 0 | F10: 0 | G10: 0 | H10: 0 | I10: 0 | J10: 0 | K10: =SUM(C10:J10) -> 0 | L10: 0 | M10: 0 | N10: =SUM(L10:M10) -> 0 | O10: 0 | P10: 0 | Q10: 0 | R10: 0 | S10: 0 | T10: 0 | U10: 0 | V10: 0 | W10: 0 | X10: 0 | Y10: 0 | Z10: 0 | AA10: =SUM(O10:Z10) -> 0 | AB10: 0 | AC10: 0 | AD10: 0 | AE10: 0 | AF10: =SUM(AB10:AE10) -> 0 | AG10: =IF((B10+K10+N10+AA10+AF10)/5=B10,"Todo Bien :D","Algo esta Mal :c") -> Todo Bien :D
A11: Administrador Programa de Curso | B11: 0 | C11: 0 | D11: 0 | E11: 0 | F11: 0 | G11: 0 | H11: 0 | I11: 0 | J11: 0 | K11: =SUM(C11:J11) -> 0 | L11: 0 | M11: 0 | N11: =SUM(L11:M11) -> 0 | O11: 0 | P11: 0 | Q11: 0 | R11: 0 | S11: 0 | T11: 0 | U11: 0 | V11: 0 | W11: 0 | X11: 0 | Y11: 0 | Z11: 0 | AA11: =SUM(O11:Z11) -> 0 | AB11: 0 | AC11: 0 | AD11: 0 | AE11: 0 | AF11: =SUM(AB11:AE11) -> 0 | AG11: =IF((B11+K11+N11+AA11+AF11)/5=B11,"Todo Bien :D","Algo esta Mal :c") -> Todo Bien :D
A12: Agregar/cambiar asociación de estudiante a curso | B12: 26 | C12: 0 | D12: 26 | E12: 0 | F12: 0 | G12: 0 | H12: 0 | I12: 0 | J12: 0 | K12: =SUM(C12:J12) -> 26 | L12: 0 | M12: 26 | N12: =SUM(L12:M12) -> 26 | O12: 19 | P12: 0 | Q12: 0 | R12: 1 | S12: 0 | T12: 0 | U12: 6 | V12: 0 | W12: 0 | X12: 0 | Y12: 0 | Z12: 0 | AA12: =SUM(O12:Z12) -> 26 | AB12: 7 | AC12: 0 | AD12: 14 | AE12: 5 | AF12: =SUM(AB12:AE12) -> 26 | AG12: =IF((B12+K12+N12+AA12+AF12)/5=B12,"Todo Bien :D","Algo esta Mal :c") -> Todo Bien :D
A13: Agregar/cambiar asociación de profesor a curso | B13: 20 | C13: 0 | D13: 20 | E13: 0 | F13: 0 | G13: 0 | H13: 0 | I13: 0 | J13: 0 | K13: =SUM(C13:J13) -> 20 | L13: 0 | M13: 20 | N13: =SUM(L13:M13) -> 20 | O13: 0 | P13: 0 | Q13: 0 | R13: 13 | S13: 1 | T13: 0 | U13: 3 | V13: 1 | W13: 2 | X13: 0 | Y13: 0 | Z13: 0 | AA13: =SUM(O13:Z13) -> 20 | AB13: 6 | AC13: 0 | AD13: 9 | AE13: 5 | AF13: =SUM(AB13:AE13) -> 20 | AG13: =IF((B13+K13+N13+AA13+AF13)/5=B13,"Todo Bien :D","Algo esta Mal :c") -> Todo Bien :D
A14: Agregar/cambiar asociación de usuario a comunidad | B14: 12 | C14: 2 | D14: 8 | E14: 0 | F14: 0 | G14: 0 | H14: 0 | I14: 2 | J14: 0 | K14: =SUM(C14:J14) -> 12 | L14: 0 | M14: 12 | N14: =SUM(L14:M14) -> 12 | O14: 2 | P14: 0 | Q14: 0 | R14: 6 | S14: 0 | T14: 0 | U14: 4 | V14: 0 | W14: 0 | X14: 0 | Y14: 0 | Z14: 0 | AA14: =SUM(O14:Z14) -> 12 | AB14: 9 | AC14: 0 | AD14: 3 | AE14: 0 | AF14: =SUM(AB14:AE14) -> 12 | AG14: =IF((B14+K14+N14+AA14+AF14)/5=B14,"Todo Bien :D","Algo esta Mal :c") -> Todo Bien :D
A15: Agregar/cambiar asociación estudiante a curso Colegio Científico | B15: 0 | C15: 0 | D15: 0 | E15: 0 | F15: 0 | G15: 0 | H15: 0 | I15: 0 | J15: 0 | K15: =SUM(C15:J15) -> 0 | L15: 0 | M15: 0 | N15: =SUM(L15:M15) -> 0 | O15: 0 | P15: 0 | Q15: 0 | R15: 0 | S15: 0 | T15: 0 | U15: 0 | V15: 0 | W15: 0 | X15: 0 | Y15: 0 | Z15: 0 | AA15: =SUM(O15:Z15) -> 0 | AB15: 0 | AC15: 0 | AD15: 0 | AE15: 0 | AF15: =SUM(AB15:AE15) -> 0 | AG15: =IF((B15+K15+N15+AA15+AF15)/5=B15,"Todo Bien :D","Algo esta Mal :c") -> Todo Bien :D
A16: Agregar/cambiar asociación estudiante a curso FundaTEC | B16: 2 | C16: 0 | D16: 2 | E16: 0 | F16: 0 | G16: 0 | H16: 0 | I16: 0 | J16: 0 | K16: =SUM(C16:J16) -> 2 | L16: 0 | M16: 2 | N16: =SUM(L16:M16) -> 2 | O16: 0 | P16: 2 | Q16: 0 | R16: 0 | S16: 0 | T16: 0 | U16: 0 | V16: 0 | W16: 0 | X16: 0 | Y16: 0 | Z16: 0 | AA16: =SUM(O16:Z16) -> 2 | AB16: 0 | AC16: 0 | AD16: 1 | AE16: 1 | AF16: =SUM(AB16:AE16) -> 2 | AG16: =IF((B16+K16+N16+AA16+AF16)/5=B16,"Todo Bien :D","Algo esta Mal :c") -> Todo Bien :D
... A32: Creación de comunidades | B32: 4 | C32: 0 | D32: 4 | E32: 0 | F32: 0 | G32: 0 | H32: 0 | I32: 0 | J32: 0 | K32: =SUM(C32:J32) -> 4 | L32: 0 | M32: 4 | N32: =SUM(L32:M32) -> 4 | O32: 0 | P32: 0 | Q32: 0 | R32: 4 | S32: 0 | T32: 0 | U32: 0 | V32: 0 | W32: 0 | X32: 0 | Y32: 0 | Z32: 0 | AA32: =SUM(O32:Z32) -> 4 | AB32: 0 | AC32: 0 | AD32: 2 | AE32: 2 | AF32: =SUM(AB32:AE32) -> 4 | AG32: =IF((B32+K32+N32+AA32+AF32)/5=B32,"Todo Bien :D","Algo esta Mal :c") -> Todo Bien :D
A33: Creación de curso | B33: 15 | C33: 0 | D33: 15 | E33: 0 | F33: 0 | G33: 0 | H33: 0 | I33: 0 | J33: 0 | K33: =SUM(C33:J33) -> 15 | L33: 0 | M33: 15 | N33: =SUM(L33:M33) -> 15 | O33: 0 | P33: 0 | Q33: 0 | R33: 1 | S33: 1 | T33: 0 | U33: 2 | V33: 10 | W33: 0 | X33: 1 | Y33: 0 | Z33: 0 | AA33: =SUM(O33:Z33) -> 15 | AB33: 9 | AC33: 0 | AD33: 2 | AE33: 3 | AF33: =SUM(AB33:AE33) -> 14 | AG33: =IF((B33+K33+N33+AA33+AF33)/5=B33,"Todo Bien :D","Algo esta Mal :c") -> Algo esta Mal :c | AI33: Falta 1 ticket en prioridad
A34: Creación de usuarios | B34: 19 | C34: 2 | D34: 17 | E34: 0 | F34: 0 | G34: 0 | H34: 0 | I34: 0 | J34: 0 | K34: =SUM(C34:J34) -> 19 | L34: 0 | M34: 19 | N34: =SUM(L34:M34) -> 19 | O34: 7 | P34: 1 | Q34: 0 | R34: 0 | S34: 0 | T34: 0 | U34: 6 | V34: 1 | W34: 2 | X34: 1 | Y34: 1 | Z34: 0 | AA34: =SUM(O34:Z34) -> 19 | AB34: 6 | AC34: 0 | AD34: 5 | AE34: 8 | AF34: =SUM(AB34:AE34) -> 19 | AG34: =IF((B34+K34+N34+AA34+AF34)/5=B34,"Todo Bien :D","Algo esta Mal :c") -> Todo Bien :D
A35: Creación de usuarios Colegio Científico | B35: 0 | C35: 0 | D35: 0 | E35: 0 | F35: 0 | G35: 0 | H35: 0 | I35: 0 | J35: 0 | K35: =SUM(C35:J35) -> 0 | L35: 0 | M35: 0 | N35: =SUM(L35:M35) -> 0 | O35: 0 | P35: 0 | Q35: 0 | R35: 0 | S35: 0 | T35: 0 | U35: 0 | V35: 0 | W35: 0 | X35: 0 | Y35: 0 | Z35: 0 | AA35: =SUM(O35:Z35) -> 0 | AB35: 0 | AC35: 0 | AD35: 0 | AE35: 0 | AF35: =SUM(AB35:AE35) -> 0 | AG35: =IF((B35+K35+N35+AA35+AF35)/5=B35,"Todo Bien :D","Algo esta Mal :c") -> Todo Bien :D
A36: Creación de usuarios FundaTEC | B36: 28 | C36: 0 | D36: 28 | E36: 0 | F36: 0 | G36: 0 | H36: 0 | I36: 0 | J36: 0 | K36: =SUM(C36:J36) -> 28 | L36: 0 | M36: 28 | N36: =SUM(L36:M36) -> 28 | O36: 0 | P36: 21 | Q36: 0 | R36: 1 | S36: 0 | T36: 0 | U36: 2 | V36: 4 | W36: 0 | X36: 0 | Y36: 0 | Z36: 0 | AA36: =SUM(O36:Z36) -> 28 | AB36: 4 | AC36: 0 | AD36: 10 | AE36: 14 | AF36: =SUM(AB36:AE36) -> 28 | AG36: =IF((B36+K36+N36+AA36+AF36)/5=B36,"Todo Bien :D","Algo esta Mal :c") -> Todo Bien :D
A37: Curso Móvil | B37: 0 | C37: 0 | D37: 0 | E37: 0 | F37: 0 | G37: 0 | H37: 0 | I37: 0 | J37: 0 | K37: =SUM(C37:J37) -> 0 | L37: 0 | M37: 0 | N37: =SUM(L37:M37) -> 0 | O37: 0 | P37: 0 | Q37: 0 | R37: 0 | S37: 0 | T37: 0 | U37: 0 | V37: 0 | W37: 0 | X37: 0 | Y37: 0 | Z37: 0 | AA37: =SUM(O37:Z37) -> 0 | AB37: 0 | AC37: 0 | AD37: 0 | AE37: 0 | AF37: =SUM(AB37:AE37) -> 0 | AG37: =IF((B37+K37+N37+AA37+AF37)/5=B37,"Todo Bien :D","Algo esta Mal :c") -> Todo Bien :D
A38: Dashboard | B38: 2 | C38: 0 | D38: 2 | E38: 0 | F38: 0 | G38: 0 | H38: 0 | I38: 0 | J38: 0 | K38: =SUM(C38:J38) -> 2 | L38: 0 | M38: 2 | N38: =SUM(L38:M38) -> 2 | O38: 1 | P38: 0 | Q38: 0 | R38: 0 | S38: 0 | T38: 0 | U38: 1 | V38: 0 | W38: 0 | X38: 0 | Y38: 0 | Z38: 0 | AA38: =SUM(O38:Z38) -> 2 | AB38: 0 | AC38: 0 | AD38: 2 | AE38: 0 | AF38: =SUM(AB38:AE38) -> 2 | AG38: =IF((B38+K38+N38+AA38+AF38)/5=B38,"Todo Bien :D","Algo esta Mal :c") -> Todo Bien :D
A39: Diagnósticos | B39: 9 | C39: 1 | D39: 8 | E39: 0 | F39: 0 | G39: 0 | H39: 0 | I39: 0 | J39: 0 | K39: =SUM(C39:J39) -> 9 | L39: 0 | M39: 9 | N39: =SUM(L39:M39) -> 9 | O39: 4 | P39: 0 | Q39: 0 | R39: 1 | S39: 0 | T39: 0 | U39: 1 | V39: 0 | W39: 0 | X39: 0 | Y39: 0 | Z39: 3 | AA39: =SUM(O39:Z39) -> 9 | AB39: 4 | AC39: 0 | AD39: 4 | AE39: 1 | AF39: =SUM(AB39:AE39) -> 9 | AG39: =IF((B39+K39+N39+AA39+AF39)/5=B39,"Todo Bien :D","Algo esta Mal :c") -> Todo Bien :D
A40: Diseño instruccional | B40: 0 | C40: 0 | D40: 0 | E40: 0 | F40: 0 | G40: 0 | H40: 0 | I40: 0 | J40: 0 | K40: =SUM(C40:J40) -> 0 | L40: 0 | M40: 0 | N40: =SUM(L40:M40) -> 0 | O40: 0 | P40: 0 | Q40: 0 | R40: 0 | S40: 0 | T40: 0 | U40: 0 | V40: 0 | W40: 0 | X40: 0 | Y40: 0 | Z40: 0 | AA40: =SUM(O40:Z40) -> 0 | AB40: 0 | AC40: 0 | AD40: 0 | AE40: 0 | AF40: =SUM(AB40:AE40) -> 0 | AG40: =IF((B40+K40+N40+AA40+AF40)/5=B40,"Todo Bien :D","Algo esta Mal :c") -> Todo Bien :D
A41: Envío de comunicados a comunidades | B41: 11 | C41: 1 | D41: 10 | E41: 0 | F41: 0 | G41: 0 | H41: 0 | I41: 0 | J41: 0 | K41: =SUM(C41:J41) -> 11 | L41: 0 | M41: 11 | N41: =SUM(L41:M41) -> 11 | O41: 3 | P41: 0 | Q41: 0 | R41: 2 | S41: 0 | T41: 0 | U41: 6 | V41: 0 | W41: 0 | X41: 0 | Y41: 0 | Z41: 0 | AA41: =SUM(O41:Z41) -> 11 | AB41: 9 | AC41: 0 | AD41: 1 | AE41: 1 | AF41: =SUM(AB41:AE41) -> 11 | AG41: =IF((B41+K41+N41+AA41+AF41)/5=B41,"Todo Bien :D","Algo esta Mal :c") -> Todo Bien :D
A42: Envío de comunicados a lista seleccionada | B42: 1 | C42: 0 | D42: 1 | E42: 0 | F42: 0 | G42: 0 | H42: 0 | I42: 0 | J42: 0 | K42: =SUM(C42:J42) -> 1 | L42: 0 | M42: 1 | N42: =SUM(L42:M42) -> 1 | O42: 1 | P42: 0 | Q42: 0 | R42: 0 | S42: 0 | T42: 0 | U42: 0 | V42: 0 | W42: 0 | X42: 0 | Y42: 0 | Z42: 0 | AA42: =SUM(O42:Z42) -> 1 | AB42: 1 | AC42: 0 | AD42: 0 | AE42: 0 | AF42: =SUM(AB42:AE42) -> 1 | AG42: =IF((B42+K42+N42+AA42+AF42)/5=B42,"Todo Bien :D","Algo esta Mal :c") -> Todo Bien :D
A43: Envío de comunicados mediante redes sociales | B43: 0 | C43: 0 | D43: 0 | E43: 0 | F43: 0 | G43: 0 | H43: 0 | I43: 0 | J43: 0 | K43: =SUM(C43:J43) -> 0 | L43: 0 | M43: 0 | N43: =SUM(L43:M43) -> 0 | O43: 0 | P43: 0 | Q43: 0 | R43: 0 | S43: 0 | T43: 0 | U43: 0 | V43: 0 | W43: 0 | X43: 0 | Y43: 0 | Z43: 0 | AA43: =SUM(O43:Z43) -> 0 | AB43: 0 | AC43: 0 | AD43: 0 | AE43: 0 | AF43: =SUM(AB43:AE43) -> 0 | AG43: =IF((B43+K43+N43+AA43+AF43)/5=B43,"Todo Bien :D","Algo esta Mal :c") -> Todo Bien :D
A44: Estadísticas de curso/comunidad | B44: 0 | C44: 0 | D44: 0 | E44: 0 | F44: 0 | G44: 0 | H44: 0 | I44: 0 | J44: 0 | K44: =SUM(C44:J44) -> 0 | L44: 0 | M44: 0 | N44: =SUM(L44:M44) -> 0 | O44: 0 | P44: 0 | Q44: 0 | R44: 0 | S44: 0 | T44: 0 | U44: 0 | V44: 0 | W44: 0 | X44: 0 | Y44: 0 | Z44: 0 | AA44: =SUM(O44:Z44) -> 0 | AB44: 0 | AC44: 0 | AD44: 0 | AE44: 0 | AF44: =SUM(AB44:AE44) -> 0 | AG44: =IF((B44+K44+N44+AA44+AF44)/5=B44,"Todo Bien :D","Algo esta Mal :c") -> Todo Bien :D
A45: Evaluaciones | B45: 5 | C45: 0 | D45: 4 | E45: 0 | F45: 0 | G45: 0 | H45: 0 | I45: 1 | J45: 0 | K45: =SUM(C45:J45) -> 5 | L45: 0 | M45: 5 | N45: =SUM(L45:M45) -> 5 | O45: 0 | P45: 0 | Q45: 0 | R45: 3 | S45: 1 | T45: 0 | U45: 0 | V45: 1 | W45: 0 | X45: 0 | Y45: 0 | Z45: 0 | AA45: =SUM(O45:Z45) -> 5 | AB45: 3 | AC45: 0 | AD45: 1 | AE45: 1 | AF45: =SUM(AB45:AE45) -> 5 | AG45: =IF((B45+K45+N45+AA45+AF45)/5=B45,"Todo Bien :D","Algo esta Mal :c") -> Todo Bien :D
... A65: Gestor de Consultas | B65: 3 | C65: 1 | D65: 2 | E65: 0 | F65: 0 | G65: 0 | H65: 0 | I65: 0 | J65: 0 | K65: =SUM(C65:J65) -> 3 | L65: 0 | M65: 3 | N65: =SUM(L65:M65) -> 3 | O65: 0 | P65: 0 | Q65: 0 | R65: 0 | S65: 0 | T65: 0 | U65: 2 | V65: 0 | W65: 1 | X65: 0 | Y65: 0 | Z65: 0 | AA65: =SUM(O65:Z65) -> 3 | AB65: 0 | AC65: 0 | AD65: 3 | AE65: 0 | AF65: =SUM(AB65:AE65) -> 3 | AG65: =IF((B65+K65+N65+AA65+AF65)/5=B65,"Todo Bien :D","Algo esta Mal :c") -> Todo Bien :D
A66: TOTAL | B66: =SUM(B4:B65) -> 674 | C66: =SUM(C3:C65) -> 23 | D66: =SUM(D3:D65) -> 614 | E66: =SUM(E4:E65) -> 0 | F66: =SUM(F3:F65) -> 0 | G66: =SUM(G3:G65) -> 0 | H66: =SUM(H3:H65) -> 1 | I66: =SUM(I3:I65) -> 36 | J66: =SUM(J3:J65) -> 0 | K66: =SUM(C66:J66) -> 674 | L66: =SUM(L3:L65) -> 95 | M66: =SUM(M3:M65) -> 579 | N66: =SUM(L66:M66) -> 674 | O66: =SUM(O3:O65) -> 353 | P66: =SUM(P3:P65) -> 49 | Q66: =SUM(Q3:Q65) -> 0 | R66: =SUM(R3:R65) -> 134 | S66: =SUM(S3:S65) -> 7 | T66: =SUM(T3:T65) -> 0 | U66: =SUM(U3:U65) -> 69 | V66: =SUM(V3:V65) -> 25 | ... Z66: =SUM(Z3:Z65) -> 17 | AA66: =SUM(O66:Z66) -> 674 | AB66: =SUM(AB3:AB65) -> 306 | AC66: =SUM(AC3:AC65) -> 6 | AD66: =SUM(AD3:AD65) -> 245 | AE66: =SUM(AE3:AE65) -> 113 | AF66: =SUM(AB66:AE66) -> 670 | AG66: =IF((B66+K66+N66+AA66+AF66)/5=B66,"Todo Bien :D","Algo esta Mal :c") -> Algo esta Mal :c

Sheet FEBRERO
A1: SERVICIO RELACIONADO | C1: TIQUETS POR CANAL | L1: TIPO | O1: ROL USUARIO | AB1: PRIORIDAD
A3: =IF((B51+K51+N51+AA51+AF51)/5=B51,"Todo Bien :D","Algo esta Mal :c") -> Todo Bien :D | B3: Cantidad x Servicio | C3: Chat | D3: Correo | E3: Formulario Web | F3: Facebook | G3: Memorandum | H3: Presencial | I3: Teléfono | J3: Twitter | K3: TOTAL | L3: Solicitud | M3: Incidente | N3: TOTAL | O3: Estudiante | P3: Estudiante FundaTEC | Q3: Estudiante Colegio Científico | R3: Profesor | S3: Profesor FundaTEC | T3: Profesor Colegio Científico | U3: Administrativo | V3: Administrativo FundaTEC | W3: Director/Coordinador | X3: Director/Coordinador FundaTEC | Y3: Director/Coordinador Colegio Ciencífico | Z3: Externo | AA3: TOTAL | AB3: Normal | AC3: Baja | AD3: Alta | AE3: Urgente | AF3: TOTAL | AG3: TOTALES
A4: Acceso a la plataforma TEC Digital | B4: 277 | C4: 3 | D4: 261 | E4: 0 | F4: 0 | G4: 0 | H4: 0 | I4: 13 | J4: 0 | K4: =SUM(C4:J4) -> 277 | L4: 244 | M4: 33 | N4: =SUM(L4:M4) -> 277 | O4: 207 | P4: 10 | Q4: 0 | R4: 34 | S4: 1 | T4: 1 | U4: 14 | V4: 1 | W4: 1 | X4: 0 | Y4: 2 | Z4: 6 | AA4: =SUM(O4:Z4) -> 277 | AB4: 222 | AC4: 2 | AD4: 48 | AE4: 5 | AF4: =SUM(AB4:AE4) -> 277 | AG4: =IF((B4+K4+N4+AA4+AF4)/5=B4,"Todo Bien :D","Algo esta Mal :c") -> Todo Bien :D
A5: Acreditación | B5: 0 | C5: 0 | D5: 0 | E5: 0 | F5: 0 | G5: 0 | H5: 0 | I5: 0 | J5: 0 | K5: =SUM(C5:J5) -> 0 | L5: 0 | M5: 0 | N5: =SUM(L5:M5) -> 0 | O5: 0 | P5: 0 | Q5: 0 | R5: 0 | S5: 0 | T5: 0 | U5: 0 | V5: 0 | W5: 0 | X5: 0 | Y5: 0 | Z5: 0 | AA5: =SUM(O5:Z5) -> 0 | AB5: 0 | AC5: 0 | AD5: 0 | AE5: 0 | AF5: =SUM(AB5:AE5) -> 0 | AG5: =IF((B5+K5+N5+AA5+AF5)/5=B5,"Todo Bien :D","Algo esta Mal :c") -> Todo Bien :D
A6: Activar cuentas de usuario | B6: 28 | C6: 3 | D6: 18 | E6: 0 | F6: 0 | G6: 0 | H6: 2 | I6: 5 | J6: 0 | K6: =SUM(C6:J6) -> 28 | L6: 28 | M6: 0 | N6: =SUM(L6:M6) -> 28 | O6: 11 | P6: 0 | Q6: 0 | R6: 6 | S6: 0 | T6: 0 | U6: 9 | V6: 0 | W6: 2 | X6: 0 | Y6: 0 | Z6: 0 | AA6: =SUM(O6:Z6) -> 28 | AB6: 18 | AC6: 0 | AD6: 6 | AE6: 4 | AF6: =SUM(AB6:AE6) -> 28 | AG6: =IF((B6+K6+N6+AA6+AF6)/5=B6,"Todo Bien :D","Algo esta Mal :c") -> Todo Bien :D
A7: Activar curso | B7: 37 | C7: 1 | D7: 36 | E7: 0 | F7: 0 | G7: 0 | H7: 0 | I7: 0 | J7: 0 | K7: =SUM(C7:J7) -> 37 | L7: 21 | M7: 16 | N7: =SUM(L7:M7) -> 37 | O7: 5 | P7: 0 | Q7: 0 | R7: 27 | S7: 0 | T7: 0 | U7: 3 | V7: 1 | W7: 1 | X7: 0 | Y7: 0 | Z7: 0 | AA7: =SUM(O7:Z7) -> 37 | AB7: 11 | AC7: 0 | AD7: 22 | AE7: 4 | AF7: =SUM(AB7:AE7) -> 37 | AG7: =IF((B7+K7+N7+AA7+AF7)/5=B7,"Todo Bien :D","Algo esta Mal :c") -> Todo Bien :D
A8: Actualizar cursos a estudiantes | B8: 16 | C8: 0 | D8: 15 | E8: 0 | F8: 0 | G8: 0 | H8: 0 | I8: 1 | J8: 0 | K8: =SUM(C8:J8) -> 16 | L8: 14 | M8: 2 | N8: =SUM(L8:M8) -> 16 | O8: 14 | P8: 0 | Q8: 0 | R8: 1 | S8: 0 | T8: 0 | U8: 1 | V8: 0 | W8: 0 | X8: 0 | Y8: 0 | Z8: 0 | AA8: =SUM(O8:Z8) -> 16 | AB8: 10 | AC8: 1 | AD8: 4 | AE8: 1 | AF8: =SUM(AB8:AE8) -> 16 | AG8: =IF((B8+K8+N8+AA8+AF8)/5=B8,"Todo Bien :D","Algo esta Mal :c") -> Todo Bien :D
A9: Actualizar miembros de comunidades | B9: 31 | C9: 1 | D9: 28 | E9: 0 | F9: 0 | G9: 0 | H9: 0 | I9: 2 | J9: 0 | K9: =SUM(C9:J9) -> 31 | L9: 30 | M9: 1 | N9: =SUM(L9:M9) -> 31 | O9: 2 | P9: 0 | Q9: 0 | R9: 29 | S9: 0 | T9: 0 | U9: 0 | V9: 0 | W9: 0 | X9: 0 | Y9: 0 | Z9: 0 | AA9: =SUM(O9:Z9) -> 31 | AB9: 19 | AC9: 0 | AD9: 10 | AE9: 2 | AF9: =SUM(AB9:AE9) -> 31 | AG9: =IF((B9+K9+N9+AA9+AF9)/5=B9,"Todo Bien :D","Algo esta Mal :c") -> Todo Bien :D
A10: Administrador de asistencia | B10: 0 | C10: 0 | D10: 0 | E10: 0 | F10: 0 | G10: 0 | H10: 0 | I10: 0 | J10: 0 | K10: =SUM(C10:J10) -> 0 | L10: 0 | M10: 0 | N10: =SUM(L10:M10) -> 0 | O10: 0 | P10: 0 | Q10: 0 | R10: 0 | S10: 0 | T10: 0 | U10: 0 | V10: 0 | W10: 0 | X10: 0 | Y10: 0 | Z10: 0 | AA10: =SUM(O10:Z10) -> 0 | AB10: 0 | AC10: 0 | AD10: 0 | AE10: 0 | AF10: =SUM(AB10:AE10) -> 0 | AG10: =IF((B10+K10+N10+AA10+AF10)/5=B10,"Todo Bien :D","Algo esta Mal :c") -> Todo Bien :D
A11: Administrador Programa de Curso | B11: 0 | C11: 0 | D11: 0 | E11: 0 | F11: 0 | G11: 0 | H11: 0 | I11: 0 | J11: 0 | K11: =SUM(C11:J11) -> 0 | L11: 0 | M11: 0 | N11: =SUM(L11:M11) -> 0 | O11: 0 | P11: 0 | Q11: 0 | R11: 0 | S11: 0 | T11: 0 | U11: 0 | V11: 0 | W11: 0 | X11: 0 | Y11: 0 | Z11: 0 | AA11: =SUM(O11:Z11) -> 0 | AB11: 0 | AC11: 0 | AD11: 0 | AE11: 0 | AF11: =SUM(AB11:AE11) -> 0 | AG11: =IF((B11+K11+N11+AA11+AF11)/5=B11,"Todo Bien :D","Algo esta Mal :c") -> Todo Bien :D
A12: Agregar/cambiar asociación de estudiante a curso | B12: 75 | C12: 4 | D12: 64 | E12: 0 | F12: 0 | G12: 0 | H12: 0 | I12: 7 | J12: 0 | K12: =SUM(C12:J12) -> 75 | L12: 73 | M12: 2 | N12: =SUM(L12:M12) -> 75 | O12: 45 | P12: 2 | Q12: 0 | R12: 21 | S12: 0 | T12: 0 | U12: 4 | V12: 1 | W12: 2 | X12: 0 | Y12: 0 | Z12: 0 | AA12: =SUM(O12:Z12) -> 75 | AB12: 67 | AC12: 0 | AD12: 8 | AE12: 0 | AF12: =SUM(AB12:AE12) -> 75 | AG12: =IF((B12+K12+N12+AA12+AF12)/5=B12,"Todo Bien :D","Algo esta Mal :c") -> Todo Bien :D
A13: Agregar/cambiar asociación de profesor a curso | B13: 82 | C13: 10 | D13: 67 | E13: 0 | F13: 0 | G13: 0 | H13: 1 | I13: 4 | J13: 0 | K13: =SUM(C13:J13) -> 82 | L13: 78 | M13: 4 | N13: =SUM(L13:M13) -> 82 | O13: 0 | P13: 0 | Q13: 0 | R13: 60 | S13: 1 | T13: 0 | U13: 13 | V13: 1 | W13: 7 | X13: 0 | Y13: 0 | Z13: 0 | AA13: =SUM(O13:Z13) -> 82 | AB13: 55 | AC13: 0 | AD13: 20 | AE13: 7 | AF13: =SUM(AB13:AE13) -> 82 | AG13: =IF((B13+K13+N13+AA13+AF13)/5=B13,"Todo Bien :D","Algo esta Mal :c") -> Todo Bien :D
A14: Agregar/cambiar asociación de usuario a comunidad | B14: 76 | C14: 3 | D14: 69 | E14: 0 | F14: 0 | G14: 0 | H14: 0 | I14: 4 | J14: 0 | K14: =SUM(C14:J14) -> 76 | L14: 75 | M14: 1 | N14: =SUM(L14:M14) -> 76 | O14: 40 | P14: 0 | Q14: 0 | R14: 28 | S14: 0 | T14: 0 | U14: 5 | V14: 0 | W14: 3 | X14: 0 | Y14: 0 | Z14: 0 | AA14: =SUM(O14:Z14) -> 76 | AB14: 67 | AC14: 0 | AD14: 7 | AE14: 2 | AF14: =SUM(AB14:AE14) -> 76 | AG14: =IF((B14+K14+N14+AA14+AF14)/5=B14,"Todo Bien :D","Algo esta Mal :c") -> Todo Bien :D
A15: Agregar/cambiar asociación estudiante a curso Colegio Científico | B15: 0 | C15: 0 | D15: 0 | E15: 0 | F15: 0 | G15: 0 | H15: 0 | I15: 0 | J15: 0 | K15: =SUM(C15:J15) -> 0 | L15: 0 | M15: 0 | N15: 0 | O15: 0 | P15: 0 | Q15: 0 | R15: 0 | S15: 0 | T15: 0 | U15: 0 | V15: 0 | W15: 0 | X15: 0 | Y15: 0 | Z15: 0 | AA15: =SUM(O15:Z15) -> 0 | AB15: 0 | AC15: 0 | AD15: 0 | AE15: 0 | AF15: =SUM(AB15:AE15) -> 0 | AG15: =IF((B15+K15+N15+AA15+AF15)/5=B15,"Todo Bien :D","Algo esta Mal :c") -> Todo Bien :D
A16: Agregar/cambiar asociación estudiante a curso FundaTEC | B16: 4 | C16: 0 | D16: 4 | E16: 0 | F16: 0 | G16: 0 | H16: 0 | I16: 0 | J16: 0 | K16: =SUM(C16:J16) -> 4 | L16: 3 | M16: 1 | N16: =SUM(L16:M16) -> 4 | O16: 0 | P16: 2 | Q16: 0 | R16: 1 | S16: 0 | T16: 0 | U16: 0 | V16: 1 | W16: 0 | X16: 0 | Y16: 0 | Z16: 0 | AA16: =SUM(O16:Z16) -> 4 | AB16: 3 | AC16: 0 | AD16: 0 | AE16: 1 | AF16: =SUM(AB16:AE16) -> 4 | AG16: =IF((B16+K16+N16+AA16+AF16)/5=B16,"Todo Bien :D","Algo esta Mal :c") -> Todo Bien :D
A17: Asignación de permisos especiales | B17: 9 | C17: 0 | D17: 9 | E17: 0 | F17: 0 | G17: 0 | H17: 0 | I17: 0 | J17: 0 | K17: =SUM(C17:J17) -> 9 | L17: 9 | M17: 0 | N17: =SUM(L17:M17) -> 9 | O17: 0 | P17: 0 | Q17: 0 | R17: 0 | S17: 0 | T17: 0 | U17: 1 | V17: 0 | W17: 8 | X17: 0 | Y17: 0 | Z17: 0 | AA17: =SUM(O17:Z17) -> 9 | AB17: 6 | AC17: 0 | AD17: 2 | AE17: 1 | AF17: =SUM(AB17:AE17) -> 9 | AG17: =IF((B17+K17+N17+AA17+AF17)/5=B17,"Todo Bien :D","Algo esta Mal :c") -> Todo Bien :D
A18: Atención personalizada a usuarios | B18: 107 | C18: 2 | D18: 95 | E18: 0 | F18: 0 | G18: 0 | H18: 0 | I18: 10 | J18: 0 | K18: =SUM(C18:J18) -> 107 | L18: 104 | M18: 3 | N18: =SUM(L18:M18) -> 107 | O18: 54 | P18: 2 | Q18: 0 | R18: 37 | S18: 2 | T18: 0 | U18: 8 | V18: 1 | W18: 2 | X18: 0 | Y18: 1 | Z18: 0 | AA18: =SUM(O18:Z18) -> 107 | AB18: 94 | AC18: 1 | AD18: 10 | AE18: 2 | AF18: =SUM(AB18:AE18) -> 107 | AG18: =IF((B18+K18+N18+AA18+AF18)/5=B18,"Todo Bien :D","Algo esta Mal :c") -> Todo Bien :D
A19: BiciTEC | B19: 0 | C19: 0 | D19: 0 | E19: 0 | F19: 0 | G19: 0 | H19: 0 | I19: 0 | J19: 0 | K19: =SUM(C19:J19) -> 0 | L19: 0 | M19: 0 | N19: =SUM(L19:M19) -> 0 | O19: 0 | P19: 0 | Q19: 0 | R19: 0 | S19: 0 | T19: 0 | U19: 0 | V19: 0 | W19: 0 | X19: 0 | Y19: 0 | Z19: 0 | AA19: =SUM(O19:Z19) -> 0 | AB19: 0 | AC19: 0 | AD19: 0 | AE19: 0 | AF19: =SUM(AB19:AE19) -> 0 | AG19: =IF((B19+K19+N19+AA19+AF19)/5=B19,"Todo Bien :D","Algo esta Mal :c") -> Todo Bien :D
A20: Calendario | B20: 0 | C20: 0 | D20: 0 | E20: 0 | F20: 0 | G20: 0 | H20: 0 | I20: 0 | J20: 0 | K20: =SUM(C20:J20) -> 0 | L20: 0 | M20: 0 | N20: =SUM(L20:M20) -> 0 | O20: 0 | P20: 0 | Q20: 0 | R20: 0 | S20: 0 | T20: 0 | U20: 0 | V20: 0 | W20: 0 | X20: 0 | Y20: 0 | Z20: 0 | AA20: =SUM(O20:Z20) -> 0 | AB20: 0 | AC20: 0 | AD20: 0 | AE20: 0 | AF20: =SUM(AB20:AE20) -> 0 | AG20: =IF((B20+K20+N20+AA20+AF20)/5=B20,"Todo Bien :D","Algo esta Mal :c") -> Todo Bien :D
A21: Cambiar información personal | B21: 12 | C21: 1 | D21: 10 | E21: 0 | F21: 0 | G21: 0 | H21: 0 | I21: 1 | J21: 0 | K21: =SUM(C21:J21) -> 12 | L21: 10 | M21: 2 | N21: =SUM(L21:M21) -> 12 | O21: 7 | P21: 0 | Q21: 0 | R21: 5 | S21: 0 | T21: 0 | U21: 0 | V21: 0 | W21: 0 | X21: 0 | Y21: 0 | Z21: 0 | AA21: =SUM(O21:Z21) -> 12 | AB21: 12 | AC21: 0 | AD21: 0 | AE21: 0 | AF21: =SUM(AB21:AE21) -> 12 | AG21: =IF((B21+K21+N21+AA21+AF21)/5=B21,"Todo Bien :D","Algo esta Mal :c") -> Todo Bien :D
A22: Cambio de contraseña | B22: 7 | C22: 1 | D22: 6 | E22: 0 | F22: 0 | G22: 0 | H22: 0 | I22: 0 | J22: 0 | K22: =SUM(C22:J22) -> 7 | L22: 7 | M22: 0 | N22: =SUM(L22:M22) -> 7 | O22: 1 | P22: 2 | Q22: 0 | R22: 1 | S22: 2 | T22: 0 | U22: 0 | V22: 0 | W22: 0 | X22: 0 | Y22: 1 | Z22: 0 | AA22: =SUM(O22:Z22) -> 7 | AB22: 7 | AC22: 0 | AD22: 0 | AE22: 0 | AF22: =SUM(AB22:AE22) -> 7 | AG22: =IF((B22+K22+N22+AA22+AF22)/5=B22,"Todo Bien :D","Algo esta Mal :c") -> Todo Bien :D
A23: Cambio de contraseña FundaTEC | B23: 4 | C23: 1 | D23: 2 | E23: 0 | F23: 0 | G23: 0 | H23: 0 | I23: 1 | J23: 0 | K23: =SUM(C23:J23) -> 4 | L23: 4 | M23: 0 | N23: =SUM(L23:M23) -> 4 | O23: 0 | P23: 1 | Q23: 0 | R23: 0 | S23: 0 | T23: 0 | U23: 0 | V23: 2 | W23: 0 | X23: 1 | Y23: 0 | Z23: 0 | AA23: =SUM(O23:Z23) -> 4 | AB23: 4 | AC23: 0 | AD23: 0 | AE23: 0 | AF23: =SUM(AB23:AE23) -> 4 | AG23: =IF((B23+K23+N23+AA23+AF23)/5=B23,"Todo Bien :D","Algo esta Mal :c") -> Todo Bien :D
A24: Carpeta Tareas | B24: 6 | C24: 0 | D24: 6 | E24: 0 | F24: 0 | G24: 0 | H24: 0 | I24: 0 | J24: 0 | K24: =SUM(C24:J24) -> 6 | L24: 5 | M24: 1 | N24: =SUM(L24:M24) -> 6 | O24: 1 | P24: 0 | Q24: 0 | R24: 5 | S24: 0 | T24: 0 | U24: 0 | V24: 0 | W24: 0 | X24: 0 | Y24: 0 | Z24: 0 | AA24: =SUM(O24:Z24) -> 6 | AB24: 5 | AC24: 0 | AD24: 0 | AE24: 1 | AF24: =SUM(AB24:AE24) -> 6 | AG24: =IF((B24+K24+N24+AA24+AF24)/5=B24,"Todo Bien :D","Algo esta Mal :c") -> Todo Bien :D
A25: Carpetas/Documentos | B25: 22 | C25: 3 | D25: 19 | E25: 0 | F25: 0 | G25: 0 | H25: 0 | I25: 0 | J25: 0 | K25: =SUM(C25:J25) -> 22 | L25: 21 | M25: 1 | N25: =SUM(L25:M25) -> 22 | O25: 3 | P25: 0 | Q25: 0 | R25: 18 | S25: 0 | T25: 0 | U25: 0 | V25: 1 | W25: 0 | X25: 0 | Y25: 0 | Z25: 0 | AA25: =SUM(O25:Z25) -> 22 | AB25: 19 | AC25: 0 | AD25: 3 | AE25: 0 | AF25: =SUM(AB25:AE25) -> 22 | AG25: =IF((B25+K25+N25+AA25+AF25)/5=B25,"Todo Bien :D","Algo esta Mal :c") -> Todo Bien :D
A26: Configuración de Comunidades/Cursos | B26: 24 | C26: 1 | D26: 20 | E26: 0 | F26: 0 | G26: 0 | H26: 0 | I26: 3 | J26: 0 | K26: =SUM(C26:J26) -> 24 | L26: 16 | M26: 8 | N26: =SUM(L26:M26) -> 24 | O26: 0 | P26: 0 | Q26: 0 | R26: 17 | S26: 0 | T26: 0 | U26: 6 | V26: 0 | W26: 1 | X26: 0 | Y26: 0 | Z26: 0 | AA26: =SUM(O26:Z26) -> 24 | AB26: 11 | AC26: 0 | AD26: 9 | AE26: 4 | AF26: =SUM(AB26:AE26) -> 24 | AG26: =IF((B26+K26+N26+AA26+AF26)/5=B26,"Todo Bien :D","Algo esta Mal :c") -> Todo Bien :D
A27: Consulta para Directores | B27: 0 | C27: 0 | D27: 0 | E27: 0 | F27: 0 | G27: 0 | H27: 0 | I27: 0 | J27: 0 | K27: =SUM(C27:J27) -> 0 | L27: 0 | M27: 0 | N27: =SUM(L27:M27) -> 0 | O27: 0 | P27: 0 | Q27: 0 | R27: 0 | S27: 0 | T27: 0 | U27: 0 | V27: 0 | W27: 0 | X27: 0 | Y27: 0 | Z27: 0 | AA27: =SUM(O27:Z27) -> 0 | AB27: 0 | AC27: 0 | AD27: 0 | AE27: 0 | AF27: =SUM(AB27:AE27) -> 0 | AG27: =IF((B27+K27+N27+AA27+AF27)/5=B27,"Todo Bien :D","Algo esta Mal :c") -> Todo Bien :D
... A32: Creación de comunidades | B32: 28 | C32: 5 | D32: 21 | E32: 0 | F32: 0 | G32: 0 | H32: 0 | I32: 2 | J32: 0 | K32: =SUM(C32:J32) -> 28 | L32: 16 | M32: 12 | N32: =SUM(L32:M32) -> 28 | O32: 2 | P32: 0 | Q32: 0 | R32: 14 | S32: 1 | T32: 0 | U32: 9 | V32: 0 | W32: 2 | X32: 0 | Y32: 0 | Z32: 0 | AA32: =SUM(O32:Z32) -> 28 | AB32: 10 | AC32: 0 | AD32: 13 | AE32: 5 | AF32: =SUM(AB32:AE32) -> 28 | AG32: =IF((B32+K32+N32+AA32+AF32)/5=B32,"Todo Bien :D","Algo esta Mal :c") -> Todo Bien :D
A33: Creación de curso | B33: 26 | C33: 2 | D33: 24 | E33: 0 | F33: 0 | G33: 0 | H33: 0 | I33: 0 | J33: 0 | K33: =SUM(C33:J33) -> 26 | L33: 0 | M33: 26 | N33: =SUM(L33:M33) -> 26 | O33: 0 | P33: 0 | Q33: 0 | R33: 10 | S33: 1 | T33: 1 | U33: 4 | V33: 9 | W33: 1 | X33: 0 | Y33: 0 | Z33: 0 | AA33: =SUM(O33:Z33) -> 26 | AB33: 8 | AC33: 0 | AD33: 13 | AE33: 3 | AF33: =SUM(AB33:AE33) -> 24 | AG33: =IF((B33+K33+N33+AA33+AF33)/5=B33,"Todo Bien :D","Algo esta Mal :c") -> Algo esta Mal :c | AI33: FALTAN 3 EN PRIORIDAD
A34: Creación de usuarios | B34: 14 | C34: 0 | D34: 14 | E34: 0 | F34: 0 | G34: 0 | H34: 0 | I34: 0 | J34: 0 | K34: =SUM(C34:J34) -> 14 | L34: 12 | M34: 2 | N34: =SUM(L34:M34) -> 14 | O34: 3 | P34: 0 | Q34: 0 | R34: 0 | S34: 1 | T34: 0 | U34: 4 | V34: 6 | W34: 0 | X34: 0 | Y34: 0 | Z34: 0 | AA34: =SUM(O34:Z34) -> 14 | AB34: 12 | AC34: 0 | AD34: 2 | AE34: 0 | AF34: =SUM(AB34:AE34) -> 14 | AG34: =IF((B34+K34+N34+AA34+AF34)/5=B34,"Todo Bien :D","Algo esta Mal :c") -> Todo Bien :D
A35: Creación de usuarios Colegio Científico | B35: 0 | C35: 0 | D35: 0 | E35: 0 | F35: 0 | G35: 0 | H35: 0 | I35: 0 | J35: 0 | K35: =SUM(C35:J35) -> 0 | L35: 0 | M35: 0 | N35: =SUM(L35:M35) -> 0 | O35: 0 | P35: 0 | Q35: 0 | R35: 0 | S35: 0 | T35: 0 | U35: 0 | V35: 0 | W35: 0 | X35: 0 | Y35: 0 | Z35: 0 | AA35: =SUM(O35:Z35) -> 0 | AB35: 0 | AC35: 0 | AD35: 0 | AE35: 0 | AF35: =SUM(AB35:AE35) -> 0 | AG35: =IF((B35+K35+N35+AA35+AF35)/5=B35,"Todo Bien :D","Algo esta Mal :c") -> Todo Bien :D
A36: Creación de usuarios FundaTEC | B36: 7 | C36: 0 | D36: 7 | E36: 0 | F36: 0 | G36: 0 | H36: 0 | I36: 0 | J36: 0 | K36: =SUM(C36:J36) -> 7 | L36: 6 | M36: 1 | N36: =SUM(L36:M36) -> 7 | O36: 0 | P36: 0 | Q36: 0 | R36: 1 | S36: 0 | T36: 0 | U36: 1 | V36: 5 | W36: 0 | X36: 0 | Y36: 0 | Z36: 0 | AA36: =SUM(O36:Z36) -> 7 | AB36: 3 | AC36: 0 | AD36: 1 | AE36: 2 | AF36: =SUM(AB36:AE36) -> 6 | AG36: =IF((B36+K36+N36+AA36+AF36)/5=B36,"Todo Bien :D","Algo esta Mal :c") -> Algo esta Mal :c | AI36: FALTA 1 EN PRIORIDAD
A37: Curso Móvil | B37: 0 | C37: 0 | D37: 0 | E37: 0 | F37: 0 | G37: 0 | H37: 0 | I37: 0 | J37: 0 | K37: =SUM(C37:J37) -> 0 | L37: 0 | M37: 0 | N37: =SUM(L37:M37) -> 0 | O37: 0 | P37: 0 | Q37: 0 | R37: 0 | S37: 0 | T37: 0 | U37: 0 | V37: 0 | W37: 0 | X37: 0 | Y37: 0 | Z37: 0 | AA37: =SUM(O37:Z37) -> 0 | AB37: 0 | AC37: 0 | AD37: 0 | AE37: 0 | AF37: =SUM(AB37:AE37) -> 0 | AG37: =IF((B37+K37+N37+AA37+AF37)/5=B37,"Todo Bien :D","Algo esta Mal :c") -> Todo Bien :D
A38: Dashboard | B38: 0 | C38: 0 | D38: 0 | E38: 0 | F38: 0 | G38: 0 | H38: 0 | I38: 0 | J38: 0 | K38: =SUM(C38:J38) -> 0 | L38: 0 | M38: 0 | N38: =SUM(L38:M38) -> 0 | O38: 0 | P38: 0 | Q38: 0 | R38: 0 | S38: 0 | T38: 0 | U38: 0 | V38: 0 | W38: 0 | X38: 0 | Y38: 0 | Z38: 0 | AA38: =SUM(O38:Z38) -> 0 | AB38: 0 | AC38: 0 | AD38: 0 | AE38: 0 | AF38: =SUM(AB38:AE38) -> 0 | AG38: =IF((B38+K38+N38+AA38+AF38)/5=B38,"Todo Bien :D","Algo esta Mal :c") -> Todo Bien :D
A39: Diagnósticos | B39: 1 | C39: 1 | D39: 0 | E39: 0 | F39: 0 | G39: 0 | H39: 0 | I39: 0 | J39: 0 | K39: =SUM(C39:J39) -> 1 | L39: 0 | M39: 1 | N39: =SUM(L39:M39) -> 1 | O39: 0 | P39: 0 | Q39: 0 | R39: 1 | S39: 0 | T39: 0 | U39: 0 | V39: 0 | W39: 0 | X39: 0 | Y39: 0 | Z39: 0 | AA39: =SUM(O39:Z39) -> 1 | AB39: 1 | AC39: 0 | AD39: 0 | AE39: 0 | AF39: =SUM(AB39:AE39) -> 1 | AG39: =IF((B39+K39+N39+AA39+AF39)/5=B39,"Todo Bien :D","Algo esta Mal :c") -> Todo Bien :D
A40: Diseño instruccional | B40: 0 | C40: 0 | D40: 0 | E40: 0 | F40: 0 | G40: 0 | H40: 0 | I40: 0 | J40: 0 | K40: =SUM(C40:J40) -> 0 | L40: 0 | M40: 0 | N40: =SUM(L40:M40) -> 0 | O40: 0 | P40: 0 | Q40: 0 | R40: 0 | S40: 0 | T40: 0 | U40: 0 | V40: 0 | W40: 0 | X40: 0 | Y40: 0 | Z40: 0 | AA40: =SUM(O40:Z40) -> 0 | AB40: 0 | AC40: 0 | AD40: 0 | AE40: 0 | AF40: =SUM(AB40:AE40) -> 0 | AG40: =IF((B40+K40+N40+AA40+AF40)/5=B40,"Todo Bien :D","Algo esta Mal :c") -> Todo Bien :D
A41: Envío de comunicados a comunidades | B41: 17 | C41: 0 | D41: 17 | E41: 0 | F41: 0 | G41: 0 | H41: 0 | I41: 0 | J41: 0 | K41: =SUM(C41:J41) -> 17 | L41: 17 | M41: 0 | N41: =SUM(L41:M41) -> 17 | O41: 1 | P41: 0 | Q41: 0 | R41: 2 | S41: 0 | T41: 0 | U41: 14 | V41: 0 | W41: 0 | X41: 0 | Y41: 0 | Z41: 0 | AA41: =SUM(O41:Z41) -> 17 | AB41: 15 | AC41: 0 | AD41: 0 | AE41: 2 | AF41: =SUM(AB41:AE41) -> 17 | AG41: =IF((B41+K41+N41+AA41+AF41)/5=B41,"Todo Bien :D","Algo esta Mal :c") -> Todo Bien :D
A42: Envío de comunicados a lista seleccionada | B42: 0 | C42: 0 | D42: 0 | E42: 0 | F42: 0 | G42: 0 | H42: 0 | I42: 0 | J42: 0 | K42: =SUM(C42:J42) -> 0 | L42: 0 | M42: 0 | N42: =SUM(L42:M42) -> 0 | O42: 0 | P42: 0 | Q42: 0 | R42: 0 | S42: 0 | T42: 0 | U42: 0 | V42: 0 | W42: 0 | X42: 0 | Y42: 0 | Z42: 0 | AA42: =SUM(O42:Z42) -> 0 | AB42: 0 | AC42: 0 | AD42: 0 | AE42: 0 | AF42: =SUM(AB42:AE42) -> 0 | AG42: =IF((B42+K42+N42+AA42+AF42)/5=B42,"Todo Bien :D","Algo esta Mal :c") -> Todo Bien :D
A43: Envío de comunicados mediante redes sociales | B43: 0 | C43: 0 | D43: 0 | E43: 0 | F43: 0 | G43: 0 | H43: 0 | I43: 0 | J43: 0 | K43: =SUM(C43:J43) -> 0 | L43: 0 | M43: 0 | N43: =SUM(L43:M43) -> 0 | O43: 0 | P43: 0 | Q43: 0 | R43: 0 | S43: 0 | T43: 0 | U43: 0 | V43: 0 | W43: 0 | X43: 0 | Y43: 0 | Z43: 0 | AA43: =SUM(O43:Z43) -> 0 | AB43: 0 | AC43: 0 | AD43: 0 | AE43: 0 | AF43: =SUM(AB43:AE43) -> 0 | AG43: =IF((B43+K43+N43+AA43+AF43)/5=B43,"Todo Bien :D","Algo esta Mal :c") -> Todo Bien :D
A44: Estadísticas de curso/comunidad | B44: 0 | C44: 0 | D44: 0 | E44: 0 | F44: 0 | G44: 0 | H44: 0 | I44: 0 | J44: 0 | K44: =SUM(C44:J44) -> 0 | L44: 0 | M44: 0 | N44: =SUM(L44:M44) -> 0 | O44: 0 | P44: 0 | Q44: 0 | R44: 0 | S44: 0 | T44: 0 | U44: 0 | V44: 0 | W44: 0 | X44: 0 | Y44: 0 | Z44: 0 | AA44: =SUM(O44:Z44) -> 0 | AB44: 0 | AC44: 0 | AD44: 0 | AE44: 0 | AF44: =SUM(AB44:AE44) -> 0 | AG44: =IF((B44+K44+N44+AA44+AF44)/5=B44,"Todo Bien :D","Algo esta Mal :c") -> Todo Bien :D
A45: Evaluaciones | B45: 29 | C45: 0 | D45: 22 | E45: 0 | F45: 0 | G45: 0 | H45: 0 | I45: 7 | J45: 0 | K45: =SUM(C45:J45) -> 29 | L45: 0 | M45: 29 | N45: =SUM(L45:M45) -> 29 | O45: 10 | P45: 1 | Q45: 0 | R45: 15 | S45: 3 | T45: 0 | U45: 0 | V45: 0 | W45: 0 | X45: 0 | Y45: 0 | Z45: 0 | AA45: =SUM(O45:Z45) -> 29 | AB45: 25 | AC45: 1 | AD45: 2 | AE45: 1 | AF45: =SUM(AB45:AE45) -> 29 | AG45: =IF((B45+K45+N45+AA45+AF45)/5=B45,"Todo Bien :D","Algo esta Mal :c") -> Todo Bien :D
...

Sheet MARZO
A1: SERVICIO RELACIONADO | C1: TIQUETS POR CANAL | L1: TIPO | O1: ROL USUARIO | AB1: PRIORIDAD
A3: =IF((B51+K51+N51+AA51+AF51)/5=B51,"Todo Bien :D","Algo esta Mal :c") -> Todo Bien :D | B3: Cantidad x Servicio | C3: Chat | D3: Correo | E3: Formulario Web | F3: Facebook | G3: Memorandum | H3: Presencial | I3: Teléfono | J3: Twitter | K3: TOTAL | L3: Solicitud | M3: Incidente | N3: TOTAL | O3: Estudiante | P3: Estudiante FundaTEC | Q3: Estudiante Colegio Científico | R3: Profesor | S3: Profesor FundaTEC | T3: Profesor Colegio Científico | U3: Administrativo | V3: Administrativo FundaTEC | W3: Director/Coordinador | X3: Director/Coordinador FundaTEC | Y3: Director/Coordinador Colegio Ciencífico | Z3: Externo | AA3: TOTAL | AB3: Normal | AC3: Baja | AD3: Alta | AE3: Urgente | AF3: TOTAL | AG3: TOTALES
A4: Acceso a la plataforma TEC Digital | B4: 66 | C4: 0 | D4: 56 | E4: 0 | F4: 0 | G4: 0 | H4: 0 | I4: 10 | J4: 0 | K4: =SUM(C4:J4) -> 66 | L4: 65 | M4: 1 | N4: =SUM(L4:M4) -> 66 | O4: 28 | P4: 4 | Q4: 0 | R4: 15 | S4: 1 | T4: 0 | U4: 6 | V4: 3 | W4: 0 | X4: 0 | Y4: 0 | Z4: 9 | AA4: =SUM(O4:Z4) -> 66 | AB4: 58 | AC4: 0 | AD4: 6 | AE4: 2 | AF4: =SUM(AB4:AE4) -> 66 | AG4: =IF((B4+K4+N4+AA4+AF4)/5=B4,"Todo Bien :D","Algo esta Mal :c") -> Todo Bien :D
A5: Acreditación | B5: 0 | C5: 0 | D5: 0 | E5: 0 | F5: 0 | G5: 0 | H5: 0 | I5: 0 | J5: 0 | K5: =SUM(C5:J5) -> 0 | L5: 0 | M5: 0 | N5: =SUM(L5:M5) -> 0 | O5: 0 | P5: 0 | Q5: 0 | R5: 0 | S5: 0 | T5: 0 | U5: 0 | V5: 0 | W5: 0 | X5: 0 | Y5: 0 | Z5: 0 | AA5: =SUM(O5:Z5) -> 0 | AB5: 0 | AC5: 0 | AD5: 0 | AE5: 0 | AF5: =SUM(AB5:AE5) -> 0 | AG5: =IF((B5+K5+N5+AA5+AF5)/5=B5,"Todo Bien :D","Algo esta Mal :c") -> Todo Bien :D
A6: Activar cuentas de usuario | B6: 12 | C6: 2 | D6: 10 | E6: 0 | F6: 0 | G6: 0 | H6: 0 | I6: 0 | J6: 0 | K6: =SUM(C6:J6) -> 12 | L6: 12 | M6: 0 | N6: =SUM(L6:M6) -> 12 | O6: 1 | P6: 0 | Q6: 0 | R6: 5 | S6: 0 | T6: 0 | U6: 5 | V6: 0 | W6: 1 | X6: 0 | Y6: 0 | Z6: 0 | AA6: =SUM(O6:Z6) -> 12 | AB6: 8 | AC6: 0 | AD6: 3 | AE6: 1 | AF6: =SUM(AB6:AE6) -> 12 | AG6: =IF((B6+K6+N6+AA6+AF6)/5=B6,"Todo Bien :D","Algo esta Mal :c") -> Todo Bien :D
A7: Activar curso | B7: 2 | C7: 0 | D7: 2 | E7: 0 | F7: 0 | G7: 0 | H7: 0 | I7: 0 | J7: 0 | K7: =SUM(C7:J7) -> 2 | L7: 2 | M7: 0 | N7: =SUM(L7:M7) -> 2 | O7: 0 | P7: 0 | Q7: 0 | R7: 1 | S7: 0 | T7: 0 | U7: 1 | V7: 0 | W7: 0 | X7: 0 | Y7: 0 | Z7: 0 | AA7: =SUM(O7:Z7) -> 2 | AB7: 1 | AC7: 0 | AD7: 1 | AE7: 0 | AF7: =SUM(AB7:AE7) -> 2 | AG7: =IF((B7+K7+N7+AA7+AF7)/5=B7,"Todo Bien :D","Algo esta Mal :c") -> Todo Bien :D
A8: Actualizar cursos a estudiantes | B8: 1 | C8: 0 | D8: 1 | E8: 0 | F8: 0 | G8: 0 | H8: 0 | I8: 0 | J8: 0 | K8: =SUM(C8:J8) -> 1 | L8: 1 | M8: 0 | N8: =SUM(L8:M8) -> 1 | O8: 1 | P8: 0 | Q8: 0 | R8: 0 | S8: 0 | T8: 0 | U8: 0 | V8: 0 | W8: 0 | X8: 0 | Y8: 0 | Z8: 0 | AA8: =SUM(O8:Z8) -> 1 | AB8: 1 | AC8: 0 | AD8: 0 | AE8: 0 | AF8: =SUM(AB8:AE8) -> 1 | AG8: =IF((B8+K8+N8+AA8+AF8)/5=B8,"Todo Bien :D","Algo esta Mal :c") -> Todo Bien :D
A9: Actualizar miembros de comunidades | B9: 4 | C9: 0 | D9: 4 | E9: 0 | F9: 0 | G9: 0 | H9: 0 | I9: 0 | J9: 0 | K9: =SUM(C9:J9) -> 4 | L9: 4 | M9: 0 | N9: =SUM(L9:M9) -> 4 | O9: 0 | P9: 0 | Q9: 0 | R9: 1 | S9: 0 | T9: 0 | U9: 2 | V9: 0 | W9: 1 | X9: 0 | Y9: 0 | Z9: 0 | AA9: =SUM(O9:Z9) -> 4 | AB9: 1 | AC9: 0 | AD9: 3 | AE9: 0 | AF9: =SUM(AB9:AE9) -> 4 | AG9: =IF((B9+K9+N9+AA9+AF9)/5=B9,"Todo Bien :D","Algo esta Mal :c") -> Todo Bien :D
A10: Administrador de asistencia | B10: 0 | C10: 0 | D10: 0 | E10: 0 | F10: 0 | G10: 0 | H10: 0 | I10: 0 | J10: 0 | K10: 0 | L10: 0 | M10: 0 | N10: 0 | O10: 0 | P10: 0 | Q10: 0 | R10: 0 | S10: 0 | T10: 0 | U10: 0 | V10: 0 | W10: 0 | X10: 0 | Y10: 0 | Z10: 0 | AA10: 0 | AB10: 0 | AC10: 0 | AD10: 0 | AE10: 0 | AF10: =SUM(AB10:AE10) -> 0 | AG10: =IF((B10+K10+N10+AA10+AF10)/5=B10,"Todo Bien :D","Algo esta Mal :c") -> Todo Bien :D
A11: Administrador Programa de Curso | B11: 0 | C11: 0 | D11: 0 | E11: 0 | F11: 0 | G11: 0 | H11: 0 | I11: 0 | J11: 0 | K11: =SUM(C11:J11) -> 0 | L11: 0 | M11: 0 | N11: =SUM(L11:M11) -> 0 | O11: 0 | P11: 0 | Q11: 0 | R11: 0 | S11: 0 | T11: 0 | U11: 0 | V11: 0 | W11: 0 | X11: 0 | Y11: 0 | Z11: 0 | AA11: =SUM(O11:Z11) -> 0 | AB11: 0 | AC11: 0 | AD11: 0 | AE11: 0 | AF11: =SUM(AB11:AE11) -> 0 | AG11: =IF((B11+K11+N11+AA11+AF11)/5=B11,"Todo Bien :D","Algo esta Mal :c") -> Todo Bien :D
A12: Agregar/cambiar asociación de estudiante a curso | B12: 31 | C12: 2 | D12: 29 | E12: 0 | F12: 0 | G12: 0 | H12: 0 | I12: 0 | J12: 0 | K12: =SUM(C12:J12) -> 31 | L12: 0 | M12: 31 | N12: =SUM(L12:M12) -> 31 | O12: 12 | P12: 0 | Q12: 0 | R12: 4 | S12: 0 | T12: 0 | U12: 3 | V12: 11 | W12: 1 | X12: 0 | Y12: 0 | Z12: 0 | AA12: =SUM(O12:Z12) -> 31 | AB12: 31 | AC12: 0 | AD12: 0 | AE12: 0 | AF12: =SUM(AB12:AE12) -> 31 | AG12: =IF((B12+K12+N12+AA12+AF12)/5=B12,"Todo Bien :D","Algo esta Mal :c") -> Todo Bien :D
A13: Agregar/cambiar asociación de profesor a curso | B13: 12 | C13: 0 | D13: 10 | E13: 0 | F13: 0 | G13: 0 | H13: 0 | I13: 2 | J13: 0 | K13: =SUM(C13:J13) -> 12 | L13: 12 | M13: 0 | N13: =SUM(L13:M13) -> 12 | O13: 0 | P13: 0 | Q13: 0 | R13: 9 | S13: 0 | T13: 1 | U13: 2 | V13: 0 | W13: 0 | X13: 0 | Y13: 0 | Z13: 0 | AA13: =SUM(O13:Z13) -> 12 | AB13: 10 | AC13: 0 | AD13: 1 | AE13: 1 | AF13: =SUM(AB13:AE13) -> 12 | AG13: =IF((B13+K13+N13+AA13+AF13)/5=B13,"Todo Bien :D","Algo esta Mal :c") -> Todo Bien :D
A14: Agregar/cambiar asociación de usuario a comunidad | B14: 34 | C14: 4 | D14: 30 | E14: 0 | F14: 0 | G14: 0 | H14: 0 | I14: 0 | J14: 0 | K14: =SUM(C14:J14) -> 34 | L14: 0 | M14: 34 | N14: =SUM(L14:M14) -> 34 | O14: 13 | P14: 0 | Q14: 0 | R14: 11 | S14: 0 | T14: 0 | U14: 9 | V14: 0 | W14: 1 | X14: 0 | Y14: 0 | Z14: 0 | AA14: =SUM(O14:Z14) -> 34 | AB14: 32 | AC14: 0 | AD14: 0 | AE14: 2 | AF14: =SUM(AB14:AE14) -> 34 | AG14: =IF((B14+K14+N14+AA14+AF14)/5=B14,"Todo Bien :D","Algo esta Mal :c") -> Todo Bien :D
A15: Agregar/cambiar asociación estudiante a curso Colegio Científico | B15: 0 | C15: 0 | D15: 0 | E15: 0 | F15: 0 | G15: 0 | H15: 0 | I15: 0 | J15: 0 | K15: =SUM(C15:J15) -> 0 | L15: 0 | M15: 0 | N15: 0 | O15: 0 | P15: 0 | Q15: 0 | R15: 0 | S15: 0 | T15: 0 | U15: 0 | V15: 0 | W15: 0 | X15: 0 | Y15: 0 | Z15: 0 | AA15: 0 | AB15: 0 | AC15: 0 | AD15: 0 | AE15: 0 | AF15: =SUM(AB15:AE15) -> 0 | AG15: =IF((B15+K15+N15+AA15+AF15)/5=B15,"Todo Bien :D","Algo esta Mal :c") -> Todo Bien :D
A16: Agregar/cambiar asociación estudiante a curso FundaTEC | B16: 0 | C16: 0 | D16: 0 | E16: 0 | F16: 0 | G16: 0 | H16: 0 | I16: 0 | J16: 0 | K16: =SUM(C16:J16) -> 0 | L16: 0 | M16: 0 | N16: =SUM(L16:M16) -> 0 | O16: 0 | P16: 0 | Q16: 0 | R16: 0 | S16: 0 | T16: 0 | U16: 0 | V16: 0 | W16: 0 | X16: 0 | Y16: 0 | Z16: 0 | AA16: =SUM(O16:Z16) -> 0 | AB16: 0 | AC16: 0 | AD16: 0 | AE16: 0 | AF16: =SUM(AB16:AE16) -> 0 | AG16: =IF((B16+K16+N16+AA16+AF16)/5=B16,"Todo Bien :D","Algo esta Mal :c") -> Todo Bien :D
A17: Asignación de permisos especiales | B17: 7 | C17: 0 | D17: 5 | E17: 0 | F17: 0 | G17: 1 | H17: 0 | I17: 1 | J17: 0 | K17: =SUM(C17:J17) -> 7 | L17: 6 | M17: 1 | N17: =SUM(L17:M17) -> 7 | O17: 0 | P17: 0 | Q17: 0 | R17: 3 | S17: 0 | T17: 0 | U17: 3 | V17: 0 | W17: 1 | X17: 0 | Y17: 0 | Z17: 0 | AA17: =SUM(O17:Z17) -> 7 | AB17: 6 | AC17: 0 | AD17: 0 | AE17: 1 | AF17: =SUM(AB17:AE17) -> 7 | AG17: =IF((B17+K17+N17+AA17+AF17)/5=B17,"Todo Bien :D","Algo esta Mal :c") -> Todo Bien :D
A18: Atención personalizada a usuarios | B18: 66 | C18: 10 | D18: 48 | E18: 0 | F18: 1 | G18: 0 | H18: 0 | I18: 7 | J18: 0 | K18: =SUM(C18:J18) -> 66 | L18: 66 | M18: 0 | N18: =SUM(L18:M18) -> 66 | O18: 22 | P18: 3 | Q18: 0 | R18: 18 | S18: 1 | T18: 0 | U18: 14 | V18: 1 | W18: 4 | X18: 0 | Y18: 0 | Z18: 3 | AA18: =SUM(O18:Z18) -> 66 | AB18: 58 | AC18: 0 | AD18: 6 | AE18: 2 | AF18: =SUM(AB18:AE18) -> 66 | AG18: =IF((B18+K18+N18+AA18+AF18)/5=B18,"Todo Bien :D","Algo esta Mal :c") -> Todo Bien :D
A19: BiciTEC | B19: 0 | C19: 0 | D19: 0 | E19: 0 | F19: 0 | G19: 0 | H19: 0 | I19: 0 | J19: 0 | K19: 0 | L19: 0 | M19: 0 | N19: 0 | O19: 0 | P19: 0 | Q19: 0 | R19: 0 | S19: 0 | T19: 0 | U19: 0 | V19: 0 | W19: 0 | X19: 0 | Y19: 0 | Z19: 0 | AA19: 0 | AB19: 0 | AC19: 0 | AD19: 0 | AE19: 0 | AF19: 0 | AG19: =IF((B19+K19+N19+AA19+AF19)/5=B19,"Todo Bien :D","Algo esta Mal :c") -> Todo Bien :D
A20: Calendario | B20: 1 | C20: 0 | D20: 1 | E20: 0 | F20: 0 | G20: 0 | H20: 0 | I20: 0 | J20: 0 | K20: =SUM(C20:J20) -> 1 | L20: 0 | M20: 1 | N20: =SUM(L20:M20) -> 1 | O20: 1 | P20: 0 | Q20: 0 | R20: 0 | S20: 0 | T20: 0 | U20: 0 | V20: 0 | W20: 0 | X20: 0 | Y20: 0 | Z20: 0 | AA20: =SUM(O20:Z20) -> 1 | AB20: 0 | AC20: 0 | AD20: 1 | AE20: 0 | AF20: =SUM(AB20:AE20) -> 1 | AG20: =IF((B20+K20+N20+AA20+AF20)/5=B20,"Todo Bien :D","Algo esta Mal :c") -> Todo Bien :D
A21: Cambiar información personal | B21: 6 | C21: 0 | D21: 5 | E21: 0 | F21: 0 | G21: 0 | H21: 0 | I21: 1 | J21: 0 | K21: =SUM(C21:J21) -> 6 | L21: 0 | M21: 6 | N21: =SUM(L21:M21) -> 6 | O21: 1 | P21: 3 | Q21: 0 | R21: 2 | S21: 0 | T21: 0 | U21: 0 | V21: 0 | W21: 0 | X21: 0 | Y21: 0 | Z21: 0 | AA21: =SUM(O21:Z21) -> 6 | AB21: 6 | AC21: 0 | AD21: 0 | AE21: 0 | AF21: =SUM(AB21:AE21) -> 6 | AG21: =IF((B21+K21+N21+AA21+AF21)/5=B21,"Todo Bien :D","Algo esta Mal :c") -> Todo Bien :D
A22: Cambio de contraseña | B22: 6 | C22: 1 | D22: 5 | E22: 0 | F22: 0 | G22: 0 | H22: 0 | I22: 0 | J22: 0 | K22: =SUM(C22:J22) -> 6 | L22: 6 | M22: 0 | N22: =SUM(L22:M22) -> 6 | O22: 2 | P22: 1 | Q22: 0 | R22: 2 | S22: 1 | T22: 0 | U22: 0 | V22: 0 | W22: 0 | X22: 0 | Y22: 0 | Z22: 0 | AA22: =SUM(O22:Z22) -> 6 | AB22: 6 | AC22: 0 | AD22: 0 | AE22: 0 | AF22: =SUM(AB22:AE22) -> 6 | AG22: =IF((B22+K22+N22+AA22+AF22)/5=B22,"Todo Bien :D","Algo esta Mal :c") -> Todo Bien :D
A23: Cambio de contraseña FundaTEC | B23: 2 | C23: 0 | D23: 1 | E23: 0 | F23: 0 | G23: 0 | H23: 0 | I23: 1 | J23: 0 | K23: =SUM(C23:J23) -> 2 | L23: 2 | M23: 0 | N23: =SUM(L23:M23) -> 2 | O23: 0 | P23: 1 | Q23: 0 | R23: 0 | S23: 1 | T23: 0 | U23: 0 | V23: 0 | W23: 0 | X23: 0 | Y23: 0 | Z23: 0 | AA23: =SUM(O23:Z23) -> 2 | AB23: 2 | AC23: 0 | AD23: 0 | AE23: 0 | AF23: =SUM(AB23:AE23) -> 2 | AG23: =IF((B23+K23+N23+AA23+AF23)/5=B23,"Todo Bien :D","Algo esta Mal :c") -> Todo Bien :D
A24: Carpeta Tareas | B24: 0 | C24: 0 | D24: 0 | E24: 0 | F24: 0 | G24: 0 | H24: 0 | J24: 0 | K24: 0 | L24: 0 | M24: 0 | N24: 0 | O24: 0 | P24: 0 | Q24: 0 | R24: 0 | S24: 0 | T24: 0 | U24: 0 | V24: 0 | W24: 0 | X24: 0 | Y24: 0 | Z24: 0 | AA24: 0 | AB24: 0 | AC24: 0 | AD24: 0 | AE24: 0 | AF24: 0 | AG24: =IF((B24+K24+N24+AA24+AF24)/5=B24,"Todo Bien :D","Algo esta Mal :c") -> Todo Bien :D
A25: Carpetas/Documentos | B25: 21 | C25: 1 | D25: 17 | E25: 0 | F25: 0 | G25: 0 | H25: 0 | I25: 3 | J25: 0 | K25: =SUM(C25:J25) -> 21 | L25: 21 | M25: 0 | N25: =SUM(L25:M25) -> 21 | O25: 12 | P25: 0 | Q25: 0 | R25: 7 | S25: 0 | T25: 0 | U25: 1 | V25: 0 | W25: 1 | X25: 0 | Y25: 0 | Z25: 0 | AA25: =SUM(O25:Z25) -> 21 | AB25: 20 | AC25: 0 | AD25: 0 | AE25: 1 | AF25: =SUM(AB25:AE25) -> 21 | AG25: =IF((B25+K25+N25+AA25+AF25)/5=B25,"Todo Bien :D","Algo esta Mal :c") -> Todo Bien :D
A26: Configuración de Comunidades/Cursos | B26: 26 | C26: 2 | D26: 17 | E26: 0 | F26: 0 | G26: 0 | H26: 0 | I26: 7 | J26: 0 | K26: =SUM(C26:J26) -> 26 | L26: 26 | M26: 0 | N26: =SUM(L26:M26) -> 26 | O26: 3 | P26: 0 | Q26: 0 | R26: 14 | S26: 2 | T26: 0 | U26: 7 | V26: 0 | W26: 0 | X26: 0 | Y26: 0 | Z26: 0 | AA26: =SUM(O26:Z26) -> 26 | AB26: 18 | AC26: 0 | AD26: 6 | AE26: 2 | AF26: =SUM(AB26:AE26) -> 26 | AG26: =IF((B26+K26+N26+AA26+AF26)/5=B26,"Todo Bien :D","Algo esta Mal :c") -> Todo Bien :D
A27: Consulta para Directores | B27: 0 | C27: 0 | D27: 0 | E27: 0 | F27: 0 | G27: 0 | H27: 0 | I27: 0 | J27: 0 | K27: 0 | L27: 0 | M27: 0 | N27: 0 | O27: 0 | Q27: 0 | R27: 0 | S27: 0 | T27: 0 | U27: 0 | W27: 0 | X27: 0 | Y27: 0 | Z27: 0 | AA27: 0 | AB27: 0 | AC27: 0 | AD27: 0 | AE27: 0 | AF27: 0 | AG27: =IF((B27+K27+N27+AA27+AF27)/5=B27,"Todo Bien :D","Algo esta Mal :c") -> Todo Bien :D
A28: Control de plagio | B28: 8 | C28: 2 | D28: 5 | E28: 0 | F28: 0 | G28: 0 | H28: 0 | I28: 1 | J28: 0 | K28: =SUM(C28:J28) -> 8 | L28: 7 | M28: 1 | N28: =SUM(L28:M28) -> 8 | O28: 1 | P28: 0 | Q28: 0 | R28: 7 | S28: 0 | T28: 0 | U28: 0 | V28: 0 | W28: 0 | X28: 0 | Y28: 0 | Z28: 0 | AA28: =SUM(O28:Z28) -> 8 | AB28: 4 | AC28: 0 | AD28: 1 | AE28: 3 | AF28: =SUM(AB28:AE28) -> 8 | AG28: =IF((B28+K28+N28+AA28+AF28)/5=B28,"Todo Bien :D","Algo esta Mal :c") -> Todo Bien :D
A29: Copiado de contenidos | B29: 2 | C29: 2 | D29: 0 | E29: 0 | F29: 0 | G29: 0 | H29: 0 | I29: 0 | J29: 0 | K29: 2 | L29: 2 | M29: 0 | N29: =SUM(L29:M29) -> 2 | O29: 0 | P29: 0 | Q29: 0 | R29: 1 | S29: 0 | T29: 0 | U29: 1 | V29: 0 | W29: 0 | X29: 0 | Y29: 0 | Z29: 0 | AA29: =SUM(O29:Z29) -> 2 | AB29: 2 | AC29: 0 | AD29: 0 | AE29: 0 | AF29: =SUM(AB29:AE29) -> 2 | AG29: =IF((B29+K29+N29+AA29+AF29)/5=B29,"Todo Bien :D","Algo esta Mal :c") -> Todo Bien :D
A30: Creación curso Colegio Científico | B30: 0 | C30: 0 | D30: 0 | E30: 0 | F30: 0 | G30: 0 | H30: 0 | I30: 0 | J30: 0 | K30: 0 | L30: 0 | M30: 0 | N30: 0 | O30: 0 | P30: 0 | Q30: 0 | R30: 0 | S30: 0 | T30: 0 | U30: 0 | V30: 0 | W30: 0 | X30: 0 | Y30: 0 | Z30: 0 | AA30: 0 | AB30: 0 | AC30: 0 | AD30: 0 | AE30: 0 | AF30: =SUM(AB30:AE30) -> 0 | AG30: =IF((B30+K30+N30+AA30+AF30)/5=B30,"Todo Bien :D","Algo esta Mal :c") -> Todo Bien :D
A31: Creación cursos FundaTEC | B31: 24 | C31: 24 | D31: 0 | E31: 0 | F31: 0 | G31: 0 | H31: 0 | I31: 0 | J31: 0 | K31: =SUM(C31:J31) -> 24 | L31: 24 | M31: 0 | N31: =SUM(L31:M31) -> 24 | O31: 0 | P31: 0 | Q31: 0 | R31: 1 | S31: 0 | T31: 0 | U31: 0 | V31: 23 | W31: 0 | X31: 0 | Y31: 0 | Z31: 0 | AA31: =SUM(O31:Z31) -> 24 | AB31: 23 | AC31: 0 | AD31: 0 | AE31: 1 | AF31: =SUM(AB31:AE31) -> 24 | AG31: =IF((B31+K31+N31+AA31+AF31)/5=B31,"Todo Bien :D","Algo esta Mal :c") -> Todo Bien :D
A32: Creación de comunidades | B32: 6 | C32: 1 | D32: 3 | E32: 0 | F32: 0 | G32: 0 | H32: 0 | I32: 2 | J32: 0 | K32: =SUM(C32:J32) -> 6 | L32: 6 | M32: 0 | N32: =SUM(L32:M32) -> 6 | O32: 2 | P32: 0 | Q32: 0 | R32: 2 | S32: 1 | T32: 0 | U32: 1 | V32: 0 | W32: 0 | X32: 0 | Y32: 0 | Z32: 0 | AA32: =SUM(O32:Z32) -> 6 | AB32: 4 | AC32: 0 | AD32: 0 | AE32: 2 | AF32: =SUM(AB32:AE32) -> 6 | AG32: =IF((B32+K32+N32+AA32+AF32)/5=B32,"Todo Bien :D","Algo esta Mal :c") -> Todo Bien :D
A33: Creación de curso | B33: 16 | C33: 1 | D33: 15 | E33: 0 | F33: 0 | G33: 0 | H33: 0 | I33: 0 | J33: 0 | K33: =SUM(C33:J33) -> 16 | L33: 16 | M33: 0 | N33: =SUM(L33:M33) -> 16 | O33: 0 | P33: 0 | Q33: 0 | R33: 1 | S33: 0 | T33: 0 | U33: 6 | V33: 7 | W33: 2 | X33: 0 | Y33: 0 | Z33: 0 | AA33: =SUM(O33:Z33) -> 16 | AB33: 14 | AC33: 0 | AD33: 2 | AE33: 0 | AF33: =SUM(AB33:AE33) -> 16 | AG33: =IF((B33+K33+N33+AA33+AF33)/5=B33,"Todo Bien :D","Algo esta Mal :c") -> Todo Bien :D
A34: Creación de usuarios | B34: 11 | C34: 1 | D34: 10 | E34: 0 | F34: 0 | G34: 0 | H34: 0 | I34: 0 | J34: 0 | K34: 11 | L34: 11 | M34: 0 | N34: =SUM(L34:M34) -> 11 | O34: 0 | P34: 0 | Q34: 0 | R34: 0 | S34: 1 | T34: 0 | U34: 2 | V34: 8 | W34: 0 | X34: 0 | Y34: 0 | Z34: 0 | AA34: =SUM(O34:Z34) -> 11 | AB34: 9 | AC34: 0 | AD34: 1 | AE34: 1 | AF34: =SUM(AB34:AE34) -> 11 | AG34: =IF((B34+K34+N34+AA34+AF34)/5=B34,"Todo Bien :D","Algo esta Mal :c") -> Todo Bien :D
A35: Creación de usuarios Colegio Científico | B35: 0 | C35: 0 | D35: 0 | E35: 0 | F35: 0 | G35: 0 | H35: 0 | I35: 0 | J35: 0 | K35: 0 | L35: 0 | M35: 0 | N35: 0 | O35: 0 | P35: 0 | Q35: 0 | R35: 0 | S35: 0 | T35: 0 | U35: 0 | V35: 0 | W35: 0 | X35: 0 | Y35: 0 | Z35: 0 | AA35: 0 | AB35: 0 | AC35: 0 | AD35: 0 | AE35: 0 | AF35: 0 | AG35: =IF((B35+K35+N35+AA35+AF35)/5=B35,"Todo Bien :D","Algo esta Mal :c") -> Todo Bien :D
A36: Creación de usuarios FundaTEC | B36: 3 | C36: 0 | D36: 3 | E36: 0 | F36: 0 | G36: 0 | H36: 0 | I36: 0 | J36: 0 | K36: =SUM(C36:J36) -> 3 | L36: 3 | M36: 0 | N36: =SUM(L36:M36) -> 3 | O36: 0 | P36: 0 | Q36: 0 | R36: 0 | S36: 1 | T36: 0 | U36: 0 | V36: 2 | W36: 0 | X36: 0 | Y36: 0 | Z36: 0 | AA36: =SUM(O36:Z36) -> 3 | AB36: 3 | AC36: 0 | AD36: 0 | AE36: 0 | AF36: =SUM(AB36:AE36) -> 3 | AG36: =IF((B36+K36+N36+AA36+AF36)/5=B36,"Todo Bien :D","Algo esta Mal :c") -> Todo Bien :D
A37: Curso Móvil | B37: 0 | C37: 0 | D37: 0 | E37: 0 | F37: 0 | G37: 0 | H37: 0 | I37: 0 | J37: 0 | K37: =SUM(C37:J37) -> 0 | L37: 0 | M37: 0 | N37: 0 | O37: 0 | P37: 0 | Q37: 0 | R37: 0 | S37: 0 | T37: 0 | U37: 0 | V37: 0 | W37: 0 | X37: 0 | Y37: 0 | Z37: 0 | AA37: 0 | AB37: 0 | AC37: 0 | AD37: 0 | AE37: 0 | AF37: 0 | AG37: =IF((B37+K37+N37+AA37+AF37)/5=B37,"Todo Bien :D","Algo esta Mal :c") -> Todo Bien :D
A38: Dashboard | B38: 0 | C38: 0 | D38: 0 | E38: 0 | F38: 0 | G38: 0 | H38: 0 | I38: 0 | J38: 0 | K38: =SUM(C38:J38) -> 0 | L38: 0 | M38: 0 | N38: =SUM(L38:M38) -> 0 | O38: 0 | P38: 0 | Q38: 0 | R38: 0 | S38: 0 | T38: 0 | U38: 0 | V38: 0 | W38: 0 | X38: 0 | Y38: 0 | Z38: 0 | AA38: =SUM(O38:Z38) -> 0 | AB38: 0 | AC38: 0 | AD38: 0 | AE38: 0 | AF38: =SUM(AB38:AE38) -> 0 | AG38: =IF((B38+K38+N38+AA38+AF38)/5=B38,"Todo Bien :D","Algo esta Mal :c") -> Todo Bien :D
A39: Diagnósticos | B39: 0 | C39: 0 | D39: 0 | E39: 0 | F39: 0 | G39: 0 | H39: 0 | I39: 0 | J39: 0 | K39: 0 | L39: 0 | M39: 0 | N39: =SUM(L39:M39) -> 0 | O39: 0 | P39: 0 | Q39: 0 | R39: 0 | S39: 0 | T39: 0 | U39: 0 | V39: 0 | W39: 0 | X39: 0 | Y39: 0 | Z39: 0 | AA39: =SUM(O39:Z39) -> 0 | AB39: 0 | AC39: 0 | AD39: 0 | AE39: 0 | AF39: =SUM(AB39:AE39) -> 0 | AG39: =IF((B39+K39+N39+AA39+AF39)/5=B39,"Todo Bien :D","Algo esta Mal :c") -> Todo Bien :D
A40: Diseño instruccional | B40: 0 | C40: 0 | D40: 0 | E40: 0 | F40: 0 | G40: 0 | H40: 0 | I40: 0 | J40: 0 | K40: =SUM(C40:J40) -> 0 | L40: 0 | M40: 0 | N40: 0 | O40: 0 | P40: 0 | Q40: 0 | R40: 0 | S40: 0 | T40: 0 | U40: 0 | V40: 0 | W40: 0 | X40: 0 | Y40: 0 | Z40: 0 | AA40: =SUM(O40:Z40) -> 0 | AB40: 0 | AC40: 0 | AD40: 0 | AE40: 0 | AF40: =SUM(AB40:AE40) -> 0 | AG40: =IF((B40+K40+N40+AA40+AF40)/5=B40,"Todo Bien :D","Algo esta Mal :c") -> Todo Bien :D
A41: Envío de comunicados a comunidades | B41: 17 | C41: 17 | D41: 0 | E41: 0 | F41: 0 | G41: 0 | H41: 0 | I41: 0 | J41: 0 | K41: 17 | L41: 17 | M41: 0 | N41: =SUM(L41:M41) -> 17 | O41: 0 | P41: 0 | Q41: 0 | R41: 0 | S41: 0 | T41: 0 | U41: 17 | V41: 0 | W41: 0 | X41: 0 | Y41: 0 | Z41: 0 | AA41: =SUM(O41:Z41) -> 17 | AB41: 16 | AC41: 0 | AD41: 1 | AE41: 0 | AF41: =SUM(AB41:AE41) -> 17 | AG41: =IF((B41+K41+N41+AA41+AF41)/5=B41,"Todo Bien :D","Algo esta Mal :c") -> Todo Bien :D
...

Sheet ABRIL
A1: SERVICIO RELACIONADO | C1: TIQUETS POR CANAL | L1: TIPO | O1: ROL USUARIO | AB1: PRIORIDAD
A3: =IF((B51+K51+N51+AA51+AF51)/5=B51,"Todo Bien :D","Algo esta Mal :c") -> Todo Bien :D | B3: Cantidad x Servicio | C3: Chat | D3: Correo | E3: Formulario Web | F3: Facebook | G3: Memorandum | H3: Presencial | I3: Teléfono | J3: Twitter | K3: TOTAL | L3: Solicitud | M3: Incidente | N3: TOTAL | O3: Estudiante | P3: Estudiante FundaTEC | Q3: Estudiante Colegio Científico | R3: Profesor | S3: Profesor FundaTEC | T3: Profesor Colegio Científico | U3: Administrativo | V3: Administrativo FundaTEC | W3: Director/Coordinador | X3: Director/Coordinador FundaTEC | Y3: Director/Coordinador Colegio Ciencífico | Z3: Externo | AA3: TOTAL | AB3: Normal | AC3: Baja | AD3: Alta | AE3: Urgente | AF3: TOTAL | AG3: TOTALES
A4: Acceso a la plataforma TEC Digital | B4: 54 | C4: 0 | D4: 45 | E4: 0 | F4: 0 | G4: 0 | H4: 0 | I4: 9 | J4: 0 | K4: =SUM(C4:J4) -> 54 | L4: 54 | M4: 0 | N4: =SUM(L4:M4) -> 54 | O4: 33 | P4: 3 | Q4: 0 | R4: 12 | S4: 1 | T4: 0 | U4: 2 | V4: 0 | W4: 0 | X4: 0 | Y4: 0 | Z4: 3 | AA4: =SUM(O4:Z4) -> 54 | AB4: 53 | AC4: 1 | AD4: 0 | AE4: 0 | AF4: =SUM(AB4:AE4) -> 54 | AG4: =IF((B4+K4+N4+AA4+AF4)/5=B4,"Todo Bien :D","Algo esta Mal :c") -> Todo Bien :D
A5: Acreditación | B5: 0 | C5: 0 | D5: 0 | E5: 0 | F5: 0 | G5: 0 | H5: 0 | I5: 0 | J5: 0 | K5: =SUM(C5:J5) -> 0 | L5: 0 | M5: 0 | N5: =SUM(L5:M5) -> 0 | O5: 0 | P5: 0 | Q5: 0 | R5: 0 | S5: 0 | T5: 0 | U5: 0 | V5: 0 | W5: 0 | X5: 0 | Y5: 0 | Z5: 0 | AA5: =SUM(O5:Z5) -> 0 | AB5: 0 | AC5: 0 | AD5: 0 | AE5: 0 | AF5: 0 | AG5: =IF((B5+K5+N5+AA5+AF5)/5=B5,"Todo Bien :D","Algo esta Mal :c") -> Todo Bien :D
A6: Activar cuentas de usuario | B6: 7 | C6: 1 | D6: 5 | E6: 0 | F6: 0 | G6: 0 | H6: 0 | I6: 1 | J6: 0 | K6: =SUM(C6:J6) -> 7 | L6: 7 | M6: 0 | N6: =SUM(L6:M6) -> 7 | O6: 4 | P6: 0 | Q6: 0 | R6: 1 | S6: 0 | T6: 0 | U6: 2 | V6: 0 | W6: 0 | X6: 0 | Y6: 0 | Z6: 0 | AA6: =SUM(O6:Z6) -> 7 | AB6: 4 | AC6: 0 | AD6: 2 | AE6: 1 | AF6: =SUM(AB6:AE6) -> 7 | AG6: =IF((B6+K6+N6+AA6+AF6)/5=B6,"Todo Bien :D","Algo esta Mal :c") -> Todo Bien :D
A7: Activar curso | B7: 4 | C7: 0 | D7: 3 | E7: 0 | F7: 0 | G7: 0 | H7: 0 | I7: 1 | J7: 0 | K7: =SUM(C7:J7) -> 4 | L7: 4 | M7: 0 | N7: =SUM(L7:M7) -> 4 | O7: 0 | P7: 0 | Q7: 0 | R7: 1 | S7: 0 | T7: 0 | U7: 2 | V7: 1 | W7: 0 | X7: 0 | Y7: 0 | Z7: 0 | AA7: =SUM(O7:Z7) -> 4 | AB7: 4 | AC7: 0 | AD7: 0 | AE7: 0 | AF7: =SUM(AB7:AE7) -> 4 | AG7: =IF((B7+K7+N7+AA7+AF7)/5=B7,"Todo Bien :D","Algo esta Mal :c") -> Todo Bien :D
A8: Actualizar cursos a estudiantes | B8: 1 | C8: 0 | D8: 1 | E8: 0 | F8: 0 | G8: 0 | H8: 0 | I8: 0 | J8: 0 | K8: =SUM(C8:J8) -> 1 | L8: 1 | M8: 0 | N8: =SUM(L8:M8) -> 1 | O8: 1 | P8: 0 | Q8: 0 | R8: 0 | S8: 0 | T8: 0 | U8: 0 | V8: 0 | W8: 0 | X8: 0 | Y8: 0 | Z8: 0 | AA8: =SUM(O8:Z8) -> 1 | AB8: 1 | AC8: 0 | AD8: 0 | AE8: 0 | AF8: =SUM(AB8:AE8) -> 1 | AG8: =IF((B8+K8+N8+AA8+AF8)/5=B8,"Todo Bien :D","Algo esta Mal :c") -> Todo Bien :D
A9: Actualizar miembros de comunidades | B9: 0 | C9: 0 | D9: 0 | E9: 0 | F9: 0 | G9: 0 | H9: 0 | I9: 0 | J9: 0 | K9: 0 | L9: 0 | M9: 0 | N9: 0 | O9: 0 | P9: 0 | Q9: 0 | S9: 0 | T9: 0 | U9: 0 | V9: 0 | W9: 0 | X9: 0 | Y9: 0 | Z9: 0 | AA9: =SUM(O9:Z9) -> 0 | AB9: 0 | AC9: 0 | AD9: 0 | AE9: 0 | AF9: =SUM(AB9:AE9) -> 0 | AG9: =IF((B9+K9+N9+AA9+AF9)/5=B9,"Todo Bien :D","Algo esta Mal :c") -> Todo Bien :D
A10: Administrador de asistencia | B10: 0 | C10: 0 | D10: 0 | E10: 0 | F10: 0 | G10: 0 | H10: 0 | I10: 0 | J10: 0 | K10: =SUM(C10:J10) -> 0 | L10: 0 | M10: 0 | N10: =SUM(L10:M10) -> 0 | O10: 0 | P10: 0 | Q10: 0 | R10: 0 | S10: 0 | T10: 0 | U10: 0 | V10: 0 | W10: 0 | X10: 0 | Y10: 0 | Z10: 0 | AA10: 0 | AB10: 0 | AC10: 0 | AD10: 0 | AE10: 0 | AF10: 0 | AG10: =IF((B10+K10+N10+AA10+AF10)/5=B10,"Todo Bien :D","Algo esta Mal :c") -> Todo Bien :D
A11: Administrador Programa de Curso | B11: 0 | C11: 0 | D11: 0 | E11: 0 | F11: 0 | G11: 0 | H11: 0 | I11: 0 | J11: 0 | K11: =SUM(C11:J11) -> 0 | L11: 0 | M11: 0 | N11: =SUM(L11:M11) -> 0 | O11: 0 | P11: 0 | Q11: 0 | R11: 0 | S11: 0 | T11: 0 | U11: 0 | V11: 0 | W11: 0 | X11: 0 | Y11: 0 | Z11: 0 | AA11: 0 | AB11: 0 | AC11: 0 | AD11: 0 | AE11: 0 | AF11: 0 | AG11: =IF((B11+K11+N11+AA11+AF11)/5=B11,"Todo Bien :D","Algo esta Mal :c") -> Todo Bien :D
A12: Agregar/cambiar asociación de estudiante a curso | B12: 29 | C12: 2 | D12: 21 | E12: 0 | F12: 0 | G12: 0 | H12: 0 | I12: 6 | J12: 0 | K12: =SUM(C12:J12) -> 29 | L12: 29 | M12: 0 | N12: =SUM(L12:M12) -> 29 | O12: 17 | P12: 0 | Q12: 0 | R12: 5 | S12: 0 | T12: 0 | U12: 4 | V12: 3 | W12: 0 | X12: 0 | Y12: 0 | Z12: 0 | AA12: =SUM(O12:Z12) -> 29 | AB12: 25 | AC12: 1 | AD12: 0 | AE12: 3 | AF12: =SUM(AB12:AE12) -> 29 | AG12: =IF((B12+K12+N12+AA12+AF12)/5=B12,"Todo Bien :D","Algo esta Mal :c") -> Todo Bien :D
A13: Agregar/cambiar asociación de profesor a curso | B13: 10 | C13: 1 | D13: 7 | E13: 0 | F13: 0 | G13: 0 | H13: 0 | I13: 2 | J13: 0 | K13: =SUM(C13:J13) -> 10 | L13: 10 | M13: 0 | N13: =SUM(L13:M13) -> 10 | O13: 0 | P13: 0 | Q13: 0 | R13: 4 | S13: 0 | T13: 0 | U13: 6 | V13: 0 | W13: 0 | X13: 0 | Y13: 0 | Z13: 0 | AA13: =SUM(O13:Z13) -> 10 | AB13: 10 | AC13: 0 | AD13: 0 | AE13: 0 | AF13: =SUM(AB13:AE13) -> 10 | AG13: =IF((B13+K13+N13+AA13+AF13)/5=B13,"Todo Bien :D","Algo esta Mal :c") -> Todo Bien :D
A14: Agregar/cambiar asociación de usuario a comunidad | B14: 12 | C14: 2 | D14: 8 | E14: 0 | F14: 0 | G14: 0 | H14: 0 | I14: 2 | J14: 0 | K14: =SUM(C14:J14) -> 12 | L14: 12 | M14: 0 | N14: =SUM(L14:M14) -> 12 | O14: 3 | P14: 0 | Q14: 0 | R14: 2 | S14: 0 | T14: 0 | U14: 5 | V14: 0 | W14: 2 | X14: 0 | Y14: 0 | Z14: 0 | AA14: =SUM(O14:Z14) -> 12 | AB14: 12 | AC14: 0 | AD14: 0 | AE14: 0 | AF14: =SUM(AB14:AE14) -> 12 | AG14: =IF((B14+K14+N14+AA14+AF14)/5=B14,"Todo Bien :D","Algo esta Mal :c") -> Todo Bien :D
A15: Agregar/cambiar asociación estudiante a curso Colegio Científico | B15: 0 | C15: 0 | D15: 0 | E15: 0 | F15: 0 | G15: 0 | H15: 0 | I15: 0 | J15: 0 | K15: =SUM(C15:J15) -> 0 | L15: 0 | M15: 0 | N15: =SUM(L15:M15) -> 0 | O15: 0 | P15: 0 | Q15: 0 | R15: 0 | S15: 0 | T15: 0 | U15: 0 | V15: 0 | W15: 0 | X15: 0 | Y15: 0 | Z15: 0 | AA15: 0 | AB15: 0 | AC15: 0 | AD15: 0 | AE15: 0 | AF15: 0 | AG15: =IF((B15+K15+N15+AA15+AF15)/5=B15,"Todo Bien :D","Algo esta Mal :c") -> Todo Bien :D
A16: Agregar/cambiar asociación estudiante a curso FundaTEC | B16: 4 | C16: 0 | D16: 4 | E16: 0 | F16: 0 | G16: 0 | H16: 0 | I16: 0 | J16: 0 | K16: =SUM(C16:J16) -> 4 | L16: 4 | M16: 0 | N16: =SUM(L16:M16) -> 4 | O16: 0 | P16: 2 | Q16: 0 | R16: 0 | S16: 0 | T16: 0 | U16: 1 | V16: 1 | W16: 0 | X16: 0 | Y16: 0 | Z16: 0 | AA16: =SUM(O16:Z16) -> 4 | AB16: 3 | AC16: 0 | AD16: 0 | AE16: 1 | AF16: =SUM(AB16:AE16) -> 4 | AG16: =IF((B16+K16+N16+AA16+AF16)/5=B16,"Todo Bien :D","Algo esta Mal :c") -> Todo Bien :D
