Workbook

Sheet Enero
A1: SERVICIO RELACIONADO | C1: TIQUETS POR CANAL | L1: TIPO | O1: ROL USUARIO | AB1: PRIORIDAD | AG1: TOTALES
A3: =IF((B68+K68+N68+AA68+AF68)/5=B68,"Todo Bien :D","Algo esta Mal :c") -> Todo Bien :D | B3: Cantidad x Servicio | C3: Chat | D3: Correo | E3: Formulario Web | F3: Facebook | G3: Memorandum | H3: Presencial | I3: Teléfono | J3: Twitter | K3: TOTAL | L3: Solicitud | M3: Incidente | N3: TOTAL | O3: Estudiante | P3: Estudiante FundaTEC | Q3: Estudiante Colegio Científico | R3: Profesor | S3: Profesor FundaTEC | T3: Profesor Colegio Científico | U3: Administrativo | V3: Administrativo FundaTEC | W3: Director/Coordinador | X3: Director/Coordinador FundaTEC | Y3: Director/Coordinador Colegio Científico | Z3: Externo | AA3: TOTAL | AB3: Normal | AC3: Baja | AD3: Alta | AE3: Urgente | AF3: TOTAL
A4: Acceso a la plataforma TEC Digital | B4: 16 | C4: 0 | D4: 16 | E4: 0 | F4: 0 | G4: 0 | H4: 0 | I4: 0 | J4: 0 | K4: =SUM(C4:J4) -> 16 | L4: 16 | M4: 0 | N4: =SUM(L4:M4) -> 16 | O4: 13 | P4: 1 | Q4: 0 | R4: 1 | S4: 0 | T4: 0 | U4: 0 | V4: 0 | W4: 0 | X4: 0 | Y4: 0 | Z4: 1 | AA4: =SUM(O4:Z4) -> 16 | AB4: 16 | AC4: 0 | AD4: 0 | AE4: 0 | AF4: =SUM(AB4:AE4) -> 16 | AG4: =IF((B4+K4+N4+AA4+AF4)/5=B4,"Todo Bien :D","Algo esta Mal :c") -> Todo Bien :D
A5: Acreditación | B5: 0 | C5: 0 | D5: 0 | E5: 0 | F5: 0 | G5: 0 | H5: 0 | I5: 0 | J5: 0 | K5: =SUM(C5:J5) -> 0 | L5: 0 | M5: 0 | N5: =SUM(L5:M5) -> 0 | O5: 0 | P5: 0 | Q5: 0 | R5: 0 | S5: 0 | T5: 0 | U5: 0 | V5: 0 | W5: 0 | X5: 0 | Y5: 0 | Z5: 0 | AA5: =SUM(O5:Z5) -> 0 | AB5: 0 | AC5: 0 | AD5: 0 | AE5: 0 | AF5: =SUM(AB5:AE5) -> 0 | AG5: =IF((B5+K5+N5+AA5+AF5)/5=B5,"Todo Bien :D","Algo esta Mal :c") -> Todo Bien :D
A6: Activar cuentas de usuario | B6: 1 | C6: 0 | D6: 1 | E6: 0 | F6: 0 | G6: 0 | H6: 0 | I6: 0 | J6: 0 | K6: =SUM(C6:J6) -> 1 | L6: 1 | M6: 0 | N6: =SUM(L6:M6) -> 1 | O6: 0 | P6: 0 | Q6: 0 | R6: 0 | S6: 0 | T6: 0 | U6: 1 | V6: 0 | W6: 0 | X6: 0 | Y6: 0 | Z6: 0 | AA6: =SUM(O6:Z6) -> 1 | AB6: 1 | AC6: 0 | AD6: 0 | AE6: 0 | AF6: =SUM(AB6:AE6) -> 1 | AG6: =IF((B6+K6+N6+AA6+AF6)/5=B6,"Todo Bien :D","Algo esta Mal :c") -> Todo Bien :D
A7: Activar curso | B7: 0 | C7: 0 | D7: 0 | E7: 0 | F7: 0 | G7: 0 | H7: 0 | I7: 0 | J7: 0 | K7: =SUM(C7:J7) -> 0 | L7: 0 | M7: 0 | N7: =SUM(L7:M7) -> 0 | O7: 0 | P7: 0 | Q7: 0 | R7: 0 | S7: 0 | T7: 0 | U7: 0 | V7: 0 | W7: 0 | X7: 0 | Y7: 0 | Z7: 0 | AA7: =SUM(O7:Z7) -> 0 | AB7: 0 | AC7: 0 | AD7: 0 | AE7: 0 | AF7: =SUM(AB7:AE7) -> 0 | AG7: =IF((B7+K7+N7+AA7+AF7)/5=B7,"Todo Bien :D","Algo esta Mal :c") -> Todo Bien :D
A8: Actualizar cursos a estudiantes | B8: 0 | C8: 0 | D8: 0 | E8: 0 | F8: 0 | G8: 0 | H8: 0 | I8: 0 | J8: 0 | K8: =SUM(C8:J8) -> 0 | L8: 0 | M8: 0 | N8: =SUM(L8:M8) -> 0 | O8: 0 | P8: 0 | Q8: 0 | R8: 0 | S8: 0 | T8: 0 | U8: 0 | V8: 0 | W8: 0 | X8: 0 | Y8: 0 | Z8: 0 | AA8: =SUM(O8:Z8) -> 0 | AB8: 0 | AC8: 0 | AD8: 0 | AE8: 0 | AF8: =SUM(AB8:AE8) -> 0 | AG8: =IF((B8+K8+N8+AA8+AF8)/5=B8,"Todo Bien :D","Algo esta Mal :c") -> Todo Bien :D
A9: Actualizar miembros de comunidades | B9: 0 | C9: 0 | D9: 0 | E9: 0 | F9: 0 | G9: 0 | H9: 0 | I9: 0 | J9: 0 | K9: =SUM(C9:J9) -> 0 | L9: 0 | M9: 0 | N9: =SUM(L9:M9) -> 0 | O9: 0 | P9: 0 | Q9: 0 | R9: 0 | S9: 0 | T9: 0 | U9: 0 | V9: 0 | W9: 0 | X9: 0 | Y9: 0 | Z9: 0 | AA9: =SUM(O9:Z9) -> 0 | AB9: 0 | AC9: 0 | AD9: 0 | AE9: 0 | AF9: =SUM(AB9:AE9) -> 0 | AG9: =IF((B9+K9+N9+AA9+AF9)/5=B9,"Todo Bien :D","Algo esta Mal :c") -> Todo Bien :D
A10: Administrador de asistencia | B10: 0 | C10: 0 | D10: 0 | E10: 0 | F10: 0 | G10: 0 | H10: 0 | I10: 0 | J10: 0 | K10: =SUM(C10:J10) -> 0 | L10: 0 | M10: 0 | N10: =SUM(L10:M10) -> 0 | O10: 0 | P10: 0 | Q10: 0 | R10: 0 | S10: 0 | T10: 0 | U10: 0 | V10: 0 | W10: 0 | X10: 0 | Y10: 0 | Z10: 0 | AA10: =SUM(O10:Z10) -> 0 | AB10: 0 | AC10: 0 | AD10: 0 | AE10: 0 | AF10: =SUM(AB10:AE10) -> 0 | AG10: =IF((B10+K10+N10+AA10+AF10)/5=B10,"Todo Bien :D","Algo esta Mal :c") -> Todo Bien :D
A11: Administrador Programa de Curso | B11: 2 | C11: 0 | D11: 2 | E11: 0 | F11: 0 | G11: 0 | H11: 0 | I11: 0 | J11: 0 | K11: =SUM(C11:J11) -> 2 | L11: 2 | M11: 0 | N11: =SUM(L11:M11) -> 2 | O11: 0 | P11: 0 | Q11: 0 | R11: 0 | S11: 0 | T11: 0 | U11: 2 | V11: 0 | W11: 0 | X11: 0 | Y11: 0 | Z11: 0 | AA11: =SUM(O11:Z11) -> 2 | AB11: 2 | AC11: 0 | AD11: 0 | AE11: 0 | AF11: =SUM(AB11:AE11) -> 2 | AG11: =IF((B11+K11+N11+AA11+AF11)/5=B11,"Todo Bien :D","Algo esta Mal :c") -> Todo Bien :D
A12: Agregar/cambiar asociación de estudiante a curso | B12: 19 | C12: 0 | D12: 17 | E12: 0 | F12: 0 | G12: 0 | H12: 0 | I12: 2 | J12: 0 | K12: =SUM(C12:J12) -> 19 | L12: 19 | M12: 0 | N12: =SUM(L12:M12) -> 19 | O12: 9 | P12: 0 | Q12: 0 | R12: 3 | S12: 0 | T12: 0 | U12: 5 | V12: 2 | W12: 0 | X12: 0 | Y12: 0 | Z12: 0 | AA12: =SUM(O12:Z12) -> 19 | AB12: 19 | AC12: 0 | AD12: 0 | AE12: 0 | AF12: =SUM(AB12:AE12) -> 19 | AG12: =IF((B12+K12+N12+AA12+AF12)/5=B12,"Todo Bien :D","Algo esta Mal :c") -> Todo Bien :D
A13: Agregar/cambiar asociación de profesor a curso | B13: 5 | C13: 0 | D13: 5 | E13: 0 | F13: 0 | G13: 0 | H13: 0 | I13: 0 | J13: 0 | K13: =SUM(C13:J13) -> 5 | L13: 5 | M13: 0 | N13: =SUM(L13:M13) -> 5 | O13: 0 | P13: 0 | Q13: 0 | R13: 3 | S13: 0 | T13: 0 | U13: 1 | V13: 0 | W13: 0 | X13: 0 | Y13: 1 | Z13: 0 | AA13: =SUM(O13:Z13) -> 5 | AB13: 5 | AC13: 0 | AD13: 0 | AE13: 0 | AF13: =SUM(AB13:AE13) -> 5 | AG13: =IF((B13+K13+N13+AA13+AF13)/5=B13,"Todo Bien :D","Algo esta Mal :c") -> Todo Bien :D
A14: Agregar/cambiar asociación de usuario a comunidad | B14: 10 | C14: 0 | D14: 9 | E14: 0 | F14: 0 | G14: 0 | H14: 1 | I14: 0 | J14: 0 | K14: =SUM(C14:J14) -> 10 | L14: 10 | M14: 0 | N14: =SUM(L14:M14) -> 10 | O14: 5 | P14: 0 | Q14: 0 | R14: 2 | S14: 0 | T14: 0 | U14: 2 | V14: 0 | W14: 1 | X14: 0 | Y14: 0 | Z14: 0 | AA14: =SUM(O14:Z14) -> 10 | AB14: 10 | AC14: 0 | AD14: 0 | AE14: 0 | AF14: =SUM(AB14:AE14) -> 10 | AG14: =IF((B14+K14+N14+AA14+AF14)/5=B14,"Todo Bien :D","Algo esta Mal :c") -> Todo Bien :D
A15: Agregar/cambiar asociación estudiante a curso Colegio Científico | B15: 0 | C15: 0 | D15: 0 | E15: 0 | F15: 0 | G15: 0 | H15: 0 | I15: 0 | J15: 0 | K15: =SUM(C15:J15) -> 0 | L15: 0 | M15: 0 | N15: =SUM(L15:M15) -> 0 | O15: 0 | P15: 0 | Q15: 0 | R15: 0 | S15: 0 | T15: 0 | U15: 0 | V15: 0 | W15: 0 | X15: 0 | Y15: 0 | Z15: 0 | AA15: =SUM(O15:Z15) -> 0 | AB15: 0 | AC15: 0 | AD15: 0 | AE15: 0 | AF15: =SUM(AB15:AE15) -> 0 | AG15: =IF((B15+K15+N15+AA15+AF15)/5=B15,"Todo Bien :D","Algo esta Mal :c") -> Todo Bien :D
... A67: Solicitud de información de la plataforma | B67: 0 | C67: 0 | D67: 0 | E67: 0 | F67: 0 | G67: 0 | H67: 0 | I67: 0 | J67: 0 | K67: =SUM(C67:J67) -> 0 | L67: 0 | M67: 0 | N67: =SUM(L67:M67) -> 0 | O67: 0 | P67: 0 | Q67: 0 | R67: 0 | S67: 0 | T67: 0 | U67: 0 | V67: 0 | W67: 0 | X67: 0 | Y67: 0 | Z67: 0 | AA67: =SUM(O67:Z67) -> 0 | AB67: 0 | AC67: 0 | AD67: 0 | AE67: 0 | AF67: =SUM(AB67:AE67) -> 0 | AG67: =IF((B67+K67+N67+AA67+AF67)/5=B67,"Todo Bien :D","Algo esta Mal :c") -> Todo Bien :D
A68: TOTAL | B68: =SUM(B4:B67) -> 138 | C68: =SUM(C3:C67) -> 0 | D68: =SUM(D3:D67) -> 94 | E68: =SUM(E3:E67) -> 39 | F68: =SUM(F3:F67) -> 0 | G68: =SUM(G3:G67) -> 0 | H68: =SUM(H3:H67) -> 2 | I68: =SUM(I3:I67) -> 3 | J68: =SUM(J3:J67) -> 0 | K68: =SUM(C68:J68) -> 138 | L68: =SUM(L3:L67) -> 138 | M68: =SUM(M3:M67) -> 0 | N68: =SUM(L68:M68) -> 138 | O68: =SUM(O3:O67) -> 55 | P68: =SUM(P3:P67) -> 8 | Q68: =SUM(Q3:Q67) -> 0 | R68: =SUM(R3:R67) -> 22 | S68: =SUM(S3:S67) -> 2 | T68: =SUM(T3:T67) -> 0 | U68: =SUM(U3:U67) -> 28 | V68: =SUM(V3:V67) -> 13 | ... Z68: =SUM(Z3:Z67) -> 5 | AA68: =SUM(O68:Z68) -> 138 | AB68: =SUM(AB3:AB67) -> 138 | AC68: =SUM(AC3:AC67) -> 0 | AD68: =SUM(AD3:AD67) -> 0 | AE68: =SUM(AE3:AE67) -> 0 | AF68: =SUM(AB68:AE68) -> 138 | AG68: =IF((B68+K68+N68+AA68+AF68)/5=B68,"Todo Bien :D","Algo esta Mal :c") -> Todo Bien :D

Sheet Febrero
A1: SERVICIO RELACIONADO | C1: TIQUETS POR CANAL | L1: TIPO | O1: ROL USUARIO | AB1: PRIORIDAD | AG1: TOTALES
A3: =IF((B68+K68+N68+AA68+AF68)/5=B68,"Todo Bien :D","Algo esta Mal :c") -> Todo Bien :D | B3: Cantidad x Servicio | C3: Chat | D3: Correo | E3: Formulario Web | F3: Facebook | G3: Memorandum | H3: Presencial | I3: Teléfono | J3: Twitter | K3: TOTAL | L3: Solicitud | M3: Incidente | N3: TOTAL | O3: Estudiante | P3: Estudiante FundaTEC | Q3: Estudiante Colegio Científico | R3: Profesor | S3: Profesor FundaTEC | T3: Profesor Colegio Científico | U3: Administrativo | V3: Administrativo FundaTEC | W3: Director/Coordinador | X3: Director/Coordinador FundaTEC | Y3: Director/Coordinador Colegio Científico | Z3: Externo | AA3: TOTAL | AB3: Normal | AC3: Baja | AD3: Alta | AE3: Urgente | AF3: TOTAL
A4: Acceso a la plataforma TEC Digital | B4: 55 | C4: 0 | D4: 55 | E4: 0 | F4: 0 | G4: 0 | H4: 0 | I4: 0 | J4: 0 | K4: =SUM(C4:J4) -> 55 | L4: 55 | M4: 0 | N4: =SUM(L4:M4) -> 55 | O4: 43 | P4: 0 | Q4: 0 | R4: 3 | S4: 0 | T4: 0 | U4: 2 | V4: 1 | W4: 1 | X4: 0 | Y4: 0 | Z4: 5 | AA4: =SUM(O4:Z4) -> 55 | AB4: 55 | AC4: 0 | AD4: 0 | AE4: 0 | AF4: =SUM(AB4:AE4) -> 55 | AG4: =IF((B4+K4+N4+AA4+AF4)/5=B4,"Todo Bien :D","Algo esta Mal :c") -> Todo Bien :D
A5: Acreditación | B5: 0 | C5: 0 | D5: 0 | E5: 0 | F5: 0 | G5: 0 | H5: 0 | I5: 0 | J5: 0 | K5: =SUM(C5:J5) -> 0 | L5: 0 | M5: 0 | N5: =SUM(L5:M5) -> 0 | O5: 0 | P5: 0 | Q5: 0 | R5: 0 | S5: 0 | T5: 0 | U5: 0 | V5: 0 | W5: 0 | X5: 0 | Y5: 0 | Z5: 0 | AA5: =SUM(O5:Z5) -> 0 | AB5: 0 | AC5: 0 | AD5: 0 | AE5: 0 | AF5: =SUM(AB5:AE5) -> 0 | AG5: =IF((B5+K5+N5+AA5+AF5)/5=B5,"Todo Bien :D","Algo esta Mal :c") -> Todo Bien :D
A6: Activar cuentas de usuario | B6: 17 | C6: 0 | D6: 17 | E6: 0 | F6: 0 | G6: 0 | H6: 0 | I6: 0 | J6: 0 | K6: =SUM(C6:J6) -> 17 | L6: 17 | M6: 0 | N6: =SUM(L6:M6) -> 17 | O6: 2 | P6: 0 | Q6: 0 | R6: 10 | S6: 0 | T6: 0 | U6: 4 | V6: 1 | W6: 0 | X6: 0 | Y6: 0 | Z6: 0 | AA6: =SUM(O6:Z6) -> 17 | AB6: 17 | AC6: 0 | AD6: 0 | AE6: 0 | AF6: =SUM(AB6:AE6) -> 17 | AG6: =IF((B6+K6+N6+AA6+AF6)/5=B6,"Todo Bien :D","Algo esta Mal :c") -> Todo Bien :D
A7: Activar curso | B7: 0 | C7: 0 | D7: 0 | E7: 0 | F7: 0 | G7: 0 | H7: 0 | I7: 0 | J7: 0 | K7: =SUM(C7:J7) -> 0 | L7: 0 | M7: 0 | N7: =SUM(L7:M7) -> 0 | O7: 0 | P7: 0 | Q7: 0 | R7: 0 | S7: 0 | T7: 0 | U7: 0 | V7: 0 | W7: 0 | X7: 0 | Y7: 0 | Z7: 0 | AA7: =SUM(O7:Z7) -> 0 | AB7: 0 | AC7: 0 | AD7: 0 | AE7: 0 | AF7: =SUM(AB7:AE7) -> 0 | AG7: =IF((B7+K7+N7+AA7+AF7)/5=B7,"Todo Bien :D","Algo esta Mal :c") -> Todo Bien :D
A8: Actualizar cursos a estudiantes | B8: 4 | C8: 1 | D8: 3 | E8: 0 | F8: 0 | G8: 0 | H8: 0 | I8: 0 | J8: 0 | K8: =SUM(C8:J8) -> 4 | L8: 1 | M8: 3 | N8: =SUM(L8:M8) -> 4 | O8: 4 | P8: 0 | Q8: 0 | R8: 0 | S8: 0 | T8: 0 | U8: 0 | V8: 0 | W8: 0 | X8: 0 | Y8: 0 | Z8: 0 | AA8: =SUM(O8:Z8) -> 4 | AB8: 4 | AC8: 0 | AD8: 0 | AE8: 0 | AF8: =SUM(AB8:AE8) -> 4 | AG8: =IF((B8+K8+N8+AA8+AF8)/5=B8,"Todo Bien :D","Algo esta Mal :c") -> Todo Bien :D
A9: Actualizar miembros de comunidades | B9: 22 | C9: 2 | D9: 19 | E9: 0 | F9: 0 | G9: 0 | H9: 1 | I9: 0 | J9: 0 | K9: =SUM(C9:J9) -> 22 | L9: 22 | M9: 0 | N9: =SUM(L9:M9) -> 22 | O9: 2 | P9: 0 | Q9: 0 | R9: 16 | S9: 0 | T9: 0 | U9: 0 | V9: 0 | W9: 4 | X9: 0 | Y9: 0 | Z9: 0 | AA9: =SUM(O9:Z9) -> 22 | AB9: 22 | AC9: 0 | AD9: 0 | AE9: 0 | AF9: =SUM(AB9:AE9) -> 22 | AG9: =IF((B9+K9+N9+AA9+AF9)/5=B9,"Todo Bien :D","Algo esta Mal :c") -> Todo Bien :D
A10: Administrador de asistencia | B10: 0 | C10: 0 | D10: 0 | E10: 0 | F10: 0 | G10: 0 | H10: 0 | I10: 0 | J10: 0 | K10: =SUM(C10:J10) -> 0 | L10: 0 | M10: 0 | N10: =SUM(L10:M10) -> 0 | O10: 0 | P10: 0 | Q10: 0 | R10: 0 | S10: 0 | T10: 0 | U10: 0 | V10: 0 | W10: 0 | X10: 0 | Y10: 0 | Z10: 0 | AA10: =SUM(O10:Z10) -> 0 | AB10: 0 | AC10: 0 | AD10: 0 | AE10: 0 | AF10: =SUM(AB10:AE10) -> 0 | AG10: =IF((B10+K10+N10+AA10+AF10)/5=B10,"Todo Bien :D","Algo esta Mal :c") -> Todo Bien :D
A11: Administrador Programa de Curso | B11: 2 | C11: 0 | D11: 2 | E11: 0 | F11: 0 | G11: 0 | H11: 0 | I11: 0 | J11: 0 | K11: =SUM(C11:J11) -> 2 | L11: 2 | M11: 0 | N11: =SUM(L11:M11) -> 2 | O11: 0 | P11: 0 | Q11: 0 | R11: 2 | S11: 0 | T11: 0 | U11: 0 | V11: 0 | W11: 0 | X11: 0 | Y11: 0 | Z11: 0 | AA11: =SUM(O11:Z11) -> 2 | AB11: 2 | AC11: 0 | AD11: 0 | AE11: 0 | AF11: =SUM(AB11:AE11) -> 2 | AG11: =IF((B11+K11+N11+AA11+AF11)/5=B11,"Todo Bien :D","Algo esta Mal :c") -> Todo Bien :D
A12: Agregar/cambiar asociación de estudiante a curso | B12: 50 | C12: 0 | D12: 43 | E12: 0 | F12: 0 | G12: 0 | H12: 7 | I12: 0 | J12: 0 | K12: =SUM(C12:J12) -> 50 | L12: 50 | M12: 0 | N12: =SUM(L12:M12) -> 50 | O12: 35 | P12: 0 | Q12: 0 | R12: 9 | S12: 0 | T12: 0 | U12: 3 | V12: 1 | W12: 2 | X12: 0 | Y12: 0 | Z12: 0 | AA12: =SUM(O12:Z12) -> 50 | AB12: 50 | AC12: 0 | AD12: 0 | AE12: 0 | AF12: =SUM(AB12:AE12) -> 50 | AG12: =IF((B12+K12+N12+AA12+AF12)/5=B12,"Todo Bien :D","Algo esta Mal :c") -> Todo Bien :D
A13: Agregar/cambiar asociación de profesor a curso | B13: 65 | C13: 3 | D13: 55 | E13: 0 | F13: 0 | G13: 0 | H13: 3 | I13: 4 | J13: 0 | K13: =SUM(C13:J13) -> 65 | L13: 65 | M13: 0 | N13: =SUM(L13:M13) -> 65 | O13: 1 | P13: 0 | Q13: 0 | R13: 41 | S13: 0 | T13: 0 | U13: 17 | V13: 0 | W13: 6 | X13: 0 | Y13: 0 | Z13: 0 | AA13: =SUM(O13:Z13) -> 65 | AB13: 63 | AC13: 0 | AD13: 0 | AE13: 2 | AF13: =SUM(AB13:AE13) -> 65 | AG13: =IF((B13+K13+N13+AA13+AF13)/5=B13,"Todo Bien :D","Algo esta Mal :c") -> Todo Bien :D
A14: Agregar/cambiar asociación de usuario a comunidad | B14: 50 | C14: 0 | D14: 37 | E14: 0 | F14: 0 | G14: 0 | H14: 10 | I14: 3 | J14: 0 | K14: =SUM(C14:J14) -> 50 | L14: 50 | M14: 0 | N14: =SUM(L14:M14) -> 50 | O14: 27 | P14: 0 | Q14: 0 | R14: 16 | S14: 0 | T14: 0 | U14: 4 | V14: 0 | W14: 3 | X14: 0 | Y14: 0 | Z14: 0 | AA14: =SUM(O14:Z14) -> 50 | AB14: 50 | AC14: 0 | AD14: 0 | AE14: 0 | AF14: =SUM(AB14:AE14) -> 50 | AG14: =IF((B14+K14+N14+AA14+AF14)/5=B14,"Todo Bien :D","Algo esta Mal :c") -> Todo Bien :D
A15: Agregar/cambiar asociación estudiante a curso Colegio Científico | B15: 0 | C15: 0 | D15: 0 | E15: 0 | F15: 0 | G15: 0 | H15: 0 | I15: 0 | J15: 0 | K15: =SUM(C15:J15) -> 0 | L15: 0 | M15: 0 | N15: =SUM(L15:M15) -> 0 | O15: 0 | P15: 0 | Q15: 0 | R15: 0 | S15: 0 | T15: 0 | U15: 0 | V15: 0 | W15: 0 | X15: 0 | Y15: 0 | Z15: 0 | AA15: =SUM(O15:Z15) -> 0 | AB15: 0 | AC15: 0 | AD15: 0 | AE15: 0 | AF15: =SUM(AB15:AE15) -> 0 | AG15: =IF((B15+K15+N15+AA15+AF15)/5=B15,"Todo Bien :D","Algo esta Mal :c") -> Todo Bien :D
... A67: Solicitud de información de la plataforma | B67: 2 | C67: 0 | D67: 2 | E67: 0 | F67: 0 | G67: 0 | H67: 0 | I67: 0 | J67: 0 | K67: =SUM(C67:J67) -> 2 | L67: 2 | M67: 0 | N67: =SUM(L67:M67) -> 2 | O67: 0 | P67: 0 | Q67: 0 | R67: 1 | S67: 0 | T67: 0 | U67: 0 | V67: 0 | W67: 1 | X67: 0 | Y67: 0 | Z67: 0 | AA67: =SUM(O67:Z67) -> 2 | AB67: 2 | AC67: 0 | AD67: 0 | AE67: 0 | AF67: =SUM(AB67:AE67) -> 2 | AG67: =IF((B67+K67+N67+AA67+AF67)/5=B67,"Todo Bien :D","Algo esta Mal :c") -> Todo Bien :D
A68: TOTAL | B68: =SUM(B4:B67) -> 526 | C68: =SUM(C3:C67) -> 8 | D68: =SUM(D3:D67) -> 483 | E68: =SUM(E3:E67) -> 0 | F68: =SUM(F3:F67) -> 0 | G68: =SUM(G3:G67) -> 0 | H68: =SUM(H3:H67) -> 25 | I68: =SUM(I3:I67) -> 10 | J68: =SUM(J3:J67) -> 0 | K68: =SUM(C68:J68) -> 526 | L68: =SUM(L3:L67) -> 522 | M68: =SUM(M3:M67) -> 4 | N68: =SUM(L68:M68) -> 526 | O68: =SUM(O3:O67) -> 219 | P68: =SUM(P3:P67) -> 5 | Q68: =SUM(Q3:Q67) -> 0 | R68: =SUM(R3:R67) -> 172 | S68: =SUM(S3:S67) -> 2 | T68: =SUM(T3:T67) -> 0 | U68: =SUM(U3:U67) -> 74 | V68: =SUM(V3:V67) -> 25 | ... Z68: =SUM(Z3:Z67) -> 8 | AA68: =SUM(O68:Z68) -> 526 | AB68: =SUM(AB3:AB67) -> 521 | AC68: =SUM(AC3:AC67) -> 0 | AD68: =SUM(AD3:AD67) -> 2 | AE68: =SUM(AE3:AE67) -> 3 | AF68: =SUM(AB68:AE68) -> 526 | AG68: =IF((B68+K68+N68+AA68+AF68)/5=B68,"Todo Bien :D","Algo esta Mal :c") -> Todo Bien :D

Sheet Marzo
A1: SERVICIO RELACIONADO | C1: TIQUETS POR CANAL | L1: TIPO | O1: ROL USUARIO | AB1: PRIORIDAD | AG1: TOTALES
A3: =IF((B68+K68+N68+AA68+AF68)/5=B68,"Todo Bien :D","Algo esta Mal :c") -> Todo Bien :D | B3: Cantidad x Servicio | C3: Chat | D3: Correo | E3: Formulario Web | F3: Facebook | G3: Memorandum | H3: Presencial | I3: Teléfono | J3: Twitter | K3: TOTAL | L3: Solicitud | M3: Incidente | N3: TOTAL | O3: Estudiante | P3: Estudiante FundaTEC | Q3: Estudiante Colegio Científico | R3: Profesor | S3: Profesor FundaTEC | T3: Profesor Colegio Científico | U3: Administrativo | V3: Administrativo FundaTEC | W3: Director/Coordinador | X3: Director/Coordinador FundaTEC | Y3: Director/Coordinador Colegio Científico | Z3: Externo | AA3: TOTAL | AB3: Normal | AC3: Baja | AD3: Alta | AE3: Urgente | AF3: TOTAL
A4: Acceso a la plataforma TEC Digital | B4: 49 | C4: 1 | D4: 48 | E4: 0 | F4: 0 | G4: 0 | H4: 0 | I4: 0 | J4: 0 | K4: =SUM(C4:J4) -> 49 | L4: 49 | M4: 0 | N4: =SUM(L4:M4) -> 49 | O4: 29 | P4: 3 | Q4: 0 | R4: 3 | S4: 0 | T4: 0 | U4: 7 | V4: 4 | W4: 1 | X4: 0 | Y4: 0 | Z4: 2 | AA4: =SUM(O4:Z4) -> 49 | AB4: 48 | AC4: 0 | AD4: 1 | AE4: 0 | AF4: =SUM(AB4:AE4) -> 49 | AG4: =IF((B4+K4+N4+AA4+AF4)/5=B4,"Todo Bien :D","Algo esta Mal :c") -> Todo Bien :D
A5: Acreditación | B5: 0 | C5: 0 | D5: 0 | E5: 0 | F5: 0 | G5: 0 | H5: 0 | I5: 0 | J5: 0 | K5: =SUM(C5:J5) -> 0 | L5: 0 | M5: 0 | N5: =SUM(L5:M5) -> 0 | O5: 0 | P5: 0 | Q5: 0 | R5: 0 | S5: 0 | T5: 0 | U5: 0 | V5: 0 | W5: 0 | X5: 0 | Y5: 0 | Z5: 0 | AA5: =SUM(O5:Z5) -> 0 | AB5: 0 | AC5: 0 | AD5: 0 | AE5: 0 | AF5: =SUM(AB5:AE5) -> 0 | AG5: =IF((B5+K5+N5+AA5+AF5)/5=B5,"Todo Bien :D","Algo esta Mal :c") -> Todo Bien :D
A6: Activar cuentas de usuario | B6: 9 | C6: 0 | D6: 7 | E6: 0 | F6: 0 | G6: 0 | H6: 0 | I6: 2 | J6: 0 | K6: =SUM(C6:J6) -> 9 | L6: 9 | M6: 0 | N6: =SUM(L6:M6) -> 9 | O6: 5 | P6: 0 | Q6: 0 | R6: 0 | S6: 0 | T6: 0 | U6: 3 | V6: 1 | W6: 0 | X6: 0 | Y6: 0 | Z6: 0 | AA6: =SUM(O6:Z6) -> 9 | AB6: 9 | AC6: 0 | AD6: 0 | AE6: 0 | AF6: =SUM(AB6:AE6) -> 9 | AG6: =IF((B6+K6+N6+AA6+AF6)/5=B6,"Todo Bien :D","Algo esta Mal :c") -> Todo Bien :D
A7: Activar curso | B7: 0 | C7: 0 | D7: 0 | E7: 0 | F7: 0 | G7: 0 | H7: 0 | I7: 0 | J7: 0 | K7: =SUM(C7:J7) -> 0 | L7: 0 | M7: 0 | N7: =SUM(L7:M7) -> 0 | O7: 0 | P7: 0 | Q7: 0 | R7: 0 | S7: 0 | T7: 0 | U7: 0 | V7: 0 | W7: 0 | X7: 0 | Y7: 0 | Z7: 0 | AA7: =SUM(O7:Z7) -> 0 | AB7: 0 | AC7: 0 | AD7: 0 | AE7: 0 | AF7: =SUM(AB7:AE7) -> 0 | AG7: =IF((B7+K7+N7+AA7+AF7)/5=B7,"Todo Bien :D","Algo esta Mal :c") -> Todo Bien :D
A8: Actualizar cursos a estudiantes | B8: 11 | C8: 0 | D8: 11 | E8: 0 | F8: 0 | G8: 0 | H8: 0 | I8: 0 | J8: 0 | K8: =SUM(C8:J8) -> 11 | L8: 9 | M8: 2 | N8: =SUM(L8:M8) -> 11 | O8: 7 | P8: 0 | Q8: 0 | R8: 3 | S8: 0 | T8: 0 | U8: 0 | V8: 1 | W8: 0 | X8: 0 | Y8: 0 | Z8: 0 | AA8: =SUM(O8:Z8) -> 11 | AB8: 10 | AC8: 0 | AD8: 1 | AE8: 0 | AF8: =SUM(AB8:AE8) -> 11 | AG8: =IF((B8+K8+N8+AA8+AF8)/5=B8,"Todo Bien :D","Algo esta Mal :c") -> Todo Bien :D
A9: Actualizar miembros de comunidades | B9: 12 | C9: 0 | D9: 11 | E9: 0 | F9: 0 | G9: 0 | H9: 0 | I9: 1 | J9: 0 | K9: =SUM(C9:J9) -> 12 | L9: 12 | M9: 0 | N9: =SUM(L9:M9) -> 12 | O9: 5 | P9: 0 | Q9: 0 | R9: 4 | S9: 0 | T9: 0 | U9: 3 | V9: 0 | W9: 0 | X9: 0 | Y9: 0 | Z9: 0 | AA9: =SUM(O9:Z9) -> 12 | AB9: 12 | AC9: 0 | AD9: 0 | AE9: 0 | AF9: =SUM(AB9:AE9) -> 12 | AG9: =IF((B9+K9+N9+AA9+AF9)/5=B9,"Todo Bien :D","Algo esta Mal :c") -> Todo Bien :D
A10: Administrador de asistencia | B10: 0 | C10: 0 | D10: 0 | E10: 0 | F10: 0 | G10: 0 | H10: 0 | I10: 0 | J10: 0 | K10: =SUM(C10:J10) -> 0 | L10: 0 | M10: 0 | N10: =SUM(L10:M10) -> 0 | O10: 0 | P10: 0 | Q10: 0 | R10: 0 | S10: 0 | T10: 0 | U10: 0 | V10: 0 | W10: 0 | X10: 0 | Y10: 0 | Z10: 0 | AA10: =SUM(O10:Z10) -> 0 | AB10: 0 | AC10: 0 | AD10: 0 | AE10: 0 | AF10: =SUM(AB10:AE10) -> 0 | AG10: =IF((B10+K10+N10+AA10+AF10)/5=B10,"Todo Bien :D","Algo esta Mal :c") -> Todo Bien :D
A11: Administrador Programa de Curso | B11: 0 | C11: 0 | D11: 0 | E11: 0 | F11: 0 | G11: 0 | H11: 0 | I11: 0 | J11: 0 | K11: =SUM(C11:J11) -> 0 | L11: 0 | M11: 0 | N11: =SUM(L11:M11) -> 0 | O11: 0 | P11: 0 | Q11: 0 | R11: 0 | S11: 0 | T11: 0 | U11: 0 | V11: 0 | W11: 0 | X11: 0 | Y11: 0 | Z11: 0 | AA11: =SUM(O11:Z11) -> 0 | AB11: 0 | AC11: 0 | AD11: 0 | AE11: 0 | AF11: =SUM(AB11:AE11) -> 0 | AG11: =IF((B11+K11+N11+AA11+AF11)/5=B11,"Todo Bien :D","Algo esta Mal :c") -> Todo Bien :D
A12: Agregar/cambiar asociación de estudiante a curso | B12: 43 | C12: 1 | D12: 31 | E12: 0 | F12: 0 | G12: 0 | H12: 9 | I12: 2 | J12: 0 | K12: =SUM(C12:J12) -> 43 | L12: 43 | M12: 0 | N12: =SUM(L12:M12) -> 43 | O12: 19 | P12: 0 | Q12: 0 | R12: 5 | S12: 1 | T12: 0 | U12: 17 | V12: 1 | W12: 0 | X12: 0 | Y12: 0 | Z12: 0 | AA12: =SUM(O12:Z12) -> 43 | AB12: 43 | AC12: 0 | AD12: 0 | AE12: 0 | AF12: =SUM(AB12:AE12) -> 43 | AG12: =IF((B12+K12+N12+AA12+AF12)/5=B12,"Todo Bien :D","Algo esta Mal :c") -> Todo Bien :D
A13: Agregar/cambiar asociación de profesor a curso | B13: 18 | C13: 1 | D13: 17 | E13: 0 | F13: 0 | G13: 0 | H13: 0 | I13: 0 | J13: 0 | K13: =SUM(C13:J13) -> 18 | L13: 17 | M13: 1 | N13: =SUM(L13:M13) -> 18 | O13: 1 | P13: 0 | Q13: 0 | R13: 13 | S13: 0 | T13: 0 | U13: 3 | V13: 0 | W13: 1 | X13: 0 | Y13: 0 | Z13: 0 | AA13: =SUM(O13:Z13) -> 18 | AB13: 17 | AC13: 0 | AD13: 0 | AE13: 1 | AF13: =SUM(AB13:AE13) -> 18 | AG13: =IF((B13+K13+N13+AA13+AF13)/5=B13,"Todo Bien :D","Algo esta Mal :c") -> Todo Bien :D
A14: Agregar/cambiar asociación de usuario a comunidad | B14: 18 | C14: 0 | D14: 17 | E14: 0 | F14: 0 | G14: 0 | H14: 0 | I14: 1 | J14: 0 | K14: =SUM(C14:J14) -> 18 | L14: 18 | M14: 0 | N14: =SUM(L14:M14) -> 18 | O14: 10 | P14: 0 | Q14: 0 | R14: 6 | S14: 0 | T14: 0 | U14: 1 | V14: 0 | W14: 1 | X14: 0 | Y14: 0 | Z14: 0 | AA14: =SUM(O14:Z14) -> 18 | AB14: 18 | AC14: 0 | AD14: 0 | AE14: 0 | AF14: =SUM(AB14:AE14) -> 18 | AG14: =IF((B14+K14+N14+AA14+AF14)/5=B14,"Todo Bien :D","Algo esta Mal :c") -> Todo Bien :D
A15: Agregar/cambiar asociación estudiante a curso Colegio Científico | B15: 0 | C15: 0 | D15: 0 | E15: 0 | F15: 0 | G15: 0 | H15: 0 | I15: 0 | J15: 0 | K15: =SUM(C15:J15) -> 0 | L15: 0 | M15: 0 | N15: =SUM(L15:M15) -> 0 | O15: 0 | P15: 0 | Q15: 0 | R15: 0 | S15: 0 | T15: 0 | U15: 0 | V15: 0 | W15: 0 | X15: 0 | Y15: 0 | Z15: 0 | AA15: =SUM(O15:Z15) -> 0 | AB15: 0 | AC15: 0 | AD15: 0 | AE15: 0 | AF15: =SUM(AB15:AE15) -> 0 | AG15: =IF((B15+K15+N15+AA15+AF15)/5=B15,"Todo Bien :D","Algo esta Mal :c") -> Todo Bien :D
... A67: Solicitud de información de la plataforma | B67: 1 | C67: 0 | D67: 1 | E67: 0 | F67: 0 | G67: 0 | H67: 0 | I67: 0 | J67: 0 | K67: =SUM(C67:J67) -> 1 | L67: 1 | M67: 0 | N67: =SUM(L67:M67) -> 1 | O67: 1 | P67: 0 | Q67: 0 | R67: 0 | S67: 0 | T67: 0 | U67: 0 | V67: 0 | W67: 0 | X67: 0 | Y67: 0 | Z67: 0 | AA67: =SUM(O67:Z67) -> 1 | AB67: 1 | AC67: 0 | AD67: 0 | AE67: 0 | AF67: =SUM(AB67:AE67) -> 1 | AG67: =IF((B67+K67+N67+AA67+AF67)/5=B67,"Todo Bien :D","Algo esta Mal :c") -> Todo Bien :D
A68: TOTAL | B68: =SUM(B4:B67) -> 419 | C68: =SUM(C3:C67) -> 4 | D68: =SUM(D3:D67) -> 397 | E68: =SUM(E3:E67) -> 0 | F68: =SUM(F3:F67) -> 0 | G68: =SUM(G3:G67) -> 0 | H68: =SUM(H3:H67) -> 11 | I68: =SUM(I3:I67) -> 7 | J68: =SUM(J3:J67) -> 0 | K68: =SUM(C68:J68) -> 419 | L68: =SUM(L3:L67) -> 414 | M68: =SUM(M3:M67) -> 5 | N68: =SUM(L68:M68) -> 419 | O68: =SUM(O3:O67) -> 156 | P68: =SUM(P3:P67) -> 6 | Q68: =SUM(Q3:Q67) -> 0 | R68: =SUM(R3:R67) -> 80 | S68: =SUM(S3:S67) -> 4 | T68: =SUM(T3:T67) -> 0 | U68: =SUM(U3:U67) -> 94 | V68: =SUM(V3:V67) -> 70 | ... Z68: =SUM(Z3:Z67) -> 4 | AA68: =SUM(O68:Z68) -> 419 | AB68: =SUM(AB3:AB67) -> 412 | AC68: =SUM(AC3:AC67) -> 0 | AD68: =SUM(AD3:AD67) -> 2 | AE68: =SUM(AE3:AE67) -> 5 | AF68: =SUM(AB68:AE68) -> 419 | AG68: =IF((B68+K68+N68+AA68+AF68)/5=B68,"Todo Bien :D","Algo esta Mal :c") -> Todo Bien :D

Sheet Abril
A1: SERVICIO RELACIONADO | C1: TIQUETS POR CANAL | L1: TIPO | O1: ROL USUARIO | AB1: PRIORIDAD | AG1: TOTALES
A3: =IF((B68+K68+N68+AA68+AF68)/5=B68,"Todo Bien :D","Algo esta Mal :c") -> Todo Bien :D | B3: Cantidad x Servicio | C3: Chat | D3: Correo | E3: Formulario Web | F3: Facebook | G3: Memorandum | H3: Presencial | I3: Teléfono | J3: Twitter | K3: TOTAL | L3: Solicitud | M3: Incidente | N3: TOTAL | O3: Estudiante | P3: Estudiante FundaTEC | Q3: Estudiante Colegio Científico | R3: Profesor | S3: Profesor FundaTEC | T3: Profesor Colegio Científico | U3: Administrativo | V3: Administrativo FundaTEC | W3: Director/Coordinador | X3: Director/Coordinador FundaTEC | Y3: Director/Coordinador Colegio Científico | Z3: Externo | AA3: TOTAL | AB3: Normal | AC3: Baja | AD3: Alta | AE3: Urgente | AF3: TOTAL
A4: Acceso a la plataforma TEC Digital | B4: 28 | C4: 0 | D4: 28 | E4: 0 | F4: 0 | G4: 0 | H4: 0 | I4: 0 | J4: 0 | K4: =SUM(C4:J4) -> 28 | L4: 27 | M4: 1 | N4: =SUM(L4:M4) -> 28 | O4: 16 | P4: 0 | Q4: 0 | R4: 5 | S4: 0 | T4: 0 | U4: 4 | V4: 3 | W4: 0 | X4: 0 | Y4: 0 | Z4: 0 | AA4: =SUM(O4:Z4) -> 28 | AB4: 28 | AC4: 0 | AD4: 0 | AE4: 0 | AF4: =SUM(AB4:AE4) -> 28 | AG4: =IF((B4+K4+N4+AA4+AF4)/5=B4,"Todo Bien :D","Algo esta Mal :c") -> Todo Bien :D
A5: Acreditación | B5: 0 | C5: 0 | D5: 0 | E5: 0 | F5: 0 | G5: 0 | H5: 0 | I5: 0 | J5: 0 | K5: =SUM(C5:J5) -> 0 | L5: 0 | M5: 0 | N5: =SUM(L5:M5) -> 0 | O5: 0 | P5: 0 | Q5: 0 | R5: 0 | S5: 0 | T5: 0 | U5: 0 | V5: 0 | W5: 0 | X5: 0 | Y5: 0 | Z5: 0 | AA5: =SUM(O5:Z5) -> 0 | AB5: 0 | AC5: 0 | AD5: 0 | AE5: 0 | AF5: =SUM(AB5:AE5) -> 0 | AG5: =IF((B5+K5+N5+AA5+AF5)/5=B5,"Todo Bien :D","Algo esta Mal :c") -> Todo Bien :D
A6: Activar cuentas de usuario | B6: 2 | C6: 1 | D6: 0 | E6: 0 | F6: 0 | G6: 0 | H6: 0 | I6: 1 | J6: 0 | K6: =SUM(C6:J6) -> 2 | L6: 2 | M6: 0 | N6: =SUM(L6:M6) -> 2 | O6: 1 | P6: 0 | Q6: 0 | R6: 1 | S6: 0 | T6: 0 | U6: 0 | V6: 0 | W6: 0 | X6: 0 | Y6: 0 | Z6: 0 | AA6: =SUM(O6:Z6) -> 2 | AB6: 2 | AC6: 0 | AD6: 0 | AE6: 0 | AF6: =SUM(AB6:AE6) -> 2 | AG6: =IF((B6+K6+N6+AA6+AF6)/5=B6,"Todo Bien :D","Algo esta Mal :c") -> Todo Bien :D
A7: Activar curso | B7: 0 | C7: 0 | D7: 0 | E7: 0 | F7: 0 | G7: 0 | H7: 0 | I7: 0 | J7: 0 | K7: =SUM(C7:J7) -> 0 | L7: 0 | M7: 0 | N7: =SUM(L7:M7) -> 0 | O7: 0 | P7: 0 | Q7: 0 | R7: 0 | S7: 0 | T7: 0 | U7: 0 | V7: 0 | W7: 0 | X7: 0 | Y7: 0 | Z7: 0 | AA7: =SUM(O7:Z7) -> 0 | AB7: 0 | AC7: 0 | AD7: 0 | AE7: 0 | AF7: =SUM(AB7:AE7) -> 0 | AG7: =IF((B7+K7+N7+AA7+AF7)/5=B7,"Todo Bien :D","Algo esta Mal :c") -> Todo Bien :D
A8: Actualizar cursos a estudiantes | B8: 2 | C8: 0 | D8: 2 | E8: 0 | F8: 0 | G8: 0 | H8: 0 | I8: 0 | J8: 0 | K8: =SUM(C8:J8) -> 2 | L8: 2 | M8: 0 | N8: =SUM(L8:M8) -> 2 | O8: 2 | P8: 0 | Q8: 0 | R8: 0 | S8: 0 | T8: 0 | U8: 0 | V8: 0 | W8: 0 | X8: 0 | Y8: 0 | Z8: 0 | AA8: =SUM(O8:Z8) -> 2 | AB8: 2 | AC8: 0 | AD8: 0 | AE8: 0 | AF8: =SUM(AB8:AE8) -> 2 | AG8: =IF((B8+K8+N8+AA8+AF8)/5=B8,"Todo Bien :D","Algo esta Mal :c") -> Todo Bien :D
A9: Actualizar miembros de comunidades | B9: 3 | C9: 0 | D9: 3 | E9: 0 | F9: 0 | G9: 0 | H9: 0 | I9: 0 | J9: 0 | K9: =SUM(C9:J9) -> 3 | L9: 3 | M9: 0 | N9: =SUM(L9:M9) -> 3 | O9: 2 | P9: 0 | Q9: 0 | R9: 0 | S9: 0 | T9: 0 | U9: 1 | V9: 0 | W9: 0 | X9: 0 | Y9: 0 | Z9: 0 | AA9: =SUM(O9:Z9) -> 3 | AB9: 3 | AC9: 0 | AD9: 0 | AE9: 0 | AF9: =SUM(AB9:AE9) -> 3 | AG9: =IF((B9+K9+N9+AA9+AF9)/5=B9,"Todo Bien :D","Algo esta Mal :c") -> Todo Bien :D
A10: Administrador de asistencia | B10: 0 | C10: 0 | D10: 0 | E10: 0 | F10: 0 | G10: 0 | H10: 0 | I10: 0 | J10: 0 | K10: =SUM(C10:J10) -> 0 | L10: 0 | M10: 0 | N10: =SUM(L10:M10) -> 0 | O10: 0 | P10: 0 | Q10: 0 | R10: 0 | S10: 0 | T10: 0 | U10: 0 | V10: 0 | W10: 0 | X10: 0 | Y10: 0 | Z10: 0 | AA10: =SUM(O10:Z10) -> 0 | AB10: 0 | AC10: 0 | AD10: 0 | AE10: 0 | AF10: =SUM(AB10:AE10) -> 0 | AG10: =IF((B10+K10+N10+AA10+AF10)/5=B10,"Todo Bien :D","Algo esta Mal :c") -> Todo Bien :D
A11: Administrador Programa de Curso | B11: 0 | C11: 0 | D11: 0 | E11: 0 | F11: 0 | G11: 0 | H11: 0 | I11: 0 | J11: 0 | K11: =SUM(C11:J11) -> 0 | L11: 0 | M11: 0 | N11: =SUM(L11:M11) -> 0 | O11: 0 | P11: 0 | Q11: 0 | R11: 0 | S11: 0 | T11: 0 | U11: 0 | V11: 0 | W11: 0 | X11: 0 | Y11: 0 | Z11: 0 | AA11: =SUM(O11:Z11) -> 0 | AB11: 0 | AC11: 0 | AD11: 0 | AE11: 0 | AF11: =SUM(AB11:AE11) -> 0 | AG11: =IF((B11+K11+N11+AA11+AF11)/5=B11,"Todo Bien :D","Algo esta Mal :c") -> Todo Bien :D
A12: Agregar/cambiar asociación de estudiante a curso | B12: 6 | C12: 1 | D12: 2 | E12: 0 | F12: 0 | G12: 0 | H12: 2 | I12: 1 | J12: 0 | K12: =SUM(C12:J12) -> 6 | L12: 6 | M12: 0 | N12: =SUM(L12:M12) -> 6 | O12: 5 | P12: 0 | Q12: 0 | R12: 1 | S12: 0 | T12: 0 | U12: 0 | V12: 0 | W12: 0 | X12: 0 | Y12: 0 | Z12: 0 | AA12: =SUM(O12:Z12) -> 6 | AB12: 6 | AC12: 0 | AD12: 0 | AE12: 0 | AF12: =SUM(AB12:AE12) -> 6 | AG12: =IF((B12+K12+N12+AA12+AF12)/5=B12,"Todo Bien :D","Algo esta Mal :c") -> Todo Bien :D
A13: Agregar/cambiar asociación de profesor a curso | B13: 8 | C13: 0 | D13: 8 | E13: 0 | F13: 0 | G13: 0 | H13: 0 | I13: 0 | J13: 0 | K13: =SUM(C13:J13) -> 8 | L13: 8 | M13: 0 | N13: =SUM(L13:M13) -> 8 | O13: 0 | P13: 0 | Q13: 0 | R13: 3 | S13: 0 | T13: 0 | U13: 5 | V13: 0 | W13: 0 | X13: 0 | Y13: 0 | Z13: 0 | AA13: =SUM(O13:Z13) -> 8 | AB13: 8 | AC13: 0 | AD13: 0 | AE13: 0 | AF13: =SUM(AB13:AE13) -> 8 | AG13: =IF((B13+K13+N13+AA13+AF13)/5=B13,"Todo Bien :D","Algo esta Mal :c") -> Todo Bien :D
A14: Agregar/cambiar asociación de usuario a comunidad | B14: 8 | C14: 0 | D14: 7 | E14: 0 | F14: 0 | G14: 0 | H14: 0 | I14: 1 | J14: 0 | K14: =SUM(C14:J14) -> 8 | L14: 8 | M14: 0 | N14: =SUM(L14:M14) -> 8 | O14: 5 | P14: 0 | Q14: 0 | R14: 1 | S14: 0 | T14: 0 | U14: 1 | V14: 0 | W14: 1 | X14: 0 | Y14: 0 | Z14: 0 | AA14: =SUM(O14:Z14) -> 8 | AB14: 8 | AC14: 0 | AD14: 0 | AE14: 0 | AF14: =SUM(AB14:AE14) -> 8 | AG14: =IF((B14+K14+N14+AA14+AF14)/5=B14,"Todo Bien :D","Algo esta Mal :c") -> Todo Bien :D
A15: Agregar/cambiar asociación estudiante a curso Colegio Científico | B15: 0 | C15: 0 | D15: 0 | E15: 0 | F15: 0 | G15: 0 | H15: 0 | I15: 0 | J15: 0 | K15: =SUM(C15:J15) -> 0 | L15: 0 | M15: 0 | N15: =SUM(L15:M15) -> 0 | O15: 0 | P15: 0 | Q15: 0 | R15: 0 | S15: 0 | T15: 0 | U15: 0 | V15: 0 | W15: 0 | X15: 0 | Y15: 0 | Z15: 0 | AA15: =SUM(O15:Z15) -> 0 | AB15: 0 | AC15: 0 | AD15: 0 | AE15: 0 | AF15: =SUM(AB15:AE15) -> 0 | AG15: =IF((B15+K15+N15+AA15+AF15)/5=B15,"Todo Bien :D","Algo esta Mal :c") -> Todo Bien :D
... A67: Solicitud de información de la plataforma | B67: 1 | C67: 0 | D67: 1 | E67: 0 | F67: 0 | G67: 0 | H67: 0 | I67: 0 | J67: 0 | K67: =SUM(C67:J67) -> 1 | L67: 1 | M67: 0 | N67: =SUM(L67:M67) -> 1 | O67: 0 | P67: 0 | Q67: 0 | R67: 0 | S67: 0 | T67: 0 | U67: 0 | V67: 0 | W67: 0 | X67: 0 | Y67: 0 | Z67: 1 | AA67: =SUM(O67:Z67) -> 1 | AB67: 1 | AC67: 0 | AD67: 0 | AE67: 0 | AF67: =SUM(AB67:AE67) -> 1 | AG67: =IF((B67+K67+N67+AA67+AF67)/5=B67,"Todo Bien :D","Algo esta Mal :c") -> Todo Bien :D
A68: TOTAL | B68: =SUM(B4:B67) -> 198 | C68: =SUM(C3:C67) -> 6 | D68: =SUM(D3:D67) -> 183 | E68: =SUM(E3:E67) -> 0 | F68: =SUM(F3:F67) -> 0 | G68: =SUM(G3:G67) -> 0 | H68: =SUM(H3:H67) -> 2 | I68: =SUM(I3:I67) -> 7 | J68: =SUM(J3:J67) -> 0 | K68: =SUM(C68:J68) -> 198 | L68: =SUM(L3:L67) -> 197 | M68: =SUM(M3:M67) -> 1 | N68: =SUM(L68:M68) -> 198 | O68: =SUM(O3:O67) -> 58 | P68: =SUM(P3:P67) -> 2 | Q68: =SUM(Q3:Q67) -> 0 | R68: =SUM(R3:R67) -> 47 | S68: =SUM(S3:S67) -> 1 | T68: =SUM(T3:T67) -> 0 | U68: =SUM(U3:U67) -> 40 | V68: =SUM(V3:V67) -> 43 | ... Z68: =SUM(Z3:Z67) -> 3 | AA68: =SUM(O68:Z68) -> 198 | AB68: =SUM(AB3:AB67) -> 198 | AC68: =SUM(AC3:AC67) -> 0 | AD68: =SUM(AD3:AD67) -> 0 | AE68: =SUM(AE3:AE67) -> 0 | AF68: =SUM(AB68:AE68) -> 198 | AG68: =IF((B68+K68+N68+AA68+AF68)/5=B68,"Todo Bien :D","Algo esta Mal :c") -> Todo Bien :D

Sheet Mayo
A1: SERVICIO RELACIONADO | C1: TIQUETS POR CANAL | L1: TIPO | O1: ROL USUARIO | AB1: PRIORIDAD | AG1: TOTALES
A3: =IF((B68+K68+N68+AA68+AF68)/5=B68,"Todo Bien :D","Algo esta Mal :c") -> Todo Bien :D | B3: Cantidad x Servicio | C3: Chat | D3: Correo | E3: Formulario Web | F3: Facebook | G3: Memorandum | H3: Presencial | I3: Teléfono | J3: Twitter | K3: TOTAL | L3: Solicitud | M3: Incidente | N3: TOTAL | O3: Estudiante | P3: Estudiante FundaTEC | Q3: Estudiante Colegio Científico | R3: Profesor | S3: Profesor FundaTEC | T3: Profesor Colegio Científico | U3: Administrativo | V3: Administrativo FundaTEC | W3: Director/Coordinador | X3: Director/Coordinador FundaTEC | Y3: Director/Coordinador Colegio Científico | Z3: Externo | AA3: TOTAL | AB3: Normal | AC3: Baja | AD3: Alta | AE3: Urgente | AF3: TOTAL
A4: Acceso a la plataforma TEC Digital | B4: 51 | C4: 0 | D4: 47 | E4: 0 | F4: 0 | G4: 0 | H4: 1 | I4: 3 | J4: 0 | K4: =SUM(C4:J4) -> 51 | L4: 51 | M4: 0 | N4: =SUM(L4:M4) -> 51 | O4: 31 | P4: 1 | Q4: 0 | R4: 6 | S4: 0 | T4: 0 | U4: 2 | V4: 7 | W4: 0 | X4: 0 | Y4: 0 | Z4: 4 | AA4: =SUM(O4:Z4) -> 51 | AB4: 50 | AC4: 0 | AD4: 1 | AE4: 0 | AF4: =SUM(AB4:AE4) -> 51 | AG4: =IF((B4+K4+N4+AA4+AF4)/5=B4,"Todo Bien :D","Algo esta Mal :c") -> Todo Bien :D
A5: Acreditación | B5: 0 | C5: 0 | D5: 0 | E5: 0 | F5: 0 | G5: 0 | H5: 0 | I5: 0 | J5: 0 | K5: =SUM(C5:J5) -> 0 | L5: 0 | M5: 0 | N5: =SUM(L5:M5) -> 0 | O5: 0 | P5: 0 | Q5: 0 | R5: 0 | S5: 0 | T5: 0 | U5: 0 | V5: 0 | W5: 0 | X5: 0 | Y5: 0 | Z5: 0 | AA5: =SUM(O5:Z5) -> 0 | AB5: 0 | AC5: 0 | AD5: 0 | AE5: 0 | AF5: =SUM(AB5:AE5) -> 0 | AG5: =IF((B5+K5+N5+AA5+AF5)/5=B5,"Todo Bien :D","Algo esta Mal :c") -> Todo Bien :D
A6: Activar cuentas de usuario | B6: 5 | C6: 0 | D6: 3 | E6: 0 | F6: 0 | G6: 0 | H6: 0 | I6: 2 | J6: 0 | K6: =SUM(C6:J6) -> 5 | L6: 5 | M6: 0 | N6: =SUM(L6:M6) -> 5 | O6: 1 | P6: 0 | Q6: 0 | R6: 3 | S6: 0 | T6: 0 | U6: 1 | V6: 0 | W6: 0 | X6: 0 | Y6: 0 | Z6: 0 | AA6: =SUM(O6:Z6) -> 5 | AB6: 5 | AC6: 0 | AD6: 0 | AE6: 0 | AF6: =SUM(AB6:AE6) -> 5 | AG6: =IF((B6+K6+N6+AA6+AF6)/5=B6,"Todo Bien :D","Algo esta Mal :c") -> Todo Bien :D
A7: Activar curso | B7: 0 | C7: 0 | D7: 0 | E7: 0 | F7: 0 | G7: 0 | H7: 0 | I7: 0 | J7: 0 | K7: =SUM(C7:J7) -> 0 | L7: 0 | M7: 0 | N7: =SUM(L7:M7) -> 0 | O7: 0 | P7: 0 | Q7: 0 | R7: 0 | S7: 0 | T7: 0 | U7: 0 | V7: 0 | W7: 0 | X7: 0 | Y7: 0 | Z7: 0 | AA7: =SUM(O7:Z7) -> 0 | AB7: 0 | AC7: 0 | AD7: 0 | AE7: 0 | AF7: =SUM(AB7:AE7) -> 0 | AG7: =IF((B7+K7+N7+AA7+AF7)/5=B7,"Todo Bien :D","Algo esta Mal :c") -> Todo Bien :D
A8: Actualizar cursos a estudiantes | B8: 0 | C8: 0 | D8: 0 | E8: 0 | F8: 0 | G8: 0 | H8: 0 | I8: 0 | J8: 0 | K8: =SUM(C8:J8) -> 0 | L8: 0 | M8: 0 | N8: =SUM(L8:M8) -> 0 | O8: 0 | P8: 0 | Q8: 0 | R8: 0 | S8: 0 | T8: 0 | U8: 0 | V8: 0 | W8: 0 | X8: 0 | Y8: 0 | Z8: 0 | AA8: =SUM(O8:Z8) -> 0 | AB8: 0 | AC8: 0 | AD8: 0 | AE8: 0 | AF8: =SUM(AB8:AE8) -> 0 | AG8: =IF((B8+K8+N8+AA8+AF8)/5=B8,"Todo Bien :D","Algo esta Mal :c") -> Todo Bien :D
A9: Actualizar miembros de comunidades | B9: 0 | C9: 0 | D9: 0 | E9: 0 | F9: 0 | G9: 0 | H9: 0 | I9: 0 | J9: 0 | K9: =SUM(C9:J9) -> 0 | L9: 0 | M9: 0 | N9: =SUM(L9:M9) -> 0 | O9: 0 | P9: 0 | Q9: 0 | R9: 0 | S9: 0 | T9: 0 | U9: 0 | V9: 0 | W9: 0 | X9: 0 | Y9: 0 | Z9: 0 | AA9: =SUM(O9:Z9) -> 0 | AB9: 0 | AC9: 0 | AD9: 0 | AE9: 0 | AF9: =SUM(AB9:AE9) -> 0 | AG9: =IF((B9+K9+N9+AA9+AF9)/5=B9,"Todo Bien :D","Algo esta Mal :c") -> Todo Bien :D
A10: Administrador de asistencia | B10: 0 | C10: 0 | D10: 0 | E10: 0 | F10: 0 | G10: 0 | H10: 0 | I10: 0 | J10: 0 | K10: =SUM(C10:J10) -> 0 | L10: 0 | M10: 0 | N10: =SUM(L10:M10) -> 0 | O10: 0 | P10: 0 | Q10: 0 | R10: 0 | S10: 0 | T10: 0 | U10: 0 | V10: 0 | W10: 0 | X10: 0 | Y10: 0 | Z10: 0 | AA10: =SUM(O10:Z10) -> 0 | AB10: 0 | AC10: 0 | AD10: 0 | AE10: 0 | AF10: =SUM(AB10:AE10) -> 0 | AG10: =IF((B10+K10+N10+AA10+AF10)/5=B10,"Todo Bien :D","Algo esta Mal :c") -> Todo Bien :D
A11: Administrador Programa de Curso | B11: 0 | C11: 0 | D11: 0 | E11: 0 | F11: 0 | G11: 0 | H11: 0 | I11: 0 | J11: 0 | K11: =SUM(C11:J11) -> 0 | L11: 0 | M11: 0 | N11: =SUM(L11:M11) -> 0 | O11: 0 | P11: 0 | Q11: 0 | R11: 0 | S11: 0 | T11: 0 | U11: 0 | V11: 0 | W11: 0 | X11: 0 | Y11: 0 | Z11: 0 | AA11: =SUM(O11:Z11) -> 0 | AB11: 0 | AC11: 0 | AD11: 0 | AE11: 0 | AF11: =SUM(AB11:AE11) -> 0 | AG11: =IF((B11+K11+N11+AA11+AF11)/5=B11,"Todo Bien :D","Algo esta Mal :c") -> Todo Bien :D
A12: Agregar/cambiar asociación de estudiante a curso | B12: 6 | C12: 0 | D12: 6 | E12: 0 | F12: 0 | G12: 0 | H12: 0 | I12: 0 | J12: 0 | K12: =SUM(C12:J12) -> 6 | L12: 6 | M12: 0 | N12: =SUM(L12:M12) -> 6 | O12: 4 | P12: 0 | Q12: 0 | R12: 2 | S12: 0 | T12: 0 | U12: 0 | V12: 0 | W12: 0 | X12: 0 | Y12: 0 | Z12: 0 | AA12: =SUM(O12:Z12) -> 6 | AB12: 6 | AC12: 0 | AD12: 0 | AE12: 0 | AF12: =SUM(AB12:AE12) -> 6 | AG12: =IF((B12+K12+N12+AA12+AF12)/5=B12,"Todo Bien :D","Algo esta Mal :c") -> Todo Bien :D
A13: Agregar/cambiar asociación de profesor a curso | B13: 3 | C13: 0 | D13: 2 | E13: 0 | F13: 0 | G13: 0 | H13: 0 | I13: 1 | J13: 0 | K13: =SUM(C13:J13) -> 3 | L13: 3 | M13: 0 | N13: =SUM(L13:M13) -> 3 | O13: 0 | P13: 0 | Q13: 0 | R13: 1 | S13: 0 | T13: 0 | U13: 2 | V13: 0 | W13: 0 | X13: 0 | Y13: 0 | Z13: 0 | AA13: =SUM(O13:Z13) -> 3 | AB13: 3 | AC13: 0 | AD13: 0 | AE13: 0 | AF13: =SUM(AB13:AE13) -> 3 | AG13: =IF((B13+K13+N13+AA13+AF13)/5=B13,"Todo Bien :D","Algo esta Mal :c") -> Todo Bien :D
A14: Agregar/cambiar asociación de usuario a comunidad | B14: 4 | C14: 1 | D14: 1 | E14: 0 | F14: 0 | G14: 0 | H14: 1 | I14: 1 | J14: 0 | K14: =SUM(C14:J14) -> 4 | L14: 4 | M14: 0 | N14: =SUM(L14:M14) -> 4 | O14: 2 | P14: 0 | Q14: 0 | R14: 1 | S14: 0 | T14: 0 | U14: 1 | V14: 0 | W14: 0 | X14: 0 | Y14: 0 | Z14: 0 | AA14: =SUM(O14:Z14) -> 4 | AB14: 4 | AC14: 0 | AD14: 0 | AE14: 0 | AF14: =SUM(AB14:AE14) -> 4 | AG14: =IF((B14+K14+N14+AA14+AF14)/5=B14,"Todo Bien :D","Algo esta Mal :c") -> Todo Bien :D
A15: Agregar/cambiar asociación estudiante a curso Colegio Científico | B15: 0 | C15: 0 | D15: 0 | E15: 0 | F15: 0 | G15: 0 | H15: 0 | I15: 0 | J15: 0 | K15: =SUM(C15:J15) -> 0 | L15: 0 | M15: 0 | N15: =SUM(L15:M15) -> 0 | O15: 0 | P15: 0 | Q15: 0 | R15: 0 | S15: 0 | T15: 0 | U15: 0 | V15: 0 | W15: 0 | X15: 0 | Y15: 0 | Z15: 0 | AA15: =SUM(O15:Z15) -> 0 | AB15: 0 | AC15: 0 | AD15: 0 | AE15: 0 | AF15: =SUM(AB15:AE15) -> 0 | AG15: =IF((B15+K15+N15+AA15+AF15)/5=B15,"Todo Bien :D","Algo esta Mal :c") -> Todo Bien :D
... A67: Solicitud de información de la plataforma | B67: 0 | C67: 0 | D67: 0 | E67: 0 | F67: 0 | G67: 0 | H67: 0 | I67: 0 | J67: 0 | K67: =SUM(C67:J67) -> 0 | L67: 0 | M67: 0 | N67: =SUM(L67:M67) -> 0 | O67: 0 | P67: 0 | Q67: 0 | R67: 0 | S67: 0 | T67: 0 | U67: 0 | V67: 0 | W67: 0 | X67: 0 | Y67: 0 | Z67: 0 | AA67: =SUM(O67:Z67) -> 0 | AB67: 0 | AC67: 0 | AD67: 0 | AE67: 0 | AF67: =SUM(AB67:AE67) -> 0 | AG67: =IF((B67+K67+N67+AA67+AF67)/5=B67,"Todo Bien :D","Algo esta Mal :c") -> Todo Bien :D
A68: TOTAL | B68: =SUM(B4:B67) -> 203 | C68: =SUM(C3:C67) -> 3 | D68: =SUM(D3:D67) -> 188 | E68: =SUM(E3:E67) -> 0 | F68: =SUM(F3:F67) -> 0 | G68: =SUM(G3:G67) -> 0 | H68: =SUM(H3:H67) -> 3 | I68: =SUM(I3:I67) -> 9 | J68: =SUM(J3:J67) -> 0 | K68: =SUM(C68:J68) -> 203 | L68: =SUM(L3:L67) -> 203 | M68: =SUM(M3:M67) -> 0 | N68: =SUM(L68:M68) -> 203 | O68: =SUM(O3:O67) -> 77 | P68: =SUM(P3:P67) -> 5 | Q68: =SUM(Q3:Q67) -> 0 | R68: =SUM(R3:R67) -> 49 | S68: =SUM(S3:S67) -> 0 | T68: =SUM(T3:T67) -> 0 | U68: =SUM(U3:U67) -> 22 | V68: =SUM(V3:V67) -> 42 | ... Z68: =SUM(Z3:Z67) -> 7 | AA68: =SUM(O68:Z68) -> 203 | AB68: =SUM(AB3:AB67) -> 202 | AC68: =SUM(AC3:AC67) -> 0 | AD68: =SUM(AD3:AD67) -> 1 | AE68: =SUM(AE3:AE67) -> 0 | AF68: =SUM(AB68:AE68) -> 203 | AG68: =IF((B68+K68+N68+AA68+AF68)/5=B68,"Todo Bien :D","Algo esta Mal :c") -> Todo Bien :D

Sheet Junio
A1: SERVICIO RELACIONADO | C1: TIQUETS POR CANAL | L1: TIPO | O1: ROL USUARIO | AB1: PRIORIDAD | AG1: TOTALES
A3: =IF((B68+K68+N68+AA68+AF68)/5=B68,"Todo Bien :D","Algo esta Mal :c") -> Todo Bien :D | B3: Cantidad x Servicio | C3: Chat | D3: Correo | E3: Formulario Web | F3: Facebook | G3: Memorandum | H3: Presencial | I3: Teléfono | J3: Twitter | K3: TOTAL | L3: Solicitud | M3: Incidente | N3: TOTAL | O3: Estudiante | P3: Estudiante FundaTEC | Q3: Estudiante Colegio Científico | R3: Profesor | S3: Profesor FundaTEC | T3: Profesor Colegio Científico | U3: Administrativo | V3: Administrativo FundaTEC | W3: Director/Coordinador | X3: Director/Coordinador FundaTEC | Y3: Director/Coordinador Colegio Científico | Z3: Externo | AA3: TOTAL | AB3: Normal | AC3: Baja | AD3: Alta | AE3: Urgente | AF3: TOTAL
A4: Acceso a la plataforma TEC Digital | B4: 54 | C4: 0 | D4: 51 | E4: 3 | F4: 0 | G4: 0 | H4: 0 | I4: 0 | J4: 0 | K4: =SUM(C4:J4) -> 54 | L4: 54 | M4: 0 | N4: =SUM(L4:M4) -> 54 | O4: 33 | P4: 2 | Q4: 0 | R4: 10 | S4: 0 | T4: 0 | U4: 1 | V4: 2 | W4: 1 | X4: 0 | Y4: 0 | Z4: 5 | AA4: =SUM(O4:Z4) -> 54 | AB4: 54 | AC4: 0 | AD4: 0 | AE4: 0 | AF4: =SUM(AB4:AE4) -> 54 | AG4: =IF((B4+K4+N4+AA4+AF4)/5=B4,"Todo Bien :D","Algo esta Mal :c") -> Todo Bien :D
A5: Acreditación | B5: 0 | C5: 0 | D5: 0 | E5: 0 | F5: 0 | G5: 0 | H5: 0 | I5: 0 | J5: 0 | K5: =SUM(C5:J5) -> 0 | L5: 0 | M5: 0 | N5: =SUM(L5:M5) -> 0 | O5: 0 | P5: 0 | Q5: 0 | R5: 0 | S5: 0 | T5: 0 | U5: 0 | V5: 0 | W5: 0 | X5: 0 | Y5: 0 | Z5: 0 | AA5: =SUM(O5:Z5) -> 0 | AB5: 0 | AC5: 0 | AD5: 0 | AE5: 0 | AF5: =SUM(AB5:AE5) -> 0 | AG5: =IF((B5+K5+N5+AA5+AF5)/5=B5,"Todo Bien :D","Algo esta Mal :c") -> Todo Bien :D
A6: Activar cuentas de usuario | B6: 3 | C6: 0 | D6: 3 | E6: 0 | F6: 0 | G6: 0 | H6: 0 | I6: 0 | J6: 0 | K6: =SUM(C6:J6) -> 3 | L6: 3 | M6: 0 | N6: =SUM(L6:M6) -> 3 | O6: 2 | P6: 0 | Q6: 0 | R6: 0 | S6: 0 | T6: 0 | U6: 0 | V6: 0 | W6: 0 | X6: 0 | Y6: 0 | Z6: 1 | AA6: =SUM(O6:Z6) -> 3 | AB6: 3 | AC6: 0 | AD6: 0 | AE6: 0 | AF6: =SUM(AB6:AE6) -> 3 | AG6: =IF((B6+K6+N6+AA6+AF6)/5=B6,"Todo Bien :D","Algo esta Mal :c") -> Todo Bien :D
A7: Activar curso | B7: 0 | C7: 0 | D7: 0 | E7: 0 | F7: 0 | G7: 0 | H7: 0 | I7: 0 | J7: 0 | K7: =SUM(C7:J7) -> 0 | L7: 0 | M7: 0 | N7: =SUM(L7:M7) -> 0 | O7: 0 | P7: 0 | Q7: 0 | R7: 0 | S7: 0 | T7: 0 | U7: 0 | V7: 0 | W7: 0 | X7: 0 | Y7: 0 | Z7: 0 | AA7: =SUM(O7:Z7) -> 0 | AB7: 0 | AC7: 0 | AD7: 0 | AE7: 0 | AF7: =SUM(AB7:AE7) -> 0 | AG7: =IF((B7+K7+N7+AA7+AF7)/5=B7,"Todo Bien :D","Algo esta Mal :c") -> Todo Bien :D
A8: Actualizar cursos a estudiantes | B8: 6 | C8: 0 | D8: 6 | E8: 0 | F8: 0 | G8: 0 | H8: 0 | I8: 0 | J8: 0 | K8: =SUM(C8:J8) -> 6 | L8: 6 | M8: 0 | N8: =SUM(L8:M8) -> 6 | O8: 1 | P8: 1 | Q8: 0 | R8: 0 | S8: 0 | T8: 0 | U8: 3 | V8: 1 | W8: 0 | X8: 0 | Y8: 0 | Z8: 0 | AA8: =SUM(O8:Z8) -> 6 | AB8: 6 | AC8: 0 | AD8: 0 | AE8: 0 | AF8: =SUM(AB8:AE8) -> 6 | AG8: =IF((B8+K8+N8+AA8+AF8)/5=B8,"Todo Bien :D","Algo esta Mal :c") -> Todo Bien :D
A9: Actualizar miembros de comunidades | B9: 1 | C9: 0 | D9: 1 | E9: 0 | F9: 0 | G9: 0 | H9: 0 | I9: 0 | J9: 0 | K9: =SUM(C9:J9) -> 1 | L9: 1 | M9: 0 | N9: =SUM(L9:M9) -> 1 | O9: 1 | P9: 0 | Q9: 0 | R9: 0 | S9: 0 | T9: 0 | U9: 0 | V9: 0 | W9: 0 | X9: 0 | Y9: 0 | Z9: 0 | AA9: =SUM(O9:Z9) -> 1 | AB9: 1 | AC9: 0 | AD9: 0 | AE9: 0 | AF9: =SUM(AB9:AE9) -> 1 | AG9: =IF((B9+K9+N9+AA9+AF9)/5=B9,"Todo Bien :D","Algo esta Mal :c") -> Todo Bien :D
A10: Administrador de asistencia | B10: 0 | C10: 0 | D10: 0 | E10: 0 | F10: 0 | G10: 0 | H10: 0 | I10: 0 | J10: 0 | K10: =SUM(C10:J10) -> 0 | L10: 0 | M10: 0 | N10: =SUM(L10:M10) -> 0 | O10: 0 | P10: 0 | Q10: 0 | R10: 0 | S10: 0 | T10: 0 | U10: 0 | V10: 0 | W10: 0 | X10: 0 | Y10: 0 | Z10: 0 | AA10: =SUM(O10:Z10) -> 0 | AB10: 0 | AC10: 0 | AD10: 0 | AE10: 0 | AF10: =SUM(AB10:AE10) -> 0 | AG10: =IF((B10+K10+N10+AA10+AF10)/5=B10,"Todo Bien :D","Algo esta Mal :c") -> Todo Bien :D
A11: Administrador Programa de Curso | B11: 0 | C11: 0 | D11: 0 | E11: 0 | F11: 0 | G11: 0 | H11: 0 | I11: 0 | J11: 0 | K11: =SUM(C11:J11) -> 0 | L11: 0 | M11: 0 | N11: =SUM(L11:M11) -> 0 | O11: 0 | P11: 0 | Q11: 0 | R11: 0 | S11: 0 | T11: 0 | U11: 0 | V11: 0 | W11: 0 | X11: 0 | Y11: 0 | Z11: 0 | AA11: =SUM(O11:Z11) -> 0 | AB11: 0 | AC11: 0 | AD11: 0 | AE11: 0 | AF11: =SUM(AB11:AE11) -> 0 | AG11: =IF((B11+K11+N11+AA11+AF11)/5=B11,"Todo Bien :D","Algo esta Mal :c") -> Todo Bien :D
A12: Agregar/cambiar asociación de estudiante a curso | B12: 10 | C12: 1 | D12: 9 | E12: 0 | F12: 0 | G12: 0 | H12: 0 | I12: 0 | J12: 0 | K12: =SUM(C12:J12) -> 10 | L12: 10 | M12: 0 | N12: =SUM(L12:M12) -> 10 | O12: 3 | P12: 0 | Q12: 0 | R12: 3 | S12: 0 | T12: 0 | U12: 4 | V12: 0 | W12: 0 | X12: 0 | Y12: 0 | Z12: 0 | AA12: =SUM(O12:Z12) -> 10 | AB12: 10 | AC12: 0 | AD12: 0 | AE12: 0 | AF12: =SUM(AB12:AE12) -> 10 | AG12: =IF((B12+K12+N12+AA12+AF12)/5=B12,"Todo Bien :D","Algo esta Mal :c") -> Todo Bien :D
A13: Agregar/cambiar asociación de profesor a curso | B13: 12 | C13: 0 | D13: 10 | E13: 0 | F13: 0 | G13: 0 | H13: 1 | I13: 1 | J13: 0 | K13: =SUM(C13:J13) -> 12 | L13: 12 | M13: 0 | N13: =SUM(L13:M13) -> 12 | O13: 1 | P13: 0 | Q13: 0 | R13: 6 | S13: 0 | T13: 0 | U13: 4 | V13: 1 | W13: 0 | X13: 0 | Y13: 0 | Z13: 0 | AA13: =SUM(O13:Z13) -> 12 | AB13: 12 | AC13: 0 | AD13: 0 | AE13: 0 | AF13: =SUM(AB13:AE13) -> 12 | AG13: =IF((B13+K13+N13+AA13+AF13)/5=B13,"Todo Bien :D","Algo esta Mal :c") -> Todo Bien :D
A14: Agregar/cambiar asociación de usuario a comunidad | B14: 4 | C14: 0 | D14: 4 | E14: 0 | F14: 0 | G14: 0 | H14: 0 | I14: 0 | J14: 0 | K14: =SUM(C14:J14) -> 4 | L14: 4 | M14: 0 | N14: =SUM(L14:M14) -> 4 | O14: 2 | P14: 0 | Q14: 0 | R14: 0 | S14: 0 | T14: 0 | U14: 1 | V14: 0 | W14: 1 | X14: 0 | Y14: 0 | Z14: 0 | AA14: =SUM(O14:Z14) -> 4 | AB14: 4 | AC14: 0 | AD14: 0 | AE14: 0 | AF14: =SUM(AB14:AE14) -> 4 | AG14: =IF((B14+K14+N14+AA14+AF14)/5=B14,"Todo Bien :D","Algo esta Mal :c") -> Todo Bien :D
A15: Agregar/cambiar asociación estudiante a curso Colegio Científico | B15: 0 | C15: 0 | D15: 0 | E15: 0 | F15: 0 | G15: 0 | H15: 0 | I15: 0 | J15: 0 | K15: =SUM(C15:J15) -> 0 | L15: 0 | M15: 0 | N15: =SUM(L15:M15) -> 0 | O15: 0 | P15: 0 | Q15: 0 | R15: 0 | S15: 0 | T15: 0 | U15: 0 | V15: 0 | W15: 0 | X15: 0 | Y15: 0 | Z15: 0 | AA15: =SUM(O15:Z15) -> 0 | AB15: 0 | AC15: 0 | AD15: 0 | AE15: 0 | AF15: =SUM(AB15:AE15) -> 0 | AG15: =IF((B15+K15+N15+AA15+AF15)/5=B15,"Todo Bien :D","Algo esta Mal :c") -> Todo Bien :D
... A67: Solicitud de información de la plataforma | B67: 0 | C67: 0 | D67: 0 | E67: 0 | F67: 0 | G67: 0 | H67: 0 | I67: 0 | J67: 0 | K67: =SUM(C67:J67) -> 0 | L67: 0 | M67: 0 | N67: =SUM(L67:M67) -> 0 | O67: 0 | P67: 0 | Q67: 0 | R67: 0 | S67: 0 | T67: 0 | U67: 0 | V67: 0 | W67: 0 | X67: 0 | Y67: 0 | Z67: 0 | AA67: =SUM(O67:Z67) -> 0 | AB67: 0 | AC67: 0 | AD67: 0 | AE67: 0 | AF67: =SUM(AB67:AE67) -> 0 | AG67: =IF((B67+K67+N67+AA67+AF67)/5=B67,"Todo Bien :D","Algo esta Mal :c") -> Todo Bien :D
A68: TOTAL | B68: =SUM(B4:B67) -> 296 | C68: =SUM(C3:C67) -> 1 | D68: =SUM(D3:D67) -> 279 | E68: =SUM(E3:E67) -> 6 | F68: =SUM(F3:F67) -> 0 | G68: =SUM(G3:G67) -> 0 | H68: =SUM(H3:H67) -> 6 | I68: =SUM(I3:I67) -> 4 | J68: =SUM(J3:J67) -> 0 | K68: =SUM(C68:J68) -> 296 | L68: =SUM(L3:L67) -> 295 | M68: =SUM(M3:M67) -> 1 | N68: =SUM(L68:M68) -> 296 | O68: =SUM(O3:O67) -> 103 | P68: =SUM(P3:P67) -> 5 | Q68: =SUM(Q3:Q67) -> 0 | R68: =SUM(R3:R67) -> 61 | S68: =SUM(S3:S67) -> 0 | T68: =SUM(T3:T67) -> 0 | U68: =SUM(U3:U67) -> 35 | V68: =SUM(V3:V67) -> 75 | ... Z68: =SUM(Z3:Z67) -> 14 | AA68: =SUM(O68:Z68) -> 296 | AB68: =SUM(AB3:AB67) -> 296 | AC68: =SUM(AC3:AC67) -> 0 | AD68: =SUM(AD3:AD67) -> 0 | AE68: =SUM(AE3:AE67) -> 0 | AF68: =SUM(AB68:AE68) -> 296 | AG68: =IF((B68+K68+N68+AA68+AF68)/5=B68,"Todo Bien :D","Algo esta Mal :c") -> Todo Bien :D

Sheet Julio
A1: SERVICIO RELACIONADO | C1: TIQUETS POR CANAL | L1: TIPO | O1: ROL USUARIO | AB1: PRIORIDAD | AG1: TOTALES
A3: =IF((B69+K69+N69+AA69+AF69)/5=B69,"Todo Bien :D","Algo esta Mal :c") -> Todo Bien :D | B3: Cantidad x Servicio | C3: Chat | D3: Correo | E3: Formulario Web | F3: Facebook | G3: Memorandum | H3: Presencial | I3: Teléfono | J3: Twitter | K3: TOTAL | L3: Solicitud | M3: Incidente | N3: TOTAL | O3: Estudiante | P3: Estudiante FundaTEC | Q3: Estudiante Colegio Científico | R3: Profesor | S3: Profesor FundaTEC | T3: Profesor Colegio Científico | U3: Administrativo | V3: Administrativo FundaTEC | W3: Director/Coordinador | X3: Director/Coordinador FundaTEC | Y3: Director/Coordinador Colegio Científico | Z3: Externo | AA3: TOTAL | AB3: Normal | AC3: Baja | AD3: Alta | AE3: Urgente | AF3: TOTAL
A4: Acceso a la plataforma TEC Digital | B4: 44 | C4: 0 | D4: 42 | E4: 0 | F4: 0 | G4: 0 | H4: 0 | I4: 2 | J4: 0 | K4: =SUM(C4:J4) -> 44 | L4: 44 | M4: 0 | N4: =SUM(L4:M4) -> 44 | O4: 27 | P4: 1 | Q4: 0 | R4: 6 | S4: 0 | T4: 0 | U4: 5 | V4: 1 | W4: 0 | X4: 0 | Y4: 0 | Z4: 4 | AA4: =SUM(O4:Z4) -> 44 | AB4: 44 | AC4: 0 | AD4: 0 | AE4: 0 | AF4: =SUM(AB4:AE4) -> 44 | AG4: =IF((B4+K4+N4+AA4+AF4)/5=B4,"Todo Bien :D","Algo esta Mal :c") -> Todo Bien :D
A5: Acreditación | B5: 0 | C5: 0 | D5: 0 | E5: 0 | F5: 0 | G5: 0 | H5: 0 | I5: 0 | J5: 0 | K5: =SUM(C5:J5) -> 0 | L5: 0 | M5: 0 | N5: =SUM(L5:M5) -> 0 | O5: 0 | P5: 0 | Q5: 0 | R5: 0 | S5: 0 | T5: 0 | U5: 0 | V5: 0 | W5: 0 | X5: 0 | Y5: 0 | Z5: 0 | AA5: =SUM(O5:Z5) -> 0 | AB5: 0 | AC5: 0 | AD5: 0 | AE5: 0 | AF5: =SUM(AB5:AE5) -> 0 | AG5: =IF((B5+K5+N5+AA5+AF5)/5=B5,"Todo Bien :D","Algo esta Mal :c") -> Todo Bien :D
A6: Activar cuentas de usuario | B6: 3 | C6: 0 | D6: 3 | E6: 0 | F6: 0 | G6: 0 | H6: 0 | I6: 0 | J6: 0 | K6: =SUM(C6:J6) -> 3 | L6: 3 | M6: 0 | N6: =SUM(L6:M6) -> 3 | O6: 1 | P6: 0 | Q6: 0 | R6: 0 | S6: 0 | T6: 0 | U6: 2 | V6: 0 | W6: 0 | X6: 0 | Y6: 0 | Z6: 0 | AA6: =SUM(O6:Z6) -> 3 | AB6: 3 | AC6: 0 | AD6: 0 | AE6: 0 | AF6: =SUM(AB6:AE6) -> 3 | AG6: =IF((B6+K6+N6+AA6+AF6)/5=B6,"Todo Bien :D","Algo esta Mal :c") -> Todo Bien :D
A7: Activar curso | B7: 2 | C7: 0 | D7: 2 | E7: 0 | F7: 0 | G7: 0 | H7: 0 | I7: 0 | J7: 0 | K7: =SUM(C7:J7) -> 2 | L7: 2 | M7: 0 | N7: =SUM(L7:M7) -> 2 | O7: 0 | P7: 0 | Q7: 0 | R7: 1 | S7: 0 | T7: 0 | U7: 1 | V7: 0 | W7: 0 | X7: 0 | Y7: 0 | Z7: 0 | AA7: =SUM(O7:Z7) -> 2 | AB7: 2 | AC7: 0 | AD7: 0 | AE7: 0 | AF7: =SUM(AB7:AE7) -> 2 | AG7: =IF((B7+K7+N7+AA7+AF7)/5=B7,"Todo Bien :D","Algo esta Mal :c") -> Todo Bien :D
A8: Actualizar cursos a estudiantes | B8: 2 | C8: 0 | D8: 2 | E8: 0 | F8: 0 | G8: 0 | H8: 0 | I8: 0 | J8: 0 | K8: =SUM(C8:J8) -> 2 | L8: 2 | M8: 0 | N8: =SUM(L8:M8) -> 2 | O8: 2 | P8: 0 | Q8: 0 | R8: 0 | S8: 0 | T8: 0 | U8: 0 | V8: 0 | W8: 0 | X8: 0 | Y8: 0 | Z8: 0 | AA8: =SUM(O8:Z8) -> 2 | AB8: 2 | AC8: 0 | AD8: 0 | AE8: 0 | AF8: =SUM(AB8:AE8) -> 2 | AG8: =IF((B8+K8+N8+AA8+AF8)/5=B8,"Todo Bien :D","Algo esta Mal :c") -> Todo Bien :D
A9: Actualizar miembros de comunidades | B9: 7 | C9: 0 | D9: 7 | E9: 0 | F9: 0 | G9: 0 | H9: 0 | I9: 0 | J9: 0 | K9: =SUM(C9:J9) -> 7 | L9: 7 | M9: 0 | N9: =SUM(L9:M9) -> 7 | O9: 0 | P9: 0 | Q9: 0 | R9: 4 | S9: 0 | T9: 0 | U9: 1 | V9: 0 | W9: 2 | X9: 0 | Y9: 0 | Z9: 0 | AA9: =SUM(O9:Z9) -> 7 | AB9: 7 | AC9: 0 | AD9: 0 | AE9: 0 | AF9: =SUM(AB9:AE9) -> 7 | AG9: =IF((B9+K9+N9+AA9+AF9)/5=B9,"Todo Bien :D","Algo esta Mal :c") -> Todo Bien :D
A10: Administrador de asistencia | B10: 0 | C10: 0 | D10: 0 | E10: 0 | F10: 0 | G10: 0 | H10: 0 | I10: 0 | J10: 0 | K10: =SUM(C10:J10) -> 0 | L10: 0 | M10: 0 | N10: =SUM(L10:M10) -> 0 | O10: 0 | P10: 0 | Q10: 0 | R10: 0 | S10: 0 | T10: 0 | U10: 0 | V10: 0 | W10: 0 | X10: 0 | Y10: 0 | Z10: 0 | AA10: =SUM(O10:Z10) -> 0 | AB10: 0 | AC10: 0 | AD10: 0 | AE10: 0 | AF10: =SUM(AB10:AE10) -> 0 | AG10: =IF((B10+K10+N10+AA10+AF10)/5=B10,"Todo Bien :D","Algo esta Mal :c") -> Todo Bien :D
A11: Administrador Programa de Curso | B11: 1 | C11: 0 | D11: 1 | E11: 0 | F11: 0 | G11: 0 | H11: 0 | I11: 0 | J11: 0 | K11: =SUM(C11:J11) -> 1 | L11: 1 | M11: 0 | N11: =SUM(L11:M11) -> 1 | O11: 1 | P11: 0 | Q11: 0 | R11: 0 | S11: 0 | T11: 0 | U11: 0 | V11: 0 | W11: 0 | X11: 0 | Y11: 0 | Z11: 0 | AA11: =SUM(O11:Z11) -> 1 | AB11: 1 | AC11: 0 | AD11: 0 | AE11: 0 | AF11: =SUM(AB11:AE11) -> 1 | AG11: =IF((B11+K11+N11+AA11+AF11)/5=B11,"Todo Bien :D","Algo esta Mal :c") -> Todo Bien :D
A12: Agregar/cambiar asociación de estudiante a curso | B12: 10 | C12: 0 | D12: 7 | E12: 0 | F12: 0 | G12: 0 | H12: 0 | I12: 3 | J12: 0 | K12: =SUM(C12:J12) -> 10 | L12: 10 | M12: 0 | N12: =SUM(L12:M12) -> 10 | O12: 5 | P12: 1 | Q12: 0 | R12: 2 | S12: 0 | T12: 0 | U12: 1 | V12: 1 | W12: 0 | X12: 0 | Y12: 0 | Z12: 0 | AA12: =SUM(O12:Z12) -> 10 | AB12: 10 | AC12: 0 | AD12: 0 | AE12: 0 | AF12: =SUM(AB12:AE12) -> 10 | AG12: =IF((B12+K12+N12+AA12+AF12)/5=B12,"Todo Bien :D","Algo esta Mal :c") -> Todo Bien :D
A13: Agregar/cambiar asociación de profesor a curso | B13: 15 | C13: 0 | D13: 15 | E13: 0 | F13: 0 | G13: 0 | H13: 0 | I13: 0 | J13: 0 | K13: =SUM(C13:J13) -> 15 | L13: 15 | M13: 0 | N13: =SUM(L13:M13) -> 15 | O13: 0 | P13: 0 | Q13: 0 | R13: 7 | S13: 0 | T13: 0 | U13: 6 | V13: 2 | W13: 0 | X13: 0 | Y13: 0 | Z13: 0 | AA13: =SUM(O13:Z13) -> 15 | AB13: 15 | AC13: 0 | AD13: 0 | AE13: 0 | AF13: =SUM(AB13:AE13) -> 15 | AG13: =IF((B13+K13+N13+AA13+AF13)/5=B13,"Todo Bien :D","Algo esta Mal :c") -> Todo Bien :D
A14: Agregar/cambiar asociación de usuario a comunidad | B14: 13 | C14: 3 | D14: 9 | E14: 0 | F14: 0 | G14: 0 | H14: 0 | I14: 1 | J14: 0 | K14: =SUM(C14:J14) -> 13 | L14: 13 | M14: 0 | N14: =SUM(L14:M14) -> 13 | O14: 6 | P14: 0 | Q14: 0 | R14: 2 | S14: 0 | T14: 0 | U14: 5 | V14: 0 | W14: 0 | X14: 0 | Y14: 0 | Z14: 0 | AA14: =SUM(O14:Z14) -> 13 | AB14: 13 | AC14: 0 | AD14: 0 | AE14: 0 | AF14: =SUM(AB14:AE14) -> 13 | AG14: =IF((B14+K14+N14+AA14+AF14)/5=B14,"Todo Bien :D","Algo esta Mal :c") -> Todo Bien :D
A15: Agregar/cambiar asociación estudiante a curso Colegio Científico | B15: 0 | C15: 0 | D15: 0 | E15: 0 | F15: 0 | G15: 0 | H15: 0 | I15: 0 | J15: 0 | K15: =SUM(C15:J15) -> 0 | L15: 0 | M15: 0 | N15: =SUM(L15:M15) -> 0 | O15: 0 | P15: 0 | Q15: 0 | R15: 0 | S15: 0 | T15: 0 | U15: 0 | V15: 0 | W15: 0 | X15: 0 | Y15: 0 | Z15: 0 | AA15: =SUM(O15:Z15) -> 0 | AB15: 0 | AC15: 0 | AD15: 0 | AE15: 0 | AF15: =SUM(AB15:AE15) -> 0 | AG15: =IF((B15+K15+N15+AA15+AF15)/5=B15,"Todo Bien :D","Algo esta Mal :c") -> Todo Bien :D
... A68: Solicitud de información de la plataforma | B68: 3 | C68: 0 | D68: 2 | E68: 0 | F68: 0 | G68: 0 | H68: 0 | I68: 1 | J68: 0 | K68: =SUM(C68:J68) -> 3 | L68: 3 | M68: 0 | N68: =SUM(L68:M68) -> 3 | O68: 2 | P68: 0 | Q68: 0 | R68: 1 | S68: 0 | T68: 0 | U68: 0 | V68: 0 | W68: 0 | X68: 0 | Y68: 0 | Z68: 0 | AA68: =SUM(O68:Z68) -> 3 | AB68: 3 | AC68: 0 | AD68: 0 | AE68: 0 | AF68: =SUM(AB68:AE68) -> 3 | AG68: =IF((B68+K68+N68+AA68+AF68)/5=B68,"Todo Bien :D","Algo esta Mal :c") -> Todo Bien :D
A69: TOTAL | B69: =SUM(B4:B68) -> 255 | C69: =SUM(C3:C68) -> 3 | D69: =SUM(D3:D68) -> 236 | E69: =SUM(E3:E68) -> 3 | F69: =SUM(F3:F68) -> 1 | G69: =SUM(G3:G68) -> 0 | H69: =SUM(H3:H68) -> 0 | I69: =SUM(I3:I68) -> 12 | J69: =SUM(J3:J68) -> 0 | K69: =SUM(C69:J69) -> 255 | L69: =SUM(L3:L68) -> 255 | M69: =SUM(M3:M68) -> 0 | N69: =SUM(L69:M69) -> 255 | O69: =SUM(O3:O68) -> 103 | P69: =SUM(P3:P68) -> 5 | Q69: =SUM(Q3:Q68) -> 0 | R69: =SUM(R3:R68) -> 59 | S69: =SUM(S3:S68) -> 0 | T69: =SUM(T3:T68) -> 1 | U69: =SUM(U3:U68) -> 37 | V69: =SUM(V3:V68) -> 36 | ... Z69: =SUM(Z3:Z68) -> 8 | AA69: =SUM(O69:Z69) -> 255 | AB69: =SUM(AB3:AB68) -> 251 | AC69: =SUM(AC3:AC68) -> 0 | AD69: =SUM(AD3:AD68) -> 1 | AE69: =SUM(AE3:AE68) -> 3 | AF69: =SUM(AB69:AE69) -> 255 | AG69: =IF((B69+K69+N69+AA69+AF69)/5=B69,"Todo Bien :D","Algo esta Mal :c") -> Todo Bien :D
Q70: 0

Sheet Agosto
A1: SERVICIO RELACIONADO | C1: TIQUETS POR CANAL | L1: TIPO | O1: ROL USUARIO | AB1: PRIORIDAD | AG1: TOTALES
A3: =IF((B69+K69+N69+AA69+AF69)/5=B69,"Todo Bien :D","Algo esta Mal :c") -> Todo Bien :D | B3: Cantidad x Servicio | C3: Chat | D3: Correo | E3: Formulario Web | F3: Facebook | G3: Memorandum | H3: Presencial | I3: Teléfono | J3: Twitter | K3: TOTAL | L3: Solicitud | M3: Incidente | N3: TOTAL | O3: Estudiante | P3: Estudiante FundaTEC | Q3: Estudiante Colegio Científico | R3: Profesor | S3: Profesor FundaTEC | T3: Profesor Colegio Científico | U3: Administrativo | V3: Administrativo FundaTEC | W3: Director/Coordinador | X3: Director/Coordinador FundaTEC | Y3: Director/Coordinador Colegio Científico | Z3: Externo | AA3: TOTAL | AB3: Normal | AC3: Baja | AD3: Alta | AE3: Urgente | AF3: TOTAL
A4: Acceso a la plataforma TEC Digital | B4: 32 | C4: 0 | D4: 27 | E4: 0 | F4: 0 | G4: 0 | H4: 0 | I4: 5 | J4: 0 | K4: =SUM(C4:J4) -> 32 | L4: 32 | M4: 0 | N4: =SUM(L4:M4) -> 32 | O4: 16 | P4: 0 | Q4: 0 | R4: 4 | S4: 0 | T4: 0 | U4: 6 | V4: 0 | W4: 0 | X4: 0 | Y4: 0 | Z4: 6 | AA4: =SUM(O4:Z4) -> 32 | AB4: 31 | AC4: 0 | AD4: 0 | AE4: 1 | AF4: =SUM(AB4:AE4) -> 32 | AG4: =IF((B4+K4+N4+AA4+AF4)/5=B4,"Todo Bien :D","Algo esta Mal :c") -> Todo Bien :D
A5: Acreditación | B5: 0 | C5: 0 | D5: 0 | E5: 0 | F5: 0 | G5: 0 | H5: 0 | I5: 0 | J5: 0 | K5: =SUM(C5:J5) -> 0 | L5: 0 | M5: 0 | N5: =SUM(L5:M5) -> 0 | O5: 0 | P5: 0 | Q5: 0 | R5: 0 | S5: 0 | T5: 0 | U5: 0 | V5: 0 | W5: 0 | X5: 0 | Y5: 0 | Z5: 0 | AA5: =SUM(O5:Z5) -> 0 | AB5: 0 | AC5: 0 | AD5: 0 | AE5: 0 | AF5: =SUM(AB5:AE5) -> 0 | AG5: =IF((B5+K5+N5+AA5+AF5)/5=B5,"Todo Bien :D","Algo esta Mal :c") -> Todo Bien :D
A6: Activar cuentas de usuario | B6: 21 | C6: 0 | D6: 16 | E6: 0 | F6: 0 | G6: 0 | H6: 0 | I6: 5 | J6: 0 | K6: =SUM(C6:J6) -> 21 | L6: 21 | M6: 0 | N6: =SUM(L6:M6) -> 21 | O6: 11 | P6: 0 | Q6: 0 | R6: 4 | S6: 0 | T6: 0 | U6: 3 | V6: 0 | W6: 1 | X6: 0 | Y6: 0 | Z6: 2 | AA6: =SUM(O6:Z6) -> 21 | AB6: 21 | AC6: 0 | AD6: 0 | AE6: 0 | AF6: =SUM(AB6:AE6) -> 21 | AG6: =IF((B6+K6+N6+AA6+AF6)/5=B6,"Todo Bien :D","Algo esta Mal :c") -> Todo Bien :D
A7: Activar curso | B7: 2 | C7: 0 | D7: 2 | E7: 0 | F7: 0 | G7: 0 | H7: 0 | I7: 0 | J7: 0 | K7: =SUM(C7:J7) -> 2 | L7: 2 | M7: 0 | N7: =SUM(L7:M7) -> 2 | O7: 0 | P7: 0 | Q7: 0 | R7: 1 | S7: 0 | T7: 0 | U7: 1 | V7: 0 | W7: 0 | X7: 0 | Y7: 0 | Z7: 0 | AA7: =SUM(O7:Z7) -> 2 | AB7: 2 | AC7: 0 | AD7: 0 | AE7: 0 | AF7: =SUM(AB7:AE7) -> 2 | AG7: =IF((B7+K7+N7+AA7+AF7)/5=B7,"Todo Bien :D","Algo esta Mal :c") -> Todo Bien :D
A8: Actualizar cursos a estudiantes | B8: 5 | C8: 0 | D8: 5 | E8: 0 | F8: 0 | G8: 0 | H8: 0 | I8: 0 | J8: 0 | K8: =SUM(C8:J8) -> 5 | L8: 5 | M8: 0 | N8: =SUM(L8:M8) -> 5 | O8: 4 | P8: 0 | Q8: 0 | R8: 0 | S8: 0 | T8: 0 | U8: 1 | V8: 0 | W8: 0 | X8: 0 | Y8: 0 | Z8: 0 | AA8: =SUM(O8:Z8) -> 5 | AB8: 5 | AC8: 0 | AD8: 0 | AE8: 0 | AF8: =SUM(AB8:AE8) -> 5 | AG8: =IF((B8+K8+N8+AA8+AF8)/5=B8,"Todo Bien :D","Algo esta Mal :c") -> Todo Bien :D
A9: Actualizar miembros de comunidades | B9: 35 | C9: 3 | D9: 31 | E9: 0 | F9: 0 | G9: 0 | H9: 1 | I9: 0 | J9: 0 | K9: =SUM(C9:J9) -> 35 | L9: 35 | M9: 0 | N9: =SUM(L9:M9) -> 35 | O9: 5 | P9: 0 | Q9: 0 | R9: 27 | S9: 0 | T9: 0 | U9: 1 | V9: 0 | W9: 2 | X9: 0 | Y9: 0 | Z9: 0 | AA9: =SUM(O9:Z9) -> 35 | AB9: 35 | AC9: 0 | AD9: 0 | AE9: 0 | AF9: =SUM(AB9:AE9) -> 35 | AG9: =IF((B9+K9+N9+AA9+AF9)/5=B9,"Todo Bien :D","Algo esta Mal :c") -> Todo Bien :D
A10: Administrador de asistencia | B10: 0 | C10: 0 | D10: 0 | E10: 0 | F10: 0 | G10: 0 | H10: 0 | I10: 0 | J10: 0 | K10: =SUM(C10:J10) -> 0 | L10: 0 | M10: 0 | N10: =SUM(L10:M10) -> 0 | O10: 0 | P10: 0 | Q10: 0 | R10: 0 | S10: 0 | T10: 0 | U10: 0 | V10: 0 | W10: 0 | X10: 0 | Y10: 0 | Z10: 0 | AA10: =SUM(O10:Z10) -> 0 | AB10: 0 | AC10: 0 | AD10: 0 | AE10: 0 | AF10: =SUM(AB10:AE10) -> 0 | AG10: =IF((B10+K10+N10+AA10+AF10)/5=B10,"Todo Bien :D","Algo esta Mal :c") -> Todo Bien :D
A11: Administrador Programa de Curso | B11: 0 | C11: 0 | D11: 0 | E11: 0 | F11: 0 | G11: 0 | H11: 0 | I11: 0 | J11: 0 | K11: =SUM(C11:J11) -> 0 | L11: 0 | M11: 0 | N11: =SUM(L11:M11) -> 0 | O11: 0 | P11: 0 | Q11: 0 | R11: 0 | S11: 0 | T11: 0 | U11: 0 | V11: 0 | W11: 0 | X11: 0 | Y11: 0 | Z11: 0 | AA11: =SUM(O11:Z11) -> 0 | AB11: 0 | AC11: 0 | AD11: 0 | AE11: 0 | AF11: =SUM(AB11:AE11) -> 0 | AG11: =IF((B11+K11+N11+AA11+AF11)/5=B11,"Todo Bien :D","Algo esta Mal :c") -> Todo Bien :D
A12: Agregar/cambiar asociación de estudiante a curso | B12: 47 | C12: 0 | D12: 38 | E12: 0 | F12: 0 | G12: 0 | H12: 6 | I12: 3 | J12: 0 | K12: =SUM(C12:J12) -> 47 | L12: 47 | M12: 0 | N12: =SUM(L12:M12) -> 47 | O12: 29 | P12: 1 | Q12: 0 | R12: 9 | S12: 0 | T12: 0 | U12: 8 | V12: 0 | W12: 0 | X12: 0 | Y12: 0 | Z12: 0 | AA12: =SUM(O12:Z12) -> 47 | AB12: 47 | AC12: 0 | AD12: 0 | AE12: 0 | AF12: =SUM(AB12:AE12) -> 47 | AG12: =IF((B12+K12+N12+AA12+AF12)/5=B12,"Todo Bien :D","Algo esta Mal :c") -> Todo Bien :D
A13: Agregar/cambiar asociación de profesor a curso | B13: 32 | C13: 0 | D13: 27 | E13: 2 | F13: 0 | G13: 0 | H13: 1 | I13: 2 | J13: 0 | K13: =SUM(C13:J13) -> 32 | L13: 32 | M13: 0 | N13: =SUM(L13:M13) -> 32 | O13: 0 | P13: 0 | Q13: 0 | R13: 20 | S13: 0 | T13: 0 | U13: 7 | V13: 0 | W13: 5 | X13: 0 | Y13: 0 | Z13: 0 | AA13: =SUM(O13:Z13) -> 32 | AB13: 32 | AC13: 0 | AD13: 0 | AE13: 0 | AF13: =SUM(AB13:AE13) -> 32 | AG13: =IF((B13+K13+N13+AA13+AF13)/5=B13,"Todo Bien :D","Algo esta Mal :c") -> Todo Bien :D
