Workbook

Sheet Enero
A1: SERVICIO RELACIONADO | C1: TIQUETS POR CANAL | L1: TIPO | O1: ROL USUARIO | AB1: PRIORIDAD | AG1: TOTALES
A3: =IF((B67+K67+N67+AA67+AF67)/5=B67,"Todo Bien :D","Algo esta Mal :c") -> Todo Bien :D | B3: Cantidad x Servicio | C3: Chat | D3: Correo | E3: Formulario Web | F3: Facebook | G3: Memorandum | H3: Presencial | I3: Teléfono | J3: Twitter | K3: TOTAL | L3: Solicitud | M3: Incidente | N3: TOTAL | O3: Estudiante | P3: Estudiante FundaTEC | Q3: Estudiante Colegio Científico | R3: Profesor | S3: Profesor FundaTEC | T3: Profesor Colegio Científico | U3: Administrativo | V3: Administrativo FundaTEC | W3: Director/Coordinador | X3: Director/Coordinador FundaTEC | Y3: Director/Coordinador Colegio Científico | Z3: Externo | AA3: TOTAL | AB3: Normal | AC3: Baja | AD3: Alta | AE3: Urgente | AF3: TOTAL
A4: Acceso a la plataforma TEC Digital | B4: 76 | C4: 0 | D4: 71 | E4: 0 | F4: 0 | G4: 0 | H4: 0 | I4: 5 | J4: 0 | K4: =SUM(C4:J4) -> 76 | L4: 75 | M4: 1 | N4: =SUM(L4:M4) -> 76 | O4: 68 | P4: 1 | Q4: 0 | R4: 3 | S4: 0 | T4: 0 | U4: 0 | V4: 2 | W4: 0 | X4: 0 | Y4: 0 | Z4: 2 | AA4: =SUM(O4:Z4) -> 76 | AB4: 71 | AC4: 0 | AD4: 4 | AE4: 1 | AF4: =SUM(AB4:AE4) -> 76 | AG4: =IF((B4+K4+N4+AA4+AF4)/5=B4,"Todo Bien :D","Algo esta Mal :c") -> Todo Bien :D
A5: Acreditación | B5: 0 | C5: 0 | D5: 0 | E5: 0 | F5: 0 | G5: 0 | H5: 0 | I5: 0 | J5: 0 | K5: =SUM(C5:J5) -> 0 | L5: 0 | M5: 0 | N5: =SUM(L5:M5) -> 0 | O5: 0 | P5: 0 | Q5: 0 | R5: 0 | S5: 0 | T5: 0 | U5: 0 | V5: 0 | W5: 0 | X5: 0 | Y5: 0 | Z5: 0 | AA5: =SUM(O5:Z5) -> 0 | AB5: 0 | AC5: 0 | AD5: 0 | AE5: 0 | AF5: =SUM(AB5:AE5) -> 0 | AG5: =IF((B5+K5+N5+AA5+AF5)/5=B5,"Todo Bien :D","Algo esta Mal :c") -> Todo Bien :D
A6: Activar cuentas de usuario | B6: 2 | C6: 0 | D6: 2 | E6: 0 | F6: 0 | G6: 0 | H6: 0 | I6: 0 | J6: 0 | K6: =SUM(C6:J6) -> 2 | L6: 2 | M6: 0 | N6: =SUM(L6:M6) -> 2 | O6: 0 | P6: 0 | Q6: 0 | R6: 1 | S6: 0 | T6: 0 | U6: 1 | V6: 0 | W6: 0 | X6: 0 | Y6: 0 | Z6: 0 | AA6: =SUM(O6:Z6) -> 2 | AB6: 2 | AC6: 0 | AD6: 0 | AE6: 0 | AF6: =SUM(AB6:AE6) -> 2 | AG6: =IF((B6+K6+N6+AA6+AF6)/5=B6,"Todo Bien :D","Algo esta Mal :c") -> Todo Bien :D
A7: Activar curso | B7: 1 | C7: 0 | D7: 0 | E7: 0 | F7: 0 | G7: 0 | H7: 0 | I7: 1 | J7: 0 | K7: =SUM(C7:J7) -> 1 | L7: 1 | M7: 0 | N7: =SUM(L7:M7) -> 1 | O7: 1 | P7: 0 | Q7: 0 | R7: 0 | S7: 0 | T7: 0 | U7: 0 | V7: 0 | W7: 0 | X7: 0 | Y7: 0 | Z7: 0 | AA7: =SUM(O7:Z7) -> 1 | AB7: 1 | AC7: 0 | AD7: 0 | AE7: 0 | AF7: =SUM(AB7:AE7) -> 1 | AG7: =IF((B7+K7+N7+AA7+AF7)/5=B7,"Todo Bien :D","Algo esta Mal :c") -> Todo Bien :D
A8: Actualizar cursos a estudiantes | B8: 0 | C8: 0 | D8: 0 | E8: 0 | F8: 0 | G8: 0 | H8: 0 | I8: 0 | J8: 0 | K8: =SUM(C8:J8) -> 0 | L8: 0 | M8: 0 | N8: =SUM(L8:M8) -> 0 | O8: 0 | P8: 0 | Q8: 0 | R8: 0 | S8: 0 | T8: 0 | U8: 0 | V8: 0 | W8: 0 | X8: 0 | Y8: 0 | Z8: 0 | AA8: =SUM(O8:Z8) -> 0 | AB8: 0 | AC8: 0 | AD8: 0 | AE8: 0 | AF8: =SUM(AB8:AE8) -> 0 | AG8: =IF((B8+K8+N8+AA8+AF8)/5=B8,"Todo Bien :D","Algo esta Mal :c") -> Todo Bien :D
A9: Actualizar miembros de comunidades | B9: 0 | C9: 0 | D9: 0 | E9: 0 | F9: 0 | G9: 0 | H9: 0 | I9: 0 | J9: 0 | K9: =SUM(C9:J9) -> 0 | L9: 0 | M9: 0 | N9: =SUM(L9:M9) -> 0 | O9: 0 | P9: 0 | Q9: 0 | R9: 0 | S9: 0 | T9: 0 | U9: 0 | V9: 0 | W9: 0 | X9: 0 | Y9: 0 | Z9: 0 | AA9: =SUM(O9:Z9) -> 0 | AB9: 0 | AC9: 0 | AD9: 0 | AE9: 0 | AF9: =SUM(AB9:AE9) -> 0 | AG9: =IF((B9+K9+N9+AA9+AF9)/5=B9,"Todo Bien :D","Algo esta Mal :c") -> Todo Bien :D
A10: Administrador de asistencia | B10: 0 | C10: 0 | D10: 0 | E10: 0 | F10: 0 | G10: 0 | H10: 0 | I10: 0 | J10: 0 | K10: =SUM(C10:J10) -> 0 | L10: 0 | M10: 0 | N10: =SUM(L10:M10) -> 0 | O10: 0 | P10: 0 | Q10: 0 | R10: 0 | S10: 0 | T10: 0 | U10: 0 | V10: 0 | W10: 0 | X10: 0 | Y10: 0 | Z10: 0 | AA10: =SUM(O10:Z10) -> 0 | AB10: 0 | AC10: 0 | AD10: 0 | AE10: 0 | AF10: =SUM(AB10:AE10) -> 0 | AG10: =IF((B10+K10+N10+AA10+AF10)/5=B10,"Todo Bien :D","Algo esta Mal :c") -> Todo Bien :D
A11: Administrador Programa de Curso | B11: 0 | C11: 0 | D11: 0 | E11: 0 | F11: 0 | G11: 0 | H11: 0 | I11: 0 | J11: 0 | K11: =SUM(C11:J11) -> 0 | L11: 0 | M11: 0 | N11: =SUM(L11:M11) -> 0 | O11: 0 | P11: 0 | Q11: 0 | R11: 0 | S11: 0 | T11: 0 | U11: 0 | V11: 0 | W11: 0 | X11: 0 | Y11: 0 | Z11: 0 | AA11: =SUM(O11:Z11) -> 0 | AB11: 0 | AC11: 0 | AD11: 0 | AE11: 0 | AF11: =SUM(AB11:AE11) -> 0 | AG11: =IF((B11+K11+N11+AA11+AF11)/5=B11,"Todo Bien :D","Algo esta Mal :c") -> Todo Bien :D
A12: Agregar/cambiar asociación de estudiante a curso | B12: 12 | C12: 0 | D12: 11 | E12: 0 | F12: 0 | G12: 0 | H12: 1 | I12: 0 | J12: 0 | K12: =SUM(C12:J12) -> 12 | L12: 12 | M12: 0 | N12: =SUM(L12:M12) -> 12 | O12: 6 | P12: 0 | Q12: 0 | R12: 2 | S12: 0 | T12: 0 | U12: 4 | V12: 0 | W12: 0 | X12: 0 | Y12: 0 | Z12: 0 | AA12: =SUM(O12:Z12) -> 12 | AB12: 12 | AC12: 0 | AD12: 0 | AE12: 0 | AF12: =SUM(AB12:AE12) -> 12 | AG12: =IF((B12+K12+N12+AA12+AF12)/5=B12,"Todo Bien :D","Algo esta Mal :c") -> Todo Bien :D
A13: Agregar/cambiar asociación de profesor a curso | B13: 16 | C13: 1 | D13: 13 | E13: 0 | F13: 0 | G13: 0 | H13: 0 | I13: 2 | J13: 0 | K13: =SUM(C13:J13) -> 16 | L13: 16 | M13: 0 | N13: =SUM(L13:M13) -> 16 | O13: 0 | P13: 0 | Q13: 0 | R13: 8 | S13: 0 | T13: 0 | U13: 6 | V13: 0 | W13: 2 | X13: 0 | Y13: 0 | Z13: 0 | AA13: =SUM(O13:Z13) -> 16 | AB13: 14 | AC13: 0 | AD13: 2 | AE13: 0 | AF13: =SUM(AB13:AE13) -> 16 | AG13: =IF((B13+K13+N13+AA13+AF13)/5=B13,"Todo Bien :D","Algo esta Mal :c") -> Todo Bien :D
A14: Agregar/cambiar asociación de usuario a comunidad | B14: 5 | C14: 0 | D14: 5 | E14: 0 | F14: 0 | G14: 0 | H14: 0 | I14: 0 | J14: 0 | K14: =SUM(C14:J14) -> 5 | L14: 5 | M14: 0 | N14: =SUM(L14:M14) -> 5 | O14: 3 | P14: 0 | Q14: 0 | R14: 1 | S14: 0 | T14: 0 | U14: 0 | V14: 0 | W14: 1 | X14: 0 | Y14: 0 | Z14: 0 | AA14: =SUM(O14:Z14) -> 5 | AB14: 5 | AC14: 0 | AD14: 0 | AE14: 0 | AF14: =SUM(AB14:AE14) -> 5 | AG14: =IF((B14+K14+N14+AA14+AF14)/5=B14,"Todo Bien :D","Algo esta Mal :c") -> Todo Bien :D
A15: Agregar/cambiar asociación estudiante a curso Colegio Científico | B15: 0 | C15: 0 | D15: 0 | E15: 0 | F15: 0 | G15: 0 | H15: 0 | I15: 0 | J15: 0 | K15: =SUM(C15:J15) -> 0 | L15: 0 | M15: 0 | N15: 0 | O15: 0 | P15: 0 | Q15: 0 | R15: 0 | S15: 0 | T15: 0 | U15: 0 | V15: 0 | W15: 0 | X15: 0 | Y15: 0 | Z15: 0 | AA15: =SUM(O15:Z15) -> 0 | AB15: 0 | AC15: 0 | AD15: 0 | AE15: 0 | AF15: =SUM(AB15:AE15) -> 0 | AG15: =IF((B15+K15+N15+AA15+AF15)/5=B15,"Todo Bien :D","Algo esta Mal :c") -> Todo Bien :D
A16: Agregar/cambiar asociación estudiante a curso FundaTEC | B16: 1 | C16: 0 | D16: 1 | E16: 0 | F16: 0 | G16: 0 | H16: 0 | I16: 0 | J16: 0 | K16: =SUM(C16:J16) -> 1 | L16: 1 | M16: 0 | N16: =SUM(L16:M16) -> 1 | O16: 0 | P16: 0 | Q16: 0 | R16: 0 | S16: 0 | T16: 0 | U16: 0 | V16: 1 | W16: 0 | X16: 0 | Y16: 0 | Z16: 0 | AA16: =SUM(O16:Z16) -> 1 | AB16: 1 | AC16: 0 | AD16: 0 | AE16: 0 | AF16: =SUM(AB16:AE16) -> 1 | AG16: =IF((B16+K16+N16+AA16+AF16)/5=B16,"Todo Bien :D","Algo esta Mal :c") -> Todo Bien :D
A17: Asignación de permisos especiales | B17: 6 | C17: 0 | D17: 6 | E17: 0 | F17: 0 | G17: 0 | H17: 0 | I17: 0 | J17: 0 | K17: =SUM(C17:J17) -> 6 | L17: 6 | M17: 0 | N17: =SUM(L17:M17) -> 6 | O17: 0 | P17: 0 | Q17: 0 | R17: 2 | S17: 0 | T17: 0 | U17: 3 | V17: 0 | W17: 1 | X17: 0 | Y17: 0 | Z17: 0 | AA17: =SUM(O17:Z17) -> 6 | AB17: 6 | AC17: 0 | AD17: 0 | AE17: 0 | AF17: =SUM(AB17:AE17) -> 6 | AG17: =IF((B17+K17+N17+AA17+AF17)/5=B17,"Todo Bien :D","Algo esta Mal :c") -> Todo Bien :D
A18: Atención personalizada a usuarios | B18: 46 | C18: 0 | D18: 45 | E18: 0 | F18: 0 | G18: 0 | H18: 1 | I18: 0 | J18: 0 | K18: =SUM(C18:J18) -> 46 | L18: 46 | M18: 0 | N18: =SUM(L18:M18) -> 46 | O18: 27 | P18: 2 | Q18: 0 | R18: 10 | S18: 0 | T18: 0 | U18: 0 | V18: 0 | W18: 1 | X18: 0 | Y18: 6 | Z18: 0 | AA18: =SUM(O18:Z18) -> 46 | AB18: 46 | AC18: 0 | AD18: 0 | AE18: 0 | AF18: =SUM(AB18:AE18) -> 46 | AG18: =IF((B18+K18+N18+AA18+AF18)/5=B18,"Todo Bien :D","Algo esta Mal :c") -> Todo Bien :D
A19: BiciTEC | B19: 0 | C19: 0 | D19: 0 | E19: 0 | F19: 0 | G19: 0 | H19: 0 | I19: 0 | J19: 0 | K19: =SUM(C19:J19) -> 0 | L19: 0 | M19: 0 | N19: =SUM(L19:M19) -> 0 | O19: 0 | P19: 0 | Q19: 0 | R19: 0 | S19: 0 | T19: 0 | U19: 0 | V19: 0 | W19: 0 | X19: 0 | Y19: 0 | Z19: 0 | AA19: 0 | AB19: 0 | AC19: 0 | AD19: 0 | AE19: 0 | AF19: =SUM(AB19:AE19) -> 0 | AG19: =IF((B19+K19+N19+AA19+AF19)/5=B19,"Todo Bien :D","Algo esta Mal :c") -> Todo Bien :D
A20: Calendario | B20: 0 | C20: 0 | D20: 0 | E20: 0 | F20: 0 | G20: 0 | H20: 0 | I20: 0 | J20: 0 | K20: =SUM(C20:J20) -> 0 | L20: 0 | M20: 0 | N20: =SUM(L20:M20) -> 0 | O20: 0 | P20: 0 | Q20: 0 | R20: 0 | S20: 0 | T20: 0 | U20: 0 | V20: 0 | W20: 0 | X20: 0 | Y20: 0 | Z20: 0 | AA20: =SUM(O20:Z20) -> 0 | AB20: 0 | AC20: 0 | AD20: 0 | AE20: 0 | AF20: =SUM(AB20:AE20) -> 0 | AG20: =IF((B20+K20+N20+AA20+AF20)/5=B20,"Todo Bien :D","Algo esta Mal :c") -> Todo Bien :D
A21: Cambiar información personal | B21: 5 | C21: 0 | D21: 3 | E21: 0 | F21: 0 | G21: 0 | H21: 1 | I21: 1 | J21: 0 | K21: =SUM(C21:J21) -> 5 | L21: 5 | M21: 0 | N21: =SUM(L21:M21) -> 5 | O21: 5 | P21: 0 | Q21: 0 | R21: 0 | S21: 0 | T21: 0 | U21: 0 | V21: 0 | W21: 0 | X21: 0 | Y21: 0 | Z21: 0 | AA21: =SUM(O21:Z21) -> 5 | AB21: 5 | AC21: 0 | AD21: 0 | AE21: 0 | AF21: =SUM(AB21:AE21) -> 5 | AG21: =IF((B21+K21+N21+AA21+AF21)/5=B21,"Todo Bien :D","Algo esta Mal :c") -> Todo Bien :D
A22: Cambio de contraseña | B22: 1 | C22: 0 | D22: 0 | E22: 0 | F22: 0 | G22: 0 | H22: 0 | I22: 1 | J22: 0 | K22: =SUM(C22:J22) -> 1 | L22: 1 | M22: 0 | N22: =SUM(L22:M22) -> 1 | O22: 0 | P22: 0 | Q22: 0 | R22: 0 | S22: 0 | T22: 0 | U22: 1 | V22: 0 | W22: 0 | X22: 0 | Y22: 0 | Z22: 0 | AA22: =SUM(O22:Z22) -> 1 | AB22: 1 | AC22: 0 | AD22: 0 | AE22: 0 | AF22: =SUM(AB22:AE22) -> 1 | AG22: =IF((B22+K22+N22+AA22+AF22)/5=B22,"Todo Bien :D","Algo esta Mal :c") -> Todo Bien :D
A23: Cambio de contraseña FundaTEC | B23: 2 | C23: 0 | D23: 2 | E23: 0 | F23: 0 | G23: 0 | H23: 0 | I23: 0 | J23: 0 | K23: =SUM(C23:J23) -> 2 | L23: 2 | M23: 0 | N23: =SUM(L23:M23) -> 2 | O23: 2 | P23: 0 | Q23: 0 | R23: 0 | S23: 0 | T23: 0 | U23: 0 | V23: 0 | W23: 0 | X23: 0 | Y23: 0 | Z23: 0 | AA23: =SUM(O23:Z23) -> 2 | AB23: 2 | AC23: 0 | AD23: 0 | AE23: 0 | AF23: =SUM(AB23:AE23) -> 2 | AG23: =IF((B23+K23+N23+AA23+AF23)/5=B23,"Todo Bien :D","Algo esta Mal :c") -> Todo Bien :D
A24: Carpeta Tareas | B24: 0 | C24: 0 | D24: 0 | E24: 0 | F24: 0 | G24: 0 | H24: 0 | I24: 0 | J24: 0 | K24: =SUM(C24:J24) -> 0 | L24: 0 | M24: 0 | N24: =SUM(L24:M24) -> 0 | O24: 0 | P24: 0 | Q24: 0 | R24: 0 | S24: 0 | T24: 0 | U24: 0 | V24: 0 | W24: 0 | X24: 0 | Y24: 0 | Z24: 0 | AA24: =SUM(O24:Z24) -> 0 | AB24: 0 | AC24: 0 | AD24: 0 | AE24: 0 | AF24: =SUM(AB24:AE24) -> 0 | AG24: =IF((B24+K24+N24+AA24+AF24)/5=B24,"Todo Bien :D","Algo esta Mal :c") -> Todo Bien :D
A25: Carpetas/Documentos | B25: 4 | C25: 1 | D25: 3 | E25: 0 | F25: 0 | G25: 0 | H25: 0 | I25: 0 | J25: 0 | K25: =SUM(C25:J25) -> 4 | L25: 4 | M25: 0 | N25: =SUM(L25:M25) -> 4 | O25: 1 | P25: 0 | Q25: 0 | R25: 3 | S25: 0 | T25: 0 | U25: 0 | V25: 0 | W25: 0 | X25: 0 | Y25: 0 | Z25: 0 | AA25: =SUM(O25:Z25) -> 4 | AB25: 4 | AC25: 0 | AD25: 0 | AE25: 0 | AF25: =SUM(AB25:AE25) -> 4 | AG25: =IF((B25+K25+N25+AA25+AF25)/5=B25,"Todo Bien :D","Algo esta Mal :c") -> Todo Bien :D
A26: Configuración de Comunidades/Cursos | B26: 7 | C26: 4 | D26: 0 | E26: 0 | F26: 0 | G26: 0 | H26: 0 | I26: 3 | J26: 0 | K26: =SUM(C26:J26) -> 7 | L26: 5 | M26: 2 | N26: =SUM(L26:M26) -> 7 | O26: 0 | P26: 0 | Q26: 0 | R26: 6 | S26: 0 | T26: 0 | U26: 1 | V26: 0 | W26: 0 | X26: 0 | Y26: 0 | Z26: 0 | AA26: =SUM(O26:Z26) -> 7 | AB26: 6 | AC26: 0 | AD26: 0 | AE26: 1 | AF26: =SUM(AB26:AE26) -> 7 | AG26: =IF((B26+K26+N26+AA26+AF26)/5=B26,"Todo Bien :D","Algo esta Mal :c") -> Todo Bien :D
A27: Consulta para Directores | B27: 0 | C27: 0 | D27: 0 | E27: 0 | F27: 0 | G27: 0 | H27: 0 | I27: 0 | J27: 0 | K27: =SUM(C27:J27) -> 0 | L27: 0 | M27: 0 | N27: =SUM(L27:M27) -> 0 | O27: 0 | P27: 0 | Q27: 0 | R27: 0 | S27: 0 | T27: 0 | U27: 0 | V27: 0 | W27: 0 | X27: 0 | Y27: 0 | Z27: 0 | AA27: 0 | AB27: 0 | AC27: 0 | AD27: 0 | AE27: 0 | AF27: =SUM(AB27:AE27) -> 0 | AG27: =IF((B27+K27+N27+AA27+AF27)/5=B27,"Todo Bien :D","Algo esta Mal :c") -> Todo Bien :D
A28: Control de plagio | B28: 0 | C28: 0 | D28: 0 | E28: 0 | F28: 0 | G28: 0 | H28: 0 | I28: 0 | J28: 0 | K28: =SUM(C28:J28) -> 0 | L28: 0 | M28: 0 | N28: =SUM(L28:M28) -> 0 | O28: 0 | P28: 0 | Q28: 0 | R28: 0 | S28: 0 | T28: 0 | U28: 0 | V28: 0 | W28: 0 | X28: 0 | Y28: 0 | Z28: 0 | AA28: 0 | AB28: 0 | AC28: 0 | AD28: 0 | AE28: 0 | AF28: =SUM(AB28:AE28) -> 0 | AG28: =IF((B28+K28+N28+AA28+AF28)/5=B28,"Todo Bien :D","Algo esta Mal :c") -> Todo Bien :D
A29: Copiado de contenidos | B29: 2 | C29: 0 | D29: 2 | E29: 0 | F29: 0 | G29: 0 | H29: 0 | I29: 0 | J29: 0 | K29: =SUM(C29:J29) -> 2 | L29: 1 | M29: 1 | N29: =SUM(L29:M29) -> 2 | O29: 0 | P29: 0 | Q29: 0 | R29: 2 | S29: 0 | T29: 0 | U29: 0 | V29: 0 | W29: 0 | X29: 0 | Y29: 0 | Z29: 0 | AA29: =SUM(O29:Z29) -> 2 | AB29: 2 | AC29: 0 | AD29: 0 | AE29: 0 | AF29: =SUM(AB29:AE29) -> 2 | AG29: =IF((B29+K29+N29+AA29+AF29)/5=B29,"Todo Bien :D","Algo esta Mal :c") -> Todo Bien :D
A30: Creación curso Colegio Científico | B30: 1 | C30: 0 | D30: 1 | E30: 0 | F30: 0 | G30: 0 | H30: 0 | I30: 0 | J30: 0 | K30: =SUM(C30:J30) -> 1 | L30: 1 | M30: 0 | N30: =SUM(L30:M30) -> 1 | O30: 0 | P30: 0 | Q30: 0 | R30: 0 | S30: 0 | T30: 0 | U30: 0 | V30: 0 | W30: 0 | X30: 0 | Y30: 1 | Z30: 0 | AA30: =SUM(O30:Z30) -> 1 | AB30: 1 | AC30: 0 | AD30: 0 | AE30: 0 | AF30: =SUM(AB30:AE30) -> 1 | AG30: =IF((B30+K30+N30+AA30+AF30)/5=B30,"Todo Bien :D","Algo esta Mal :c") -> Todo Bien :D
A31: Creación cursos FundaTEC | B31: 11 | C31: 2 | D31: 9 | E31: 0 | F31: 0 | G31: 0 | H31: 0 | I31: 0 | J31: 0 | K31: =SUM(C31:J31) -> 11 | L31: 11 | M31: 0 | N31: =SUM(L31:M31) -> 11 | O31: 0 | P31: 0 | Q31: 0 | R31: 0 | S31: 0 | T31: 0 | U31: 0 | V31: 11 | W31: 0 | X31: 0 | Y31: 0 | Z31: 0 | AA31: =SUM(O31:Z31) -> 11 | AB31: 10 | AC31: 0 | AD31: 0 | AE31: 1 | AF31: =SUM(AB31:AE31) -> 11 | AG31: =IF((B31+K31+N31+AA31+AF31)/5=B31,"Todo Bien :D","Algo esta Mal :c") -> Todo Bien :D
A32: Creación de comunidades | B32: 3 | C32: 0 | D32: 0 | E32: 0 | F32: 0 | G32: 0 | H32: 0 | I32: 3 | J32: 0 | K32: =SUM(C32:J32) -> 3 | L32: 3 | M32: 0 | N32: =SUM(L32:M32) -> 3 | O32: 1 | P32: 0 | Q32: 0 | R32: 1 | S32: 1 | T32: 0 | U32: 0 | V32: 0 | W32: 0 | X32: 0 | Y32: 0 | Z32: 0 | AA32: =SUM(O32:Z32) -> 3 | AB32: 3 | AC32: 0 | AD32: 0 | AE32: 0 | AF32: =SUM(AB32:AE32) -> 3 | AG32: =IF((B32+K32+N32+AA32+AF32)/5=B32,"Todo Bien :D","Algo esta Mal :c") -> Todo Bien :D
A33: Creación de curso | B33: 2 | C33: 0 | D33: 2 | E33: 0 | F33: 0 | G33: 0 | H33: 0 | I33: 0 | J33: 0 | K33: =SUM(C33:J33) -> 2 | L33: 2 | M33: 0 | N33: =SUM(L33:M33) -> 2 | O33: 0 | P33: 0 | Q33: 0 | R33: 0 | S33: 0 | T33: 0 | U33: 1 | V33: 1 | W33: 0 | X33: 0 | Y33: 0 | Z33: 0 | AA33: =SUM(O33:Z33) -> 2 | AB33: 2 | AC33: 0 | AD33: 0 | AE33: 0 | AF33: =SUM(AB33:AE33) -> 2 | AG33: =IF((B33+K33+N33+AA33+AF33)/5=B33,"Todo Bien :D","Algo esta Mal :c") -> Todo Bien :D
A34: Creación de usuarios | B34: 1 | C34: 0 | D34: 1 | E34: 0 | F34: 0 | G34: 0 | H34: 0 | I34: 0 | J34: 0 | K34: =SUM(C34:J34) -> 1 | L34: 1 | M34: 0 | N34: =SUM(L34:M34) -> 1 | O34: 0 | P34: 0 | Q34: 0 | R34: 0 | S34: 0 | T34: 0 | U34: 0 | V34: 1 | W34: 0 | X34: 0 | Y34: 0 | Z34: 0 | AA34: =SUM(O34:Z34) -> 1 | AB34: 1 | AC34: 0 | AD34: 0 | AE34: 0 | AF34: =SUM(AB34:AE34) -> 1 | AG34: =IF((B34+K34+N34+AA34+AF34)/5=B34,"Todo Bien :D","Algo esta Mal :c") -> Todo Bien :D
A35: Creación de usuarios Colegio Científico | B35: 0 | C35: 0 | D35: 0 | E35: 0 | F35: 0 | G35: 0 | H35: 0 | I35: 0 | J35: 0 | K35: =SUM(C35:J35) -> 0 | L35: 0 | M35: 0 | N35: =SUM(L35:M35) -> 0 | O35: 0 | P35: 0 | Q35: 0 | R35: 0 | S35: 0 | T35: 0 | U35: 0 | V35: 0 | W35: 0 | X35: 0 | Y35: 0 | Z35: 0 | AA35: 0 | AB35: 0 | AC35: 0 | AD35: 0 | AE35: 0 | AF35: =SUM(AB35:AE35) -> 0 | AG35: =IF((B35+K35+N35+AA35+AF35)/5=B35,"Todo Bien :D","Algo esta Mal :c") -> Todo Bien :D
A36: Creación de usuarios FundaTEC | B36: 2 | C36: 2 | D36: 0 | E36: 0 | F36: 0 | G36: 0 | H36: 0 | I36: 0 | J36: 0 | K36: =SUM(C36:J36) -> 2 | L36: 2 | M36: 0 | N36: =SUM(L36:M36) -> 2 | O36: 0 | P36: 0 | Q36: 0 | R36: 0 | S36: 2 | T36: 0 | U36: 0 | V36: 0 | W36: 0 | X36: 0 | Y36: 0 | Z36: 0 | AA36: =SUM(O36:Z36) -> 2 | AB36: 2 | AC36: 0 | AD36: 0 | AE36: 0 | AF36: =SUM(AB36:AE36) -> 2 | AG36: =IF((B36+K36+N36+AA36+AF36)/5=B36,"Todo Bien :D","Algo esta Mal :c") -> Todo Bien :D
A37: Curso Móvil | B37: 0 | C37: 0 | D37: 0 | E37: 0 | F37: 0 | G37: 0 | H37: 0 | I37: 0 | J37: 0 | K37: =SUM(C37:J37) -> 0 | L37: 0 | M37: 0 | N37: =SUM(L37:M37) -> 0 | O37: 0 | P37: 0 | Q37: 0 | R37: 0 | S37: 0 | T37: 0 | U37: 0 | V37: 0 | W37: 0 | X37: 0 | Y37: 0 | Z37: 0 | AA37: 0 | AB37: 0 | AC37: 0 | AD37: 0 | AE37: 0 | AF37: =SUM(AB37:AE37) -> 0 | AG37: =IF((B37+K37+N37+AA37+AF37)/5=B37,"Todo Bien :D","Algo esta Mal :c") -> Todo Bien :D
A38: Dashboard | B38: 0 | C38: 0 | D38: 0 | E38: 0 | F38: 0 | G38: 0 | H38: 0 | I38: 0 | J38: 0 | K38: =SUM(C38:J38) -> 0 | L38: 0 | M38: 0 | N38: =SUM(L38:M38) -> 0 | O38: 0 | P38: 0 | Q38: 0 | R38: 0 | S38: 0 | T38: 0 | U38: 0 | V38: 0 | W38: 0 | X38: 0 | Y38: 0 | Z38: 0 | AA38: 0 | AB38: 0 | AC38: 0 | AD38: 0 | AE38: 0 | AF38: =SUM(AB38:AE38) -> 0 | AG38: =IF((B38+K38+N38+AA38+AF38)/5=B38,"Todo Bien :D","Algo esta Mal :c") -> Todo Bien :D
A39: Diagnósticos | B39: 12 | C39: 0 | D39: 7 | E39: 0 | F39: 0 | G39: 0 | H39: 4 | I39: 1 | J39: 0 | K39: =SUM(C39:J39) -> 12 | L39: 12 | M39: 0 | N39: =SUM(L39:M39) -> 12 | O39: 11 | P39: 0 | Q39: 0 | R39: 1 | S39: 0 | T39: 0 | U39: 0 | V39: 0 | W39: 0 | X39: 0 | Y39: 0 | Z39: 0 | AA39: =SUM(O39:Z39) -> 12 | AB39: 12 | AC39: 0 | AD39: 0 | AE39: 0 | AF39: =SUM(AB39:AE39) -> 12 | AG39: =IF((B39+K39+N39+AA39+AF39)/5=B39,"Todo Bien :D","Algo esta Mal :c") -> Todo Bien :D
A40: Diseño instruccional | B40: 0 | C40: 0 | D40: 0 | E40: 0 | F40: 0 | G40: 0 | H40: 0 | I40: 0 | J40: 0 | K40: =SUM(C40:J40) -> 0 | L40: 0 | M40: 0 | N40: =SUM(L40:M40) -> 0 | O40: 0 | P40: 0 | Q40: 0 | R40: 0 | S40: 0 | T40: 0 | U40: 0 | V40: 0 | W40: 0 | X40: 0 | Y40: 0 | Z40: 0 | AA40: 0 | AB40: 0 | AC40: 0 | AD40: 0 | AE40: 0 | AF40: =SUM(AB40:AE40) -> 0 | AG40: =IF((B40+K40+N40+AA40+AF40)/5=B40,"Todo Bien :D","Algo esta Mal :c") -> Todo Bien :D
A41: Envío de comunicados a comunidades | B41: 11 | C41: 0 | D41: 10 | E41: 0 | F41: 0 | G41: 0 | H41: 1 | I41: 0 | J41: 0 | K41: =SUM(C41:J41) -> 11 | L41: 11 | M41: 0 | N41: =SUM(L41:M41) -> 11 | O41: 0 | P41: 0 | Q41: 0 | R41: 1 | S41: 0 | T41: 0 | U41: 10 | V41: 0 | W41: 0 | X41: 0 | Y41: 0 | Z41: 0 | AA41: =SUM(O41:Z41) -> 11 | AB41: 10 | AC41: 0 | AD41: 1 | AE41: 0 | AF41: =SUM(AB41:AE41) -> 11 | AG41: =IF((B41+K41+N41+AA41+AF41)/5=B41,"Todo Bien :D","Algo esta Mal :c") -> Todo Bien :D
...

Sheet Febrero
A1: SERVICIO RELACIONADO | C1: TIQUETS POR CANAL | L1: TIPO | O1: ROL USUARIO | AB1: PRIORIDAD | AG1: TOTALES
A3: =IF((B67+K67+N67+AA67+AF67)/5=B67,"Todo Bien :D","Algo esta Mal :c") -> Todo Bien :D | B3: Cantidad x Servicio | C3: Chat | D3: Correo | E3: Formulario Web | F3: Facebook | G3: Memorandum | H3: Presencial | I3: Teléfono | J3: Twitter | K3: TOTAL | L3: Solicitud | M3: Incidente | N3: TOTAL | O3: Estudiante | P3: Estudiante FundaTEC | Q3: Estudiante Colegio Científico | R3: Profesor | S3: Profesor FundaTEC | T3: Profesor Colegio Científico | U3: Administrativo | V3: Administrativo FundaTEC | W3: Director/Coordinador | X3: Director/Coordinador FundaTEC | Y3: Director/Coordinador Colegio Científico | Z3: Externo | AA3: TOTAL | AB3: Normal | AC3: Baja | AD3: Alta | AE3: Urgente | AF3: TOTAL
A4: Acceso a la plataforma TEC Digital | B4: 69 | C4: 0 | D4: 57 | E4: 0 | F4: 0 | G4: 0 | H4: 6 | I4: 6 | J4: 0 | K4: =SUM(C4:J4) -> 69 | L4: 65 | M4: 4 | N4: =SUM(L4:M4) -> 69 | O4: 56 | P4: 1 | Q4: 0 | R4: 6 | S4: 0 | T4: 0 | U4: 1 | V4: 1 | W4: 1 | X4: 0 | Y4: 0 | Z4: 3 | AA4: =SUM(O4:Z4) -> 69 | AB4: 66 | AC4: 0 | AD4: 2 | AE4: 1 | AF4: =SUM(AB4:AE4) -> 69 | AG4: =IF((B4+K4+N4+AA4+AF4)/5=B4,"Todo Bien :D","Algo esta Mal :c") -> Todo Bien :D
A5: Acreditación | B5: 0 | C5: 0 | D5: 0 | E5: 0 | F5: 0 | G5: 0 | H5: 0 | I5: 0 | J5: 0 | K5: =SUM(C5:J5) -> 0 | L5: 0 | M5: 0 | N5: =SUM(L5:M5) -> 0 | O5: 0 | P5: 0 | Q5: 0 | R5: 0 | S5: 0 | T5: 0 | U5: 0 | V5: 0 | W5: 0 | X5: 0 | Y5: 0 | Z5: 0 | AA5: =SUM(O5:Z5) -> 0 | AB5: 0 | AC5: 0 | AD5: 0 | AE5: 0 | AF5: =SUM(AB5:AE5) -> 0 | AG5: =IF((B5+K5+N5+AA5+AF5)/5=B5,"Todo Bien :D","Algo esta Mal :c") -> Todo Bien :D
A6: Activar cuentas de usuario | B6: 20 | C6: 1 | D6: 13 | E6: 0 | F6: 0 | G6: 0 | H6: 0 | I6: 6 | J6: 0 | K6: =SUM(C6:J6) -> 20 | L6: 20 | M6: 0 | N6: =SUM(L6:M6) -> 20 | O6: 8 | P6: 0 | Q6: 0 | R6: 6 | S6: 0 | T6: 0 | U6: 6 | V6: 0 | W6: 0 | X6: 0 | Y6: 0 | Z6: 0 | AA6: =SUM(O6:Z6) -> 20 | AB6: 20 | AC6: 0 | AD6: 0 | AE6: 0 | AF6: =SUM(AB6:AE6) -> 20 | AG6: =IF((B6+K6+N6+AA6+AF6)/5=B6,"Todo Bien :D","Algo esta Mal :c") -> Todo Bien :D
A7: Activar curso | B7: 4 | C7: 3 | D7: 0 | E7: 0 | F7: 0 | G7: 0 | H7: 0 | I7: 1 | J7: 0 | K7: =SUM(C7:J7) -> 4 | L7: 4 | M7: 0 | N7: =SUM(L7:M7) -> 4 | O7: 0 | P7: 0 | Q7: 0 | R7: 2 | S7: 0 | T7: 0 | U7: 1 | V7: 0 | W7: 1 | X7: 0 | Y7: 0 | Z7: 0 | AA7: =SUM(O7:Z7) -> 4 | AB7: 4 | AC7: 0 | AD7: 0 | AE7: 0 | AF7: =SUM(AB7:AE7) -> 4 | AG7: =IF((B7+K7+N7+AA7+AF7)/5=B7,"Todo Bien :D","Algo esta Mal :c") -> Todo Bien :D
A8: Actualizar cursos a estudiantes | B8: 2 | C8: 0 | D8: 2 | E8: 0 | F8: 0 | G8: 0 | H8: 0 | I8: 0 | J8: 0 | K8: =SUM(C8:J8) -> 2 | L8: 2 | M8: 0 | N8: =SUM(L8:M8) -> 2 | O8: 1 | P8: 0 | Q8: 0 | R8: 0 | S8: 0 | T8: 0 | U8: 1 | V8: 0 | W8: 0 | X8: 0 | Y8: 0 | Z8: 0 | AA8: =SUM(O8:Z8) -> 2 | AB8: 2 | AC8: 0 | AD8: 0 | AE8: 0 | AF8: =SUM(AB8:AE8) -> 2 | AG8: =IF((B8+K8+N8+AA8+AF8)/5=B8,"Todo Bien :D","Algo esta Mal :c") -> Todo Bien :D
A9: Actualizar miembros de comunidades | B9: 29 | C9: 4 | D9: 24 | E9: 0 | F9: 0 | G9: 0 | H9: 1 | I9: 0 | J9: 0 | K9: =SUM(C9:J9) -> 29 | L9: 29 | M9: 0 | N9: =SUM(L9:M9) -> 29 | O9: 0 | P9: 0 | Q9: 0 | R9: 24 | S9: 0 | T9: 0 | U9: 4 | V9: 0 | W9: 1 | X9: 0 | Y9: 0 | Z9: 0 | AA9: =SUM(O9:Z9) -> 29 | AB9: 28 | AC9: 0 | AD9: 1 | AE9: 0 | AF9: =SUM(AB9:AE9) -> 29 | AG9: =IF((B9+K9+N9+AA9+AF9)/5=B9,"Todo Bien :D","Algo esta Mal :c") -> Todo Bien :D
A10: Administrador de asistencia | B10: 0 | C10: 0 | D10: 0 | E10: 0 | F10: 0 | G10: 0 | H10: 0 | I10: 0 | J10: 0 | K10: =SUM(C10:J10) -> 0 | L10: 0 | M10: 0 | N10: =SUM(L10:M10) -> 0 | O10: 0 | P10: 0 | Q10: 0 | R10: 0 | S10: 0 | T10: 0 | U10: 0 | V10: 0 | W10: 0 | X10: 0 | Y10: 0 | Z10: 0 | AA10: =SUM(O10:Z10) -> 0 | AB10: 0 | AC10: 0 | AD10: 0 | AE10: 0 | AF10: =SUM(AB10:AE10) -> 0 | AG10: =IF((B10+K10+N10+AA10+AF10)/5=B10,"Todo Bien :D","Algo esta Mal :c") -> Todo Bien :D
A11: Administrador Programa de Curso | B11: 0 | C11: 0 | D11: 0 | E11: 0 | F11: 0 | G11: 0 | H11: 0 | I11: 0 | J11: 0 | K11: =SUM(C11:J11) -> 0 | L11: 0 | M11: 0 | N11: =SUM(L11:M11) -> 0 | O11: 0 | P11: 0 | Q11: 0 | R11: 0 | S11: 0 | T11: 0 | U11: 0 | V11: 0 | W11: 0 | X11: 0 | Y11: 0 | Z11: 0 | AA11: =SUM(O11:Z11) -> 0 | AB11: 0 | AC11: 0 | AD11: 0 | AE11: 0 | AF11: =SUM(AB11:AE11) -> 0 | AG11: =IF((B11+K11+N11+AA11+AF11)/5=B11,"Todo Bien :D","Algo esta Mal :c") -> Todo Bien :D
A12: Agregar/cambiar asociación de estudiante a curso | B12: 76 | C12: 1 | D12: 65 | E12: 0 | F12: 0 | G12: 0 | H12: 5 | I12: 5 | J12: 0 | K12: =SUM(C12:J12) -> 76 | L12: 75 | M12: 1 | N12: =SUM(L12:M12) -> 76 | O12: 54 | P12: 1 | Q12: 0 | R12: 8 | S12: 0 | T12: 0 | U12: 7 | V12: 2 | W12: 3 | X12: 0 | Y12: 0 | Z12: 1 | AA12: =SUM(O12:Z12) -> 76 | AB12: 68 | AC12: 0 | AD12: 7 | AE12: 1 | AF12: =SUM(AB12:AE12) -> 76 | AG12: =IF((B12+K12+N12+AA12+AF12)/5=B12,"Todo Bien :D","Algo esta Mal :c") -> Todo Bien :D
A13: Agregar/cambiar asociación de profesor a curso | B13: 72 | C13: 6 | D13: 54 | E13: 0 | F13: 0 | G13: 0 | H13: 1 | I13: 11 | J13: 0 | K13: =SUM(C13:J13) -> 72 | L13: 72 | M13: 0 | N13: =SUM(L13:M13) -> 72 | O13: 2 | P13: 0 | Q13: 0 | R13: 38 | S13: 0 | T13: 0 | U13: 23 | V13: 1 | W13: 8 | X13: 0 | Y13: 0 | Z13: 0 | AA13: =SUM(O13:Z13) -> 72 | AB13: 69 | AC13: 0 | AD13: 3 | AE13: 0 | AF13: =SUM(AB13:AE13) -> 72 | AG13: =IF((B13+K13+N13+AA13+AF13)/5=B13,"Todo Bien :D","Algo esta Mal :c") -> Todo Bien :D
A14: Agregar/cambiar asociación de usuario a comunidad | B14: 63 | C14: 6 | D14: 47 | E14: 0 | F14: 0 | G14: 0 | H14: 7 | I14: 3 | J14: 0 | K14: =SUM(C14:J14) -> 63 | L14: 63 | M14: 0 | N14: =SUM(L14:M14) -> 63 | O14: 32 | P14: 0 | Q14: 0 | R14: 26 | S14: 0 | T14: 0 | U14: 5 | V14: 0 | W14: 0 | X14: 0 | Y14: 0 | Z14: 0 | AA14: =SUM(O14:Z14) -> 63 | AB14: 63 | AC14: 0 | AD14: 0 | AE14: 0 | AF14: =SUM(AB14:AE14) -> 63 | AG14: =IF((B14+K14+N14+AA14+AF14)/5=B14,"Todo Bien :D","Algo esta Mal :c") -> Todo Bien :D
A15: Agregar/cambiar asociación estudiante a curso Colegio Científico | B15: 0 | C15: 0 | D15: 0 | E15: 0 | F15: 0 | G15: 0 | H15: 0 | I15: 0 | J15: 0 | K15: =SUM(C15:J15) -> 0 | L15: 0 | M15: 0 | N15: 0 | O15: 0 | P15: 0 | Q15: 0 | R15: 0 | S15: 0 | T15: 0 | U15: 0 | V15: 0 | W15: 0 | X15: 0 | Y15: 0 | Z15: 0 | AA15: =SUM(O15:Z15) -> 0 | AB15: 0 | AC15: 0 | AD15: 0 | AE15: 0 | AF15: =SUM(AB15:AE15) -> 0 | AG15: =IF((B15+K15+N15+AA15+AF15)/5=B15,"Todo Bien :D","Algo esta Mal :c") -> Todo Bien :D
A16: Agregar/cambiar asociación estudiante a curso FundaTEC | B16: 0 | C16: 0 | D16: 0 | E16: 0 | F16: 0 | G16: 0 | H16: 0 | I16: 0 | J16: 0 | K16: =SUM(C16:J16) -> 0 | L16: 0 | M16: 0 | N16: =SUM(L16:M16) -> 0 | O16: 0 | P16: 0 | Q16: 0 | R16: 0 | S16: 0 | T16: 0 | U16: 0 | V16: 0 | W16: 0 | X16: 0 | Y16: 0 | Z16: 0 | AA16: =SUM(O16:Z16) -> 0 | AB16: 0 | AC16: 0 | AD16: 0 | AE16: 0 | AF16: =SUM(AB16:AE16) -> 0 | AG16: =IF((B16+K16+N16+AA16+AF16)/5=B16,"Todo Bien :D","Algo esta Mal :c") -> Todo Bien :D
A17: Asignación de permisos especiales | B17: 4 | C17: 0 | D17: 4 | E17: 0 | F17: 0 | G17: 0 | H17: 0 | I17: 0 | J17: 0 | K17: =SUM(C17:J17) -> 4 | L17: 4 | M17: 0 | N17: =SUM(L17:M17) -> 4 | O17: 0 | P17: 0 | Q17: 0 | R17: 0 | S17: 0 | T17: 0 | U17: 0 | V17: 0 | W17: 4 | X17: 0 | Y17: 0 | Z17: 0 | AA17: =SUM(O17:Z17) -> 4 | AB17: 4 | AC17: 0 | AD17: 0 | AE17: 0 | AF17: =SUM(AB17:AE17) -> 4 | AG17: =IF((B17+K17+N17+AA17+AF17)/5=B17,"Todo Bien :D","Algo esta Mal :c") -> Todo Bien :D
A18: Atención personalizada a usuarios | B18: 80 | C18: 0 | D18: 67 | E18: 0 | F18: 0 | G18: 0 | H18: 7 | I18: 6 | J18: 0 | K18: =SUM(C18:J18) -> 80 | L18: 79 | M18: 1 | N18: =SUM(L18:M18) -> 80 | O18: 51 | P18: 1 | Q18: 0 | R18: 17 | S18: 0 | T18: 0 | U18: 5 | V18: 1 | W18: 3 | X18: 0 | Y18: 0 | Z18: 2 | AA18: =SUM(O18:Z18) -> 80 | AB18: 77 | AC18: 1 | AD18: 2 | AE18: 0 | AF18: =SUM(AB18:AE18) -> 80 | AG18: =IF((B18+K18+N18+AA18+AF18)/5=B18,"Todo Bien :D","Algo esta Mal :c") -> Todo Bien :D
A19: BiciTEC | B19: 0 | C19: 0 | D19: 0 | E19: 0 | F19: 0 | G19: 0 | H19: 0 | I19: 0 | J19: 0 | K19: =SUM(C19:J19) -> 0 | L19: 0 | M19: 0 | N19: =SUM(L19:M19) -> 0 | O19: 0 | P19: 0 | Q19: 0 | R19: 0 | S19: 0 | T19: 0 | U19: 0 | V19: 0 | W19: 0 | X19: 0 | Y19: 0 | Z19: 0 | AA19: 0 | AB19: 0 | AC19: 0 | AD19: 0 | AE19: 0 | AF19: =SUM(AB19:AE19) -> 0 | AG19: =IF((B19+K19+N19+AA19+AF19)/5=B19,"Todo Bien :D","Algo esta Mal :c") -> Todo Bien :D
A20: Calendario | B20: 0 | C20: 0 | D20: 0 | E20: 0 | F20: 0 | G20: 0 | H20: 0 | I20: 0 | J20: 0 | K20: =SUM(C20:J20) -> 0 | L20: 0 | M20: 0 | N20: =SUM(L20:M20) -> 0 | O20: 0 | P20: 0 | Q20: 0 | R20: 0 | S20: 0 | T20: 0 | U20: 0 | V20: 0 | W20: 0 | X20: 0 | Y20: 0 | Z20: 0 | AA20: =SUM(O20:Z20) -> 0 | AB20: 0 | AC20: 0 | AD20: 0 | AE20: 0 | AF20: =SUM(AB20:AE20) -> 0 | AG20: =IF((B20+K20+N20+AA20+AF20)/5=B20,"Todo Bien :D","Algo esta Mal :c") -> Todo Bien :D
A21: Cambiar información personal | B21: 32 | C21: 0 | D21: 25 | E21: 0 | F21: 0 | G21: 0 | H21: 4 | I21: 3 | J21: 0 | K21: =SUM(C21:J21) -> 32 | L21: 30 | M21: 2 | N21: =SUM(L21:M21) -> 32 | O21: 27 | P21: 0 | Q21: 0 | R21: 1 | S21: 0 | T21: 0 | U21: 2 | V21: 1 | W21: 0 | X21: 0 | Y21: 0 | Z21: 1 | AA21: =SUM(O21:Z21) -> 32 | AB21: 27 | AC21: 0 | AD21: 4 | AE21: 1 | AF21: =SUM(AB21:AE21) -> 32 | AG21: =IF((B21+K21+N21+AA21+AF21)/5=B21,"Todo Bien :D","Algo esta Mal :c") -> Todo Bien :D
A22: Cambio de contraseña | B22: 2 | C22: 0 | D22: 1 | E22: 1 | F22: 0 | G22: 0 | H22: 0 | I22: 0 | J22: 0 | K22: =SUM(C22:J22) -> 2 | L22: 2 | M22: 0 | N22: =SUM(L22:M22) -> 2 | O22: 2 | P22: 0 | Q22: 0 | R22: 0 | S22: 0 | T22: 0 | U22: 0 | V22: 0 | W22: 0 | X22: 0 | Y22: 0 | Z22: 0 | AA22: =SUM(O22:Z22) -> 2 | AB22: 1 | AC22: 0 | AD22: 1 | AE22: 0 | AF22: =SUM(AB22:AE22) -> 2 | AG22: =IF((B22+K22+N22+AA22+AF22)/5=B22,"Todo Bien :D","Algo esta Mal :c") -> Todo Bien :D
A23: Cambio de contraseña FundaTEC | B23: 0 | C23: 0 | D23: 0 | E23: 0 | F23: 0 | G23: 0 | H23: 0 | I23: 0 | J23: 0 | K23: =SUM(C23:J23) -> 0 | L23: 0 | M23: 0 | N23: =SUM(L23:M23) -> 0 | O23: 0 | P23: 0 | Q23: 0 | R23: 0 | S23: 0 | T23: 0 | U23: 0 | V23: 0 | W23: 0 | X23: 0 | Y23: 0 | Z23: 0 | AA23: =SUM(O23:Z23) -> 0 | AB23: 0 | AC23: 0 | AD23: 0 | AE23: 0 | AF23: =SUM(AB23:AE23) -> 0 | AG23: =IF((B23+K23+N23+AA23+AF23)/5=B23,"Todo Bien :D","Algo esta Mal :c") -> Todo Bien :D
A24: Carpeta Tareas | B24: 0 | C24: 0 | D24: 0 | E24: 0 | F24: 0 | G24: 0 | H24: 0 | I24: 0 | J24: 0 | K24: =SUM(C24:J24) -> 0 | L24: 0 | M24: 0 | N24: =SUM(L24:M24) -> 0 | O24: 0 | P24: 0 | Q24: 0 | R24: 0 | S24: 0 | T24: 0 | U24: 0 | V24: 0 | W24: 0 | X24: 0 | Y24: 0 | Z24: 0 | AA24: =SUM(O24:Z24) -> 0 | AB24: 0 | AC24: 0 | AD24: 0 | AE24: 0 | AF24: =SUM(AB24:AE24) -> 0 | AG24: =IF((B24+K24+N24+AA24+AF24)/5=B24,"Todo Bien :D","Algo esta Mal :c") -> Todo Bien :D
A25: Carpetas/Documentos | B25: 14 | C25: 1 | D25: 11 | E25: 0 | F25: 0 | G25: 0 | H25: 1 | I25: 1 | J25: 0 | K25: =SUM(C25:J25) -> 14 | L25: 13 | M25: 1 | N25: =SUM(L25:M25) -> 14 | O25: 1 | P25: 0 | Q25: 0 | R25: 10 | S25: 0 | T25: 0 | U25: 2 | V25: 0 | W25: 1 | X25: 0 | Y25: 0 | Z25: 0 | AA25: =SUM(O25:Z25) -> 14 | AB25: 14 | AC25: 0 | AD25: 0 | AE25: 0 | AF25: =SUM(AB25:AE25) -> 14 | AG25: =IF((B25+K25+N25+AA25+AF25)/5=B25,"Todo Bien :D","Algo esta Mal :c") -> Todo Bien :D
A26: Configuración de Comunidades/Cursos | B26: 15 | C26: 5 | D26: 6 | E26: 0 | F26: 0 | G26: 0 | H26: 0 | I26: 4 | J26: 0 | K26: =SUM(C26:J26) -> 15 | L26: 15 | M26: 0 | N26: =SUM(L26:M26) -> 15 | O26: 0 | P26: 0 | Q26: 0 | R26: 15 | S26: 0 | T26: 0 | U26: 0 | V26: 0 | W26: 0 | X26: 0 | Y26: 0 | Z26: 0 | AA26: =SUM(O26:Z26) -> 15 | AB26: 14 | AC26: 0 | AD26: 1 | AE26: 0 | AF26: =SUM(AB26:AE26) -> 15 | AG26: =IF((B26+K26+N26+AA26+AF26)/5=B26,"Todo Bien :D","Algo esta Mal :c") -> Todo Bien :D
A27: Consulta para Directores | B27: 0 | C27: 0 | D27: 0 | E27: 0 | F27: 0 | G27: 0 | H27: 0 | I27: 0 | J27: 0 | K27: =SUM(C27:J27) -> 0 | L27: 0 | M27: 0 | N27: =SUM(L27:M27) -> 0 | O27: 0 | P27: 0 | Q27: 0 | R27: 0 | S27: 0 | T27: 0 | U27: 0 | V27: 0 | W27: 0 | X27: 0 | Y27: 0 | Z27: 0 | AA27: 0 | AB27: 0 | AC27: 0 | AD27: 0 | AE27: 0 | AF27: =SUM(AB27:AE27) -> 0 | AG27: =IF((B27+K27+N27+AA27+AF27)/5=B27,"Todo Bien :D","Algo esta Mal :c") -> Todo Bien :D
A28: Control de plagio | B28: 2 | C28: 0 | D28: 2 | E28: 0 | F28: 0 | G28: 0 | H28: 0 | I28: 0 | J28: 0 | K28: =SUM(C28:J28) -> 2 | L28: 2 | M28: 0 | N28: =SUM(L28:M28) -> 2 | O28: 1 | P28: 0 | Q28: 0 | R28: 1 | S28: 0 | T28: 0 | U28: 0 | V28: 0 | W28: 0 | X28: 0 | Y28: 0 | Z28: 0 | AA28: =SUM(O28:Z28) -> 2 | AB28: 2 | AC28: 0 | AD28: 0 | AE28: 0 | AF28: =SUM(AB28:AE28) -> 2 | AG28: =IF((B28+K28+N28+AA28+AF28)/5=B28,"Todo Bien :D","Algo esta Mal :c") -> Todo Bien :D
A29: Copiado de contenidos | B29: 5 | C29: 0 | D29: 4 | E29: 0 | F29: 0 | G29: 0 | H29: 0 | I29: 1 | J29: 0 | K29: =SUM(C29:J29) -> 5 | L29: 5 | M29: 0 | N29: =SUM(L29:M29) -> 5 | O29: 0 | P29: 0 | Q29: 0 | R29: 4 | S29: 0 | T29: 0 | U29: 1 | V29: 0 | W29: 0 | X29: 0 | Y29: 0 | Z29: 0 | AA29: =SUM(O29:Z29) -> 5 | AB29: 5 | AC29: 0 | AD29: 0 | AE29: 0 | AF29: =SUM(AB29:AE29) -> 5 | AG29: =IF((B29+K29+N29+AA29+AF29)/5=B29,"Todo Bien :D","Algo esta Mal :c") -> Todo Bien :D
A30: Creación curso Colegio Científico | B30: 1 | C30: 0 | D30: 1 | E30: 0 | F30: 0 | G30: 0 | H30: 0 | I30: 0 | J30: 0 | K30: =SUM(C30:J30) -> 1 | L30: 1 | M30: 0 | N30: =SUM(L30:M30) -> 1 | O30: 0 | P30: 0 | Q30: 0 | R30: 0 | S30: 0 | T30: 0 | U30: 0 | V30: 0 | W30: 0 | X30: 0 | Y30: 1 | Z30: 0 | AA30: =SUM(O30:Z30) -> 1 | AB30: 1 | AC30: 0 | AD30: 0 | AE30: 0 | AF30: =SUM(AB30:AE30) -> 1 | AG30: =IF((B30+K30+N30+AA30+AF30)/5=B30,"Todo Bien :D","Algo esta Mal :c") -> Todo Bien :D
A31: Creación cursos FundaTEC | B31: 18 | C31: 0 | D31: 18 | E31: 0 | F31: 0 | G31: 0 | H31: 0 | I31: 0 | J31: 0 | K31: =SUM(C31:J31) -> 18 | L31: 18 | M31: 0 | N31: =SUM(L31:M31) -> 18 | O31: 0 | P31: 0 | Q31: 0 | R31: 2 | S31: 0 | T31: 0 | U31: 0 | V31: 16 | W31: 0 | X31: 0 | Y31: 0 | Z31: 0 | AA31: =SUM(O31:Z31) -> 18 | AB31: 18 | AC31: 0 | AD31: 0 | AE31: 0 | AF31: =SUM(AB31:AE31) -> 18 | AG31: =IF((B31+K31+N31+AA31+AF31)/5=B31,"Todo Bien :D","Algo esta Mal :c") -> Todo Bien :D
A32: Creación de comunidades | B32: 4 | C32: 0 | D32: 3 | E32: 0 | F32: 0 | G32: 0 | H32: 0 | I32: 1 | J32: 0 | K32: =SUM(C32:J32) -> 4 | L32: 4 | M32: 0 | N32: =SUM(L32:M32) -> 4 | O32: 1 | P32: 0 | Q32: 0 | R32: 3 | S32: 0 | T32: 0 | U32: 0 | V32: 0 | W32: 0 | X32: 0 | Y32: 0 | Z32: 0 | AA32: =SUM(O32:Z32) -> 4 | AB32: 4 | AC32: 0 | AD32: 0 | AE32: 0 | AF32: =SUM(AB32:AE32) -> 4 | AG32: =IF((B32+K32+N32+AA32+AF32)/5=B32,"Todo Bien :D","Algo esta Mal :c") -> Todo Bien :D
A33: Creación de curso | B33: 5 | C33: 0 | D33: 5 | E33: 0 | F33: 0 | G33: 0 | H33: 0 | I33: 0 | J33: 0 | K33: =SUM(C33:J33) -> 5 | L33: 5 | M33: 0 | N33: =SUM(L33:M33) -> 5 | O33: 0 | P33: 0 | Q33: 0 | R33: 1 | S33: 0 | T33: 0 | U33: 3 | V33: 1 | W33: 0 | X33: 0 | Y33: 0 | Z33: 0 | AA33: =SUM(O33:Z33) -> 5 | AB33: 5 | AC33: 0 | AD33: 0 | AE33: 0 | AF33: =SUM(AB33:AE33) -> 5 | AG33: =IF((B33+K33+N33+AA33+AF33)/5=B33,"Todo Bien :D","Algo esta Mal :c") -> Todo Bien :D
A34: Creación de usuarios | B34: 9 | C34: 0 | D34: 9 | E34: 0 | F34: 0 | G34: 0 | H34: 0 | I34: 0 | J34: 0 | K34: =SUM(C34:J34) -> 9 | L34: 9 | M34: 0 | N34: =SUM(L34:M34) -> 9 | O34: 2 | P34: 0 | Q34: 0 | R34: 4 | S34: 0 | T34: 0 | U34: 1 | V34: 2 | W34: 0 | X34: 0 | Y34: 0 | Z34: 0 | AA34: =SUM(O34:Z34) -> 9 | AB34: 5 | AC34: 0 | AD34: 2 | AE34: 2 | AF34: =SUM(AB34:AE34) -> 9 | AG34: =IF((B34+K34+N34+AA34+AF34)/5=B34,"Todo Bien :D","Algo esta Mal :c") -> Todo Bien :D
A35: Creación de usuarios Colegio Científico | B35: 1 | C35: 0 | D35: 1 | E35: 0 | F35: 0 | G35: 0 | H35: 0 | I35: 0 | J35: 0 | K35: =SUM(C35:J35) -> 1 | L35: 1 | M35: 0 | N35: =SUM(L35:M35) -> 1 | O35: 1 | P35: 0 | Q35: 0 | R35: 0 | S35: 0 | T35: 0 | U35: 0 | V35: 0 | W35: 0 | X35: 0 | Y35: 0 | Z35: 0 | AA35: =SUM(O35:Z35) -> 1 | AB35: 1 | AC35: 0 | AD35: 0 | AE35: 0 | AF35: =SUM(AB35:AE35) -> 1 | AG35: =IF((B35+K35+N35+AA35+AF35)/5=B35,"Todo Bien :D","Algo esta Mal :c") -> Todo Bien :D
A36: Creación de usuarios FundaTEC | B36: 18 | C36: 0 | D36: 18 | E36: 0 | F36: 0 | G36: 0 | H36: 0 | I36: 0 | J36: 0 | K36: =SUM(C36:J36) -> 18 | L36: 18 | M36: 0 | N36: =SUM(L36:M36) -> 18 | O36: 0 | P36: 0 | Q36: 0 | R36: 5 | S36: 0 | T36: 0 | U36: 0 | V36: 12 | W36: 0 | X36: 0 | Y36: 0 | Z36: 1 | AA36: =SUM(O36:Z36) -> 18 | AB36: 18 | AC36: 0 | AD36: 0 | AE36: 0 | AF36: =SUM(AB36:AE36) -> 18 | AG36: =IF((B36+K36+N36+AA36+AF36)/5=B36,"Todo Bien :D","Algo esta Mal :c") -> Todo Bien :D
A37: Curso Móvil | B37: 0 | C37: 0 | D37: 0 | E37: 0 | F37: 0 | G37: 0 | H37: 0 | I37: 0 | J37: 0 | K37: =SUM(C37:J37) -> 0 | L37: 0 | M37: 0 | N37: =SUM(L37:M37) -> 0 | O37: 0 | P37: 0 | Q37: 0 | R37: 0 | S37: 0 | T37: 0 | U37: 0 | V37: 0 | W37: 0 | X37: 0 | Y37: 0 | Z37: 0 | AA37: 0 | AB37: 0 | AC37: 0 | AD37: 0 | AE37: 0 | AF37: =SUM(AB37:AE37) -> 0 | AG37: =IF((B37+K37+N37+AA37+AF37)/5=B37,"Todo Bien :D","Algo esta Mal :c") -> Todo Bien :D
A38: Dashboard | B38: 0 | C38: 0 | D38: 0 | E38: 0 | F38: 0 | G38: 0 | H38: 0 | I38: 0 | J38: 0 | K38: =SUM(C38:J38) -> 0 | L38: 0 | M38: 0 | N38: =SUM(L38:M38) -> 0 | O38: 0 | P38: 0 | Q38: 0 | R38: 0 | S38: 0 | T38: 0 | U38: 0 | V38: 0 | W38: 0 | X38: 0 | Y38: 0 | Z38: 0 | AA38: 0 | AB38: 0 | AC38: 0 | AD38: 0 | AE38: 0 | AF38: =SUM(AB38:AE38) -> 0 | AG38: =IF((B38+K38+N38+AA38+AF38)/5=B38,"Todo Bien :D","Algo esta Mal :c") -> Todo Bien :D
A39: Diagnósticos | B39: 23 | C39: 0 | D39: 12 | E39: 0 | F39: 0 | G39: 0 | H39: 9 | I39: 2 | J39: 0 | K39: =SUM(C39:J39) -> 23 | L39: 23 | M39: 0 | N39: =SUM(L39:M39) -> 23 | O39: 22 | P39: 0 | Q39: 0 | R39: 1 | S39: 0 | T39: 0 | U39: 0 | V39: 0 | W39: 0 | X39: 0 | Y39: 0 | Z39: 0 | AA39: =SUM(O39:Z39) -> 23 | AB39: 23 | AC39: 0 | AD39: 0 | AE39: 0 | AF39: =SUM(AB39:AE39) -> 23 | AG39: =IF((B39+K39+N39+AA39+AF39)/5=B39,"Todo Bien :D","Algo esta Mal :c") -> Todo Bien :D
A40: Diseño instruccional | B40: 0 | C40: 0 | D40: 0 | E40: 0 | F40: 0 | G40: 0 | H40: 0 | I40: 0 | J40: 0 | K40: =SUM(C40:J40) -> 0 | L40: 0 | M40: 0 | N40: =SUM(L40:M40) -> 0 | O40: 0 | P40: 0 | Q40: 0 | R40: 0 | S40: 0 | T40: 0 | U40: 0 | V40: 0 | W40: 0 | X40: 0 | Y40: 0 | Z40: 0 | AA40: 0 | AB40: 0 | AC40: 0 | AD40: 0 | AE40: 0 | AF40: =SUM(AB40:AE40) -> 0 | AG40: =IF((B40+K40+N40+AA40+AF40)/5=B40,"Todo Bien :D","Algo esta Mal :c") -> Todo Bien :D
A41: Envío de comunicados a comunidades | B41: 23 | C41: 0 | D41: 23 | E41: 0 | F41: 0 | G41: 0 | H41: 0 | I41: 0 | J41: 0 | K41: =SUM(C41:J41) -> 23 | L41: 23 | M41: 0 | N41: =SUM(L41:M41) -> 23 | O41: 1 | P41: 0 | Q41: 0 | R41: 4 | S41: 0 | T41: 0 | U41: 13 | V41: 0 | W41: 5 | X41: 0 | Y41: 0 | Z41: 0 | AA41: =SUM(O41:Z41) -> 23 | AB41: 22 | AC41: 0 | AD41: 1 | AE41: 0 | AF41: =SUM(AB41:AE41) -> 23 | AG41: =IF((B41+K41+N41+AA41+AF41)/5=B41,"Todo Bien :D","Algo esta Mal :c") -> Todo Bien :D
...

Sheet Marzo
A1: SERVICIO RELACIONADO | C1: TIQUETS POR CANAL | L1: TIPO | O1: ROL USUARIO | AB1: PRIORIDAD | AG1: TOTALES
A3: =IF((B67+K67+N67+AA67+AF67)/5=B67,"Todo Bien :D","Algo esta Mal :c") -> Todo Bien :D | B3: 8 | C3: Chat | D3: Correo | E3: Formulario Web | F3: Facebook | G3: Memorandum | H3: Presencial | I3: Teléfono | J3: Twitter | K3: TOTAL | L3: Solicitud | M3: Incidente | N3: TOTAL | O3: Estudiante | P3: Estudiante FundaTEC | Q3: Estudiante Colegio Científico | R3: Profesor | S3: Profesor FundaTEC | T3: Profesor Colegio Científico | U3: Administrativo | V3: Administrativo FundaTEC | W3: Director/Coordinador | X3: Director/Coordinador FundaTEC | Y3: Director/Coordinador Colegio Científico | Z3: Externo | AA3: TOTAL | AB3: Normal | AC3: Baja | AD3: Alta | AE3: Urgente | AF3: TOTAL
A4: Acceso a la plataforma TEC Digital | B4: 8 | C4: 0 | D4: 6 | E4: 0 | F4: 0 | G4: 0 | H4: 0 | I4: 2 | J4: 0 | K4: =SUM(C4:J4) -> 8 | L4: 8 | M4: 0 | N4: =SUM(L4:M4) -> 8 | O4: 1 | Q4: 0 | R4: 2 | S4: 0 | T4: 0 | U4: 2 | V4: 0 | W4: 1 | X4: 0 | Y4: 0 | Z4: 2 | AA4: =SUM(O4:Z4) -> 8 | AB4: 6 | AC4: 0 | AD4: 1 | AE4: 1 | AF4: =SUM(AB4:AE4) -> 8 | AG4: =IF((B4+K4+N4+AA4+AF4)/5=B4,"Todo Bien :D","Algo esta Mal :c") -> Todo Bien :D
A5: Acreditación | B5: 0 | C5: 0 | D5: 0 | E5: 0 | F5: 0 | G5: 0 | H5: 0 | I5: 0 | J5: 0 | K5: =SUM(C5:J5) -> 0 | L5: 0 | M5: 0 | N5: =SUM(L5:M5) -> 0 | O5: 0 | P5: 0 | Q5: 0 | R5: 0 | S5: 0 | T5: 0 | U5: 0 | V5: 0 | W5: 0 | X5: 0 | Y5: 0 | Z5: 0 | AA5: =SUM(O5:Z5) -> 0 | AB5: 0 | AC5: 0 | AD5: 0 | AE5: 0 | AF5: =SUM(AB5:AE5) -> 0 | AG5: =IF((B5+K5+N5+AA5+AF5)/5=B5,"Todo Bien :D","Algo esta Mal :c") -> Todo Bien :D
A6: Activar cuentas de usuario | B6: 0 | C6: 0 | D6: 0 | E6: 0 | F6: 0 | G6: 0 | H6: 0 | I6: 0 | J6: 0 | K6: =SUM(C6:J6) -> 0 | L6: 0 | M6: 0 | N6: =SUM(L6:M6) -> 0 | O6: 0 | P6: 0 | Q6: 0 | R6: 0 | S6: 0 | T6: 0 | U6: 0 | V6: 0 | W6: 0 | X6: 0 | Y6: 0 | Z6: 0 | AA6: =SUM(O6:Z6) -> 0 | AB6: 0 | AC6: 0 | AD6: 0 | AE6: 0 | AF6: =SUM(AB6:AE6) -> 0 | AG6: =IF((B6+K6+N6+AA6+AF6)/5=B6,"Todo Bien :D","Algo esta Mal :c") -> Todo Bien :D
A7: Activar curso | B7: 1 | C7: 0 | D7: 1 | E7: 0 | F7: 0 | G7: 0 | H7: 0 | I7: 0 | J7: 0 | K7: =SUM(C7:J7) -> 1 | L7: 1 | M7: 0 | N7: =SUM(L7:M7) -> 1 | O7: 0 | P7: 0 | Q7: 0 | R7: 1 | S7: 0 | T7: 0 | U7: 0 | V7: 0 | W7: 0 | X7: 0 | Y7: 0 | Z7: 0 | AA7: =SUM(O7:Z7) -> 1 | AB7: 1 | AC7: 0 | AD7: 0 | AE7: 0 | AF7: =SUM(AB7:AE7) -> 1 | AG7: =IF((B7+K7+N7+AA7+AF7)/5=B7,"Todo Bien :D","Algo esta Mal :c") -> Todo Bien :D
A8: Actualizar cursos a estudiantes | B8: 0 | C8: 0 | D8: 0 | E8: 0 | F8: 0 | G8: 0 | H8: 0 | I8: 0 | J8: 0 | K8: =SUM(C8:J8) -> 0 | L8: 0 | M8: 0 | N8: =SUM(L8:M8) -> 0 | O8: 0 | P8: 0 | Q8: 0 | R8: 0 | S8: 0 | T8: 0 | U8: 0 | V8: 0 | W8: 0 | X8: 0 | Y8: 0 | Z8: 0 | AA8: =SUM(O8:Z8) -> 0 | AB8: 0 | AC8: 0 | AD8: 0 | AE8: 0 | AF8: =SUM(AB8:AE8) -> 0 | AG8: =IF((B8+K8+N8+AA8+AF8)/5=B8,"Todo Bien :D","Algo esta Mal :c") -> Todo Bien :D
A9: Actualizar miembros de comunidades | B9: 1 | C9: 1 | D9: 0 | E9: 0 | F9: 0 | G9: 0 | H9: 0 | I9: 0 | J9: 0 | K9: =SUM(C9:J9) -> 1 | L9: 1 | M9: 0 | N9: =SUM(L9:M9) -> 1 | O9: 0 | P9: 0 | Q9: 0 | R9: 0 | S9: 0 | T9: 0 | U9: 1 | V9: 0 | W9: 0 | X9: 0 | Y9: 0 | Z9: 0 | AA9: =SUM(O9:Z9) -> 1 | AB9: 1 | AC9: 0 | AD9: 0 | AE9: 0 | AF9: =SUM(AB9:AE9) -> 1 | AG9: =IF((B9+K9+N9+AA9+AF9)/5=B9,"Todo Bien :D","Algo esta Mal :c") -> Todo Bien :D
A10: Administrador de asistencia | B10: 0 | C10: 0 | D10: 0 | E10: 0 | F10: 0 | G10: 0 | H10: 0 | I10: 0 | J10: 0 | K10: =SUM(C10:J10) -> 0 | L10: 0 | M10: 0 | N10: =SUM(L10:M10) -> 0 | O10: 0 | P10: 0 | Q10: 0 | R10: 0 | S10: 0 | T10: 0 | U10: 0 | V10: 0 | W10: 0 | X10: 0 | Y10: 0 | Z10: 0 | AA10: =SUM(O10:Z10) -> 0 | AB10: 0 | AC10: 0 | AD10: 0 | AE10: 0 | AF10: =SUM(AB10:AE10) -> 0 | AG10: =IF((B10+K10+N10+AA10+AF10)/5=B10,"Todo Bien :D","Algo esta Mal :c") -> Todo Bien :D
A11: Administrador Programa de Curso | B11: 0 | C11: 0 | D11: 0 | E11: 0 | F11: 0 | G11: 0 | H11: 0 | I11: 0 | J11: 0 | K11: =SUM(C11:J11) -> 0 | L11: 0 | M11: 0 | N11: =SUM(L11:M11) -> 0 | O11: 0 | P11: 0 | Q11: 0 | R11: 0 | S11: 0 | T11: 0 | U11: 0 | V11: 0 | W11: 0 | X11: 0 | Y11: 0 | Z11: 0 | AA11: =SUM(O11:Z11) -> 0 | AB11: 0 | AC11: 0 | AD11: 0 | AE11: 0 | AF11: =SUM(AB11:AE11) -> 0 | AG11: =IF((B11+K11+N11+AA11+AF11)/5=B11,"Todo Bien :D","Algo esta Mal :c") -> Todo Bien :D
A12: Agregar/cambiar asociación de estudiante a curso | B12: 17 | C12: 0 | D12: 15 | E12: 0 | F12: 0 | G12: 0 | H12: 2 | I12: 0 | J12: 0 | K12: =SUM(C12:J12) -> 17 | L12: 17 | M12: 0 | N12: =SUM(L12:M12) -> 17 | O12: 9 | P12: 0 | Q12: 0 | R12: 2 | S12: 0 | T12: 0 | U12: 3 | V12: 3 | W12: 0 | X12: 0 | Y12: 0 | Z12: 0 | AA12: =SUM(O12:Z12) -> 17 | AB12: 17 | AC12: 0 | AD12: 0 | AE12: 0 | AF12: =SUM(AB12:AE12) -> 17 | AG12: =IF((B12+K12+N12+AA12+AF12)/5=B12,"Todo Bien :D","Algo esta Mal :c") -> Todo Bien :D
A13: Agregar/cambiar asociación de profesor a curso | B13: 19 | C13: 2 | D13: 15 | E13: 2 | F13: 0 | G13: 0 | H13: 0 | I13: 0 | J13: 0 | K13: =SUM(C13:J13) -> 19 | L13: 19 | M13: 0 | N13: =SUM(L13:M13) -> 19 | O13: 0 | P13: 0 | Q13: 0 | R13: 10 | S13: 0 | T13: 0 | U13: 8 | V13: 0 | W13: 1 | X13: 0 | Y13: 0 | Z13: 0 | AA13: =SUM(O13:Z13) -> 19 | AB13: 19 | AC13: 0 | AD13: 0 | AE13: 0 | AF13: =SUM(AB13:AE13) -> 19 | AG13: =IF((B13+K13+N13+AA13+AF13)/5=B13,"Todo Bien :D","Algo esta Mal :c") -> Todo Bien :D
A14: Agregar/cambiar asociación de usuario a comunidad | B14: 30 | C14: 6 | D14: 18 | E14: 0 | F14: 0 | G14: 0 | H14: 5 | I14: 1 | J14: 0 | K14: =SUM(C14:J14) -> 30 | L14: 30 | M14: 0 | N14: =SUM(L14:M14) -> 30 | O14: 18 | P14: 0 | Q14: 0 | R14: 3 | S14: 0 | T14: 0 | U14: 6 | V14: 0 | W14: 3 | X14: 0 | Y14: 0 | Z14: 0 | AA14: =SUM(O14:Z14) -> 30 | AB14: 30 | AC14: 0 | AD14: 0 | AE14: 0 | AF14: =SUM(AB14:AE14) -> 30 | AG14: =IF((B14+K14+N14+AA14+AF14)/5=B14,"Todo Bien :D","Algo esta Mal :c") -> Todo Bien :D
A15: Agregar/cambiar asociación estudiante a curso Colegio Científico | B15: 0 | C15: 0 | D15: 0 | E15: 0 | F15: 0 | G15: 0 | H15: 0 | I15: 0 | J15: 0 | K15: =SUM(C15:J15) -> 0 | L15: 0 | M15: 0 | N15: 0 | O15: 0 | P15: 0 | Q15: 0 | R15: 0 | S15: 0 | T15: 0 | U15: 0 | V15: 0 | W15: 0 | X15: 0 | Y15: 0 | Z15: 0 | AA15: =SUM(O15:Z15) -> 0 | AB15: 0 | AC15: 0 | AD15: 0 | AE15: 0 | AF15: =SUM(AB15:AE15) -> 0 | AG15: =IF((B15+K15+N15+AA15+AF15)/5=B15,"Todo Bien :D","Algo esta Mal :c") -> Todo Bien :D
A16: Agregar/cambiar asociación estudiante a curso FundaTEC | B16: 2 | C16: 1 | D16: 1 | E16: 0 | F16: 0 | G16: 0 | H16: 0 | I16: 0 | J16: 0 | K16: =SUM(C16:J16) -> 2 | L16: 2 | M16: 0 | N16: =SUM(L16:M16) -> 2 | O16: 0 | P16: 0 | Q16: 0 | R16: 0 | S16: 0 | T16: 0 | U16: 0 | V16: 1 | W16: 0 | X16: 1 | Y16: 0 | Z16: 0 | AA16: =SUM(O16:Z16) -> 2 | AB16: 2 | AC16: 0 | AD16: 0 | AE16: 0 | AF16: =SUM(AB16:AE16) -> 2 | AG16: =IF((B16+K16+N16+AA16+AF16)/5=B16,"Todo Bien :D","Algo esta Mal :c") -> Todo Bien :D
A17: Asignación de permisos especiales | B17: 2 | C17: 0 | D17: 2 | E17: 0 | F17: 0 | G17: 0 | H17: 0 | I17: 0 | J17: 0 | K17: =SUM(C17:J17) -> 2 | L17: 2 | M17: 0 | N17: =SUM(L17:M17) -> 2 | O17: 0 | P17: 0 | Q17: 0 | R17: 1 | S17: 0 | T17: 0 | U17: 0 | V17: 0 | W17: 1 | X17: 0 | Y17: 0 | Z17: 0 | AA17: =SUM(O17:Z17) -> 2 | AB17: 2 | AC17: 0 | AD17: 0 | AE17: 0 | AF17: =SUM(AB17:AE17) -> 2 | AG17: =IF((B17+K17+N17+AA17+AF17)/5=B17,"Todo Bien :D","Algo esta Mal :c") -> Todo Bien :D
A18: Atención personalizada a usuarios | B18: 30 | C18: 2 | D18: 24 | E18: 0 | F18: 0 | G18: 0 | H18: 2 | I18: 2 | J18: 0 | K18: =SUM(C18:J18) -> 30 | L18: 30 | M18: 0 | N18: =SUM(L18:M18) -> 30 | O18: 13 | P18: 3 | Q18: 0 | R18: 5 | S18: 0 | T18: 0 | U18: 6 | V18: 0 | W18: 0 | X18: 0 | Y18: 0 | Z18: 3 | AA18: =SUM(O18:Z18) -> 30 | AB18: 29 | AC18: 0 | AD18: 1 | AE18: 0 | AF18: =SUM(AB18:AE18) -> 30 | AG18: =IF((B18+K18+N18+AA18+AF18)/5=B18,"Todo Bien :D","Algo esta Mal :c") -> Todo Bien :D
A19: BiciTEC | B19: 0 | C19: 0 | D19: 0 | E19: 0 | F19: 0 | G19: 0 | H19: 0 | I19: 0 | J19: 0 | K19: =SUM(C19:J19) -> 0 | L19: 0 | M19: 0 | N19: =SUM(L19:M19) -> 0 | O19: 0 | P19: 0 | Q19: 0 | R19: 0 | S19: 0 | T19: 0 | U19: 0 | V19: 0 | W19: 0 | X19: 0 | Y19: 0 | Z19: 0 | AA19: 0 | AB19: 0 | AC19: 0 | AD19: 0 | AE19: 0 | AF19: =SUM(AB19:AE19) -> 0 | AG19: =IF((B19+K19+N19+AA19+AF19)/5=B19,"Todo Bien :D","Algo esta Mal :c") -> Todo Bien :D
A20: Calendario | B20: 0 | C20: 0 | D20: 0 | E20: 0 | F20: 0 | G20: 0 | H20: 0 | I20: 0 | J20: 0 | K20: =SUM(C20:J20) -> 0 | L20: 0 | M20: 0 | N20: =SUM(L20:M20) -> 0 | O20: 0 | P20: 0 | Q20: 0 | R20: 0 | S20: 0 | T20: 0 | U20: 0 | V20: 0 | W20: 0 | X20: 0 | Y20: 0 | Z20: 0 | AA20: =SUM(O20:Z20) -> 0 | AB20: 0 | AC20: 0 | AD20: 0 | AE20: 0 | AF20: =SUM(AB20:AE20) -> 0 | AG20: =IF((B20+K20+N20+AA20+AF20)/5=B20,"Todo Bien :D","Algo esta Mal :c") -> Todo Bien :D
A21: Cambiar información personal | B21: 5 | C21: 1 | D21: 4 | E21: 0 | F21: 0 | G21: 0 | H21: 0 | I21: 0 | J21: 0 | K21: =SUM(C21:J21) -> 5 | L21: 5 | M21: 0 | N21: =SUM(L21:M21) -> 5 | O21: 4 | P21: 0 | Q21: 0 | R21: 0 | S21: 0 | T21: 0 | U21: 1 | V21: 0 | W21: 0 | X21: 0 | Y21: 0 | Z21: 0 | AA21: =SUM(O21:Z21) -> 5 | AB21: 5 | AC21: 0 | AD21: 0 | AE21: 0 | AF21: =SUM(AB21:AE21) -> 5 | AG21: =IF((B21+K21+N21+AA21+AF21)/5=B21,"Todo Bien :D","Algo esta Mal :c") -> Todo Bien :D
A22: Cambio de contraseña | B22: 1 | C22: 0 | D22: 1 | E22: 0 | F22: 0 | G22: 0 | H22: 0 | I22: 0 | J22: 0 | K22: =SUM(C22:J22) -> 1 | L22: 1 | M22: 0 | N22: =SUM(L22:M22) -> 1 | O22: 0 | P22: 0 | Q22: 0 | R22: 0 | S22: 0 | T22: 0 | U22: 1 | V22: 0 | W22: 0 | X22: 0 | Y22: 0 | Z22: 0 | AA22: 1 | AB22: 1 | AC22: 0 | AD22: 0 | AE22: 0 | AF22: =SUM(AB22:AE22) -> 1 | AG22: =IF((B22+K22+N22+AA22+AF22)/5=B22,"Todo Bien :D","Algo esta Mal :c") -> Todo Bien :D
A23: Cambio de contraseña FundaTEC | B23: 1 | C23: 0 | D23: 1 | E23: 0 | F23: 0 | G23: 0 | H23: 0 | I23: 0 | J23: 0 | K23: =SUM(C23:J23) -> 1 | L23: 1 | M23: 0 | N23: =SUM(L23:M23) -> 1 | O23: 0 | P23: 0 | Q23: 0 | R23: 0 | S23: 0 | T23: 0 | U23: 0 | V23: 1 | W23: 0 | X23: 0 | Y23: 0 | Z23: 0 | AA23: =SUM(O23:Z23) -> 1 | AB23: 1 | AC23: 0 | AD23: 0 | AE23: 0 | AF23: =SUM(AB23:AE23) -> 1 | AG23: =IF((B23+K23+N23+AA23+AF23)/5=B23,"Todo Bien :D","Algo esta Mal :c") -> Todo Bien :D
A24: Carpeta Tareas | B24: 0 | C24: 0 | D24: 0 | E24: 0 | F24: 0 | G24: 0 | H24: 0 | I24: 0 | J24: 0 | K24: =SUM(C24:J24) -> 0 | L24: 0 | M24: 0 | N24: =SUM(L24:M24) -> 0 | O24: 0 | P24: 0 | Q24: 0 | R24: 0 | S24: 0 | T24: 0 | U24: 0 | V24: 0 | W24: 0 | X24: 0 | Y24: 0 | Z24: 0 | AA24: =SUM(O24:Z24) -> 0 | AB24: 0 | AC24: 0 | AD24: 0 | AE24: 0 | AF24: =SUM(AB24:AE24) -> 0 | AG24: =IF((B24+K24+N24+AA24+AF24)/5=B24,"Todo Bien :D","Algo esta Mal :c") -> Todo Bien :D
A25: Carpetas/Documentos | B25: 5 | C25: 0 | D25: 3 | E25: 0 | F25: 0 | G25: 0 | H25: 0 | I25: 2 | J25: 0 | K25: =SUM(C25:J25) -> 5 | L25: 5 | M25: 0 | N25: =SUM(L25:M25) -> 5 | O25: 1 | P25: 0 | Q25: 0 | R25: 3 | S25: 0 | T25: 0 | U25: 1 | V25: 0 | W25: 0 | X25: 0 | Y25: 0 | Z25: 0 | AA25: =SUM(O25:Z25) -> 5 | AB25: 4 | AC25: 0 | AD25: 1 | AE25: 0 | AF25: =SUM(AB25:AE25) -> 5 | AG25: =IF((B25+K25+N25+AA25+AF25)/5=B25,"Todo Bien :D","Algo esta Mal :c") -> Todo Bien :D
A26: Configuración de Comunidades/Cursos | B26: 1 | C26: 1 | D26: 0 | E26: 0 | F26: 0 | G26: 0 | H26: 0 | I26: 0 | J26: 0 | K26: =SUM(C26:J26) -> 1 | L26: 1 | M26: 0 | N26: =SUM(L26:M26) -> 1 | O26: 0 | P26: 0 | Q26: 0 | R26: 1 | S26: 0 | T26: 0 | U26: 0 | V26: 0 | W26: 0 | X26: 0 | Y26: 0 | Z26: 0 | AA26: =SUM(O26:Z26) -> 1 | AB26: 1 | AC26: 0 | AD26: 0 | AE26: 0 | AF26: =SUM(AB26:AE26) -> 1 | AG26: =IF((B26+K26+N26+AA26+AF26)/5=B26,"Todo Bien :D","Algo esta Mal :c") -> Todo Bien :D
A27: Consulta para Directores | B27: 0 | C27: 0 | D27: 0 | E27: 0 | F27: 0 | G27: 0 | H27: 0 | I27: 0 | J27: 0 | K27: =SUM(C27:J27) -> 0 | L27: 0 | M27: 0 | N27: =SUM(L27:M27) -> 0 | O27: 0 | P27: 0 | Q27: 0 | R27: 0 | S27: 0 | T27: 0 | U27: 0 | V27: 0 | W27: 0 | X27: 0 | Y27: 0 | Z27: 0 | AA27: 0 | AB27: 0 | AC27: 0 | AD27: 0 | AE27: 0 | AF27: =SUM(AB27:AE27) -> 0 | AG27: =IF((B27+K27+N27+AA27+AF27)/5=B27,"Todo Bien :D","Algo esta Mal :c") -> Todo Bien :D
A28: Control de plagio | B28: 2 | C28: 0 | D28: 2 | E28: 0 | F28: 0 | G28: 0 | H28: 0 | I28: 0 | J28: 0 | K28: =SUM(C28:J28) -> 2 | L28: 2 | M28: 0 | N28: =SUM(L28:M28) -> 2 | O28: 1 | P28: 0 | Q28: 0 | R28: 1 | S28: 0 | T28: 0 | U28: 0 | V28: 0 | W28: 0 | X28: 0 | Y28: 0 | Z28: 0 | AA28: 2 | AB28: 2 | AC28: 0 | AD28: 0 | AE28: 0 | AF28: =SUM(AB28:AE28) -> 2 | AG28: =IF((B28+K28+N28+AA28+AF28)/5=B28,"Todo Bien :D","Algo esta Mal :c") -> Todo Bien :D
A29: Copiado de contenidos | B29: 0 | C29: 0 | D29: 0 | E29: 0 | F29: 0 | G29: 0 | H29: 0 | I29: 0 | J29: 0 | K29: =SUM(C29:J29) -> 0 | L29: 0 | M29: 0 | N29: =SUM(L29:M29) -> 0 | O29: 0 | P29: 0 | Q29: 0 | R29: 0 | S29: 0 | T29: 0 | U29: 0 | V29: 0 | W29: 0 | X29: 0 | Y29: 0 | Z29: 0 | AA29: =SUM(O29:Z29) -> 0 | AB29: 0 | AC29: 0 | AD29: 0 | AE29: 0 | AF29: =SUM(AB29:AE29) -> 0 | AG29: =IF((B29+K29+N29+AA29+AF29)/5=B29,"Todo Bien :D","Algo esta Mal :c") -> Todo Bien :D
A30: Creación curso Colegio Científico | B30: 0 | C30: 0 | D30: 0 | E30: 0 | F30: 0 | G30: 0 | H30: 0 | I30: 0 | J30: 0 | K30: =SUM(C30:J30) -> 0 | L30: 0 | M30: 0 | N30: =SUM(L30:M30) -> 0 | O30: 0 | P30: 0 | Q30: 0 | R30: 0 | S30: 0 | T30: 0 | U30: 0 | V30: 0 | W30: 0 | X30: 0 | Y30: 0 | Z30: 0 | AA30: =SUM(O30:Z30) -> 0 | AB30: 0 | AC30: 0 | AD30: 0 | AE30: 0 | AF30: =SUM(AB30:AE30) -> 0 | AG30: =IF((B30+K30+N30+AA30+AF30)/5=B30,"Todo Bien :D","Algo esta Mal :c") -> Todo Bien :D
A31: Creación cursos FundaTEC | B31: 39 | C31: 0 | D31: 39 | E31: 0 | F31: 0 | G31: 0 | H31: 0 | I31: 0 | J31: 0 | K31: =SUM(C31:J31) -> 39 | L31: 39 | M31: 0 | N31: =SUM(L31:M31) -> 39 | O31: 0 | P31: 0 | Q31: 0 | R31: 0 | S31: 0 | T31: 0 | U31: 0 | V31: 39 | W31: 0 | X31: 0 | Y31: 0 | Z31: 0 | AA31: =SUM(O31:Z31) -> 39 | AB31: 39 | AC31: 0 | AD31: 0 | AE31: 0 | AF31: =SUM(AB31:AE31) -> 39 | AG31: =IF((B31+K31+N31+AA31+AF31)/5=B31,"Todo Bien :D","Algo esta Mal :c") -> Todo Bien :D
A32: Creación de comunidades | B32: 2 | C32: 0 | D32: 1 | E32: 0 | F32: 0 | G32: 0 | H32: 0 | I32: 1 | J32: 0 | K32: =SUM(C32:J32) -> 2 | L32: 2 | M32: 0 | N32: =SUM(L32:M32) -> 2 | O32: 1 | P32: 0 | Q32: 0 | R32: 0 | S32: 0 | T32: 0 | U32: 1 | V32: 0 | W32: 0 | X32: 0 | Y32: 0 | Z32: 0 | AA32: =SUM(O32:Z32) -> 2 | AB32: 2 | AC32: 0 | AD32: 0 | AE32: 0 | AF32: =SUM(AB32:AE32) -> 2 | AG32: =IF((B32+K32+N32+AA32+AF32)/5=B32,"Todo Bien :D","Algo esta Mal :c") -> Todo Bien :D
A33: Creación de curso | B33: 3 | C33: 0 | D33: 3 | E33: 0 | F33: 0 | G33: 0 | H33: 0 | I33: 0 | J33: 0 | K33: =SUM(C33:J33) -> 3 | L33: 3 | M33: 0 | N33: =SUM(L33:M33) -> 3 | O33: 0 | P33: 0 | Q33: 0 | R33: 3 | S33: 0 | T33: 0 | U33: 0 | V33: 0 | W33: 0 | X33: 0 | Y33: 0 | Z33: 0 | AA33: =SUM(O33:Z33) -> 3 | AB33: 3 | AC33: 0 | AD33: 0 | AE33: 0 | AF33: =SUM(AB33:AE33) -> 3 | AG33: =IF((B33+K33+N33+AA33+AF33)/5=B33,"Todo Bien :D","Algo esta Mal :c") -> Todo Bien :D
A34: Creación de usuarios | B34: 2 | C34: 0 | D34: 2 | E34: 0 | F34: 0 | G34: 0 | H34: 0 | I34: 0 | J34: 0 | K34: =SUM(C34:J34) -> 2 | L34: 2 | M34: 0 | N34: =SUM(L34:M34) -> 2 | O34: 0 | P34: 0 | Q34: 0 | R34: 0 | S34: 0 | T34: 0 | U34: 1 | V34: 1 | W34: 0 | X34: 0 | Y34: 0 | Z34: 0 | AA34: =SUM(O34:Z34) -> 2 | AB34: 2 | AC34: 0 | AD34: 0 | AE34: 0 | AF34: =SUM(AB34:AE34) -> 2 | AG34: =IF((B34+K34+N34+AA34+AF34)/5=B34,"Todo Bien :D","Algo esta Mal :c") -> Todo Bien :D
A35: Creación de usuarios Colegio Científico | B35: 0 | C35: 0 | D35: 0 | E35: 0 | F35: 0 | G35: 0 | H35: 0 | I35: 0 | J35: 0 | K35: =SUM(C35:J35) -> 0 | L35: 0 | M35: 0 | N35: =SUM(L35:M35) -> 0 | O35: 0 | P35: 0 | Q35: 0 | R35: 0 | S35: 0 | T35: 0 | U35: 0 | V35: 0 | W35: 0 | X35: 0 | Y35: 0 | Z35: 0 | AA35: 0 | AB35: 0 | AC35: 0 | AD35: 0 | AE35: 0 | AF35: =SUM(AB35:AE35) -> 0 | AG35: =IF((B35+K35+N35+AA35+AF35)/5=B35,"Todo Bien :D","Algo esta Mal :c") -> Todo Bien :D
A36: Creación de usuarios FundaTEC | B36: 20 | C36: 1 | D36: 19 | E36: 0 | F36: 0 | G36: 0 | H36: 0 | I36: 0 | J36: 0 | K36: =SUM(C36:J36) -> 20 | L36: 20 | M36: 0 | N36: =SUM(L36:M36) -> 20 | O36: 0 | P36: 0 | Q36: 0 | R36: 0 | S36: 0 | T36: 0 | U36: 0 | V36: 20 | W36: 0 | X36: 0 | Y36: 0 | Z36: 0 | AA36: =SUM(O36:Z36) -> 20 | AB36: 20 | AC36: 0 | AD36: 0 | AE36: 0 | AF36: =SUM(AB36:AE36) -> 20 | AG36: =IF((B36+K36+N36+AA36+AF36)/5=B36,"Todo Bien :D","Algo esta Mal :c") -> Todo Bien :D
A37: Curso Móvil | B37: 0 | C37: 0 | D37: 0 | E37: 0 | F37: 0 | G37: 0 | H37: 0 | I37: 0 | J37: 0 | K37: =SUM(C37:J37) -> 0 | L37: 0 | M37: 0 | N37: =SUM(L37:M37) -> 0 | O37: 0 | P37: 0 | Q37: 0 | R37: 0 | S37: 0 | T37: 0 | U37: 0 | V37: 0 | W37: 0 | X37: 0 | Y37: 0 | Z37: 0 | AA37: 0 | AB37: 0 | AC37: 0 | AD37: 0 | AE37: 0 | AF37: =SUM(AB37:AE37) -> 0 | AG37: =IF((B37+K37+N37+AA37+AF37)/5=B37,"Todo Bien :D","Algo esta Mal :c") -> Todo Bien :D
A38: Dashboard | B38: 0 | C38: 0 | D38: 0 | E38: 0 | F38: 0 | G38: 0 | H38: 0 | I38: 0 | J38: 0 | K38: =SUM(C38:J38) -> 0 | L38: 0 | M38: 0 | N38: =SUM(L38:M38) -> 0 | O38: 0 | P38: 0 | Q38: 0 | R38: 0 | S38: 0 | T38: 0 | U38: 0 | V38: 0 | W38: 0 | X38: 0 | Y38: 0 | Z38: 0 | AA38: 0 | AB38: 0 | AC38: 0 | AD38: 0 | AE38: 0 | AF38: =SUM(AB38:AE38) -> 0 | AG38: =IF((B38+K38+N38+AA38+AF38)/5=B38,"Todo Bien :D","Algo esta Mal :c") -> Todo Bien :D
A39: Diagnósticos | B39: 1 | C39: 0 | D39: 0 | E39: 0 | F39: 0 | G39: 0 | H39: 1 | I39: 0 | J39: 0 | K39: =SUM(C39:J39) -> 1 | L39: 1 | M39: 0 | N39: =SUM(L39:M39) -> 1 | O39: 1 | P39: 0 | Q39: 0 | R39: 0 | S39: 0 | T39: 0 | U39: 0 | V39: 0 | W39: 0 | X39: 0 | Y39: 0 | Z39: 0 | AA39: =SUM(O39:Z39) -> 1 | AB39: 1 | AC39: 0 | AD39: 0 | AE39: 0 | AF39: =SUM(AB39:AE39) -> 1 | AG39: =IF((B39+K39+N39+AA39+AF39)/5=B39,"Todo Bien :D","Algo esta Mal :c") -> Todo Bien :D
A40: Diseño instruccional | B40: 0 | C40: 0 | D40: 0 | E40: 0 | F40: 0 | G40: 0 | H40: 0 | I40: 0 | J40: 0 | K40: =SUM(C40:J40) -> 0 | L40: 0 | M40: 0 | N40: =SUM(L40:M40) -> 0 | O40: 0 | P40: 0 | Q40: 0 | R40: 0 | S40: 0 | T40: 0 | U40: 0 | V40: 0 | W40: 0 | X40: 0 | Y40: 0 | Z40: 0 | AA40: 0 | AB40: 0 | AC40: 0 | AD40: 0 | AE40: 0 | AF40: =SUM(AB40:AE40) -> 0 | AG40: =IF((B40+K40+N40+AA40+AF40)/5=B40,"Todo Bien :D","Algo esta Mal :c") -> Todo Bien :D
A41: Envío de comunicados a comunidades | B41: 12 | C41: 0 | D41: 12 | E41: 0 | F41: 0 | G41: 0 | H41: 0 | I41: 0 | J41: 0 | K41: =SUM(C41:J41) -> 12 | L41: 12 | M41: 0 | N41: =SUM(L41:M41) -> 12 | O41: 0 | P41: 0 | Q41: 0 | R41: 1 | S41: 0 | T41: 0 | U41: 10 | V41: 0 | W41: 1 | X41: 0 | Y41: 0 | Z41: 0 | AA41: =SUM(O41:Z41) -> 12 | AB41: 12 | AC41: 0 | AD41: 0 | AE41: 0 | AF41: =SUM(AB41:AE41) -> 12 | AG41: =IF((B41+K41+N41+AA41+AF41)/5=B41,"Todo Bien :D","Algo esta Mal :c") -> Todo Bien :D
...

Sheet Abril
A1: SERVICIO RELACIONADO | C1: TIQUETS POR CANAL | L1: TIPO | O1: ROL USUARIO | AB1: PRIORIDAD | AG1: TOTALES
A3: =IF((B67+K67+N67+AA67+AF67)/5=B67,"Todo Bien :D","Algo esta Mal :c") -> Todo Bien :D | B3: Cantidad x Servicio | C3: Chat | D3: Correo | E3: Formulario Web | F3: Facebook | G3: Memorandum | H3: Presencial | I3: Teléfono | J3: Twitter | K3: TOTAL | L3: Solicitud | M3: Incidente | N3: TOTAL | O3: Estudiante | P3: Estudiante FundaTEC | Q3: Estudiante Colegio Científico | R3: Profesor | S3: Profesor FundaTEC | T3: Profesor Colegio Científico | U3: Administrativo | V3: Administrativo FundaTEC | W3: Director/Coordinador | X3: Director/Coordinador FundaTEC | Y3: Director/Coordinador Colegio Científico | Z3: Externo | AA3: TOTAL | AB3: Normal | AC3: Baja | AD3: Alta | AE3: Urgente | AF3: TOTAL
A4: Acceso a la plataforma TEC Digital | B4: 16 | C4: 1 | D4: 10 | E4: 0 | F4: 0 | G4: 0 | H4: 3 | I4: 2 | J4: 0 | K4: =SUM(C4:J4) -> 16 | L4: 16 | M4: 0 | N4: =SUM(L4:M4) -> 16 | O4: 9 | P4: 3 | Q4: 0 | R4: 2 | S4: 0 | T4: 0 | U4: 1 | V4: 0 | W4: 0 | X4: 0 | Y4: 0 | Z4: 1 | AA4: =SUM(O4:Z4) -> 16 | AB4: 16 | AC4: 0 | AD4: 0 | AE4: 0 | AF4: =SUM(AB4:AE4) -> 16 | AG4: =IF((B4+K4+N4+AA4+AF4)/5=B4,"Todo Bien :D","Algo esta Mal :c") -> Todo Bien :D
A5: Acreditación | B5: 0 | C5: 0 | D5: 0 | E5: 0 | F5: 0 | G5: 0 | H5: 0 | I5: 0 | J5: 0 | K5: =SUM(C5:J5) -> 0 | L5: 0 | M5: 0 | N5: =SUM(L5:M5) -> 0 | O5: 0 | P5: 0 | Q5: 0 | R5: 0 | S5: 0 | T5: 0 | U5: 0 | V5: 0 | W5: 0 | X5: 0 | Y5: 0 | Z5: 0 | AA5: =SUM(O5:Z5) -> 0 | AB5: 0 | AC5: 0 | AD5: 0 | AE5: 0 | AF5: =SUM(AB5:AE5) -> 0 | AG5: =IF((B5+K5+N5+AA5+AF5)/5=B5,"Todo Bien :D","Algo esta Mal :c") -> Todo Bien :D
A6: Activar cuentas de usuario | B6: 3 | C6: 0 | D6: 3 | E6: 0 | F6: 0 | G6: 0 | H6: 0 | I6: 0 | J6: 0 | K6: =SUM(C6:J6) -> 3 | L6: 3 | M6: 0 | N6: =SUM(L6:M6) -> 3 | O6: 0 | P6: 0 | Q6: 0 | R6: 1 | S6: 0 | T6: 0 | U6: 2 | V6: 0 | W6: 0 | X6: 0 | Y6: 0 | Z6: 0 | AA6: =SUM(O6:Z6) -> 3 | AB6: 3 | AC6: 0 | AD6: 0 | AE6: 0 | AF6: =SUM(AB6:AE6) -> 3 | AG6: =IF((B6+K6+N6+AA6+AF6)/5=B6,"Todo Bien :D","Algo esta Mal :c") -> Todo Bien :D
A7: Activar curso | B7: 1 | C7: 0 | D7: 0 | E7: 0 | F7: 0 | G7: 0 | H7: 0 | I7: 1 | J7: 0 | K7: =SUM(C7:J7) -> 1 | L7: 1 | M7: 0 | N7: =SUM(L7:M7) -> 1 | O7: 0 | P7: 0 | Q7: 0 | R7: 1 | S7: 0 | T7: 0 | U7: 0 | V7: 0 | W7: 0 | X7: 0 | Y7: 0 | Z7: 0 | AA7: =SUM(O7:Z7) -> 1 | AB7: 1 | AC7: 0 | AD7: 0 | AE7: 0 | AF7: =SUM(AB7:AE7) -> 1 | AG7: =IF((B7+K7+N7+AA7+AF7)/5=B7,"Todo Bien :D","Algo esta Mal :c") -> Todo Bien :D
A8: Actualizar cursos a estudiantes | B8: 0 | C8: 0 | D8: 0 | E8: 0 | F8: 0 | G8: 0 | H8: 0 | I8: 0 | J8: 0 | K8: =SUM(C8:J8) -> 0 | L8: 0 | M8: 0 | N8: =SUM(L8:M8) -> 0 | O8: 0 | P8: 0 | Q8: 0 | R8: 0 | S8: 0 | T8: 0 | U8: 0 | V8: 0 | W8: 0 | X8: 0 | Y8: 0 | Z8: 0 | AA8: =SUM(O8:Z8) -> 0 | AB8: 0 | AC8: 0 | AD8: 0 | AE8: 0 | AF8: =SUM(AB8:AE8) -> 0 | AG8: =IF((B8+K8+N8+AA8+AF8)/5=B8,"Todo Bien :D","Algo esta Mal :c") -> Todo Bien :D
A9: Actualizar miembros de comunidades | B9: 0 | C9: 0 | D9: 0 | E9: 0 | F9: 0 | G9: 0 | H9: 0 | I9: 0 | J9: 0 | K9: =SUM(C9:J9) -> 0 | L9: 0 | M9: 0 | N9: =SUM(L9:M9) -> 0 | O9: 0 | P9: 0 | Q9: 0 | R9: 0 | S9: 0 | T9: 0 | U9: 0 | V9: 0 | W9: 0 | X9: 0 | Y9: 0 | Z9: 0 | AA9: =SUM(O9:Z9) -> 0 | AB9: 0 | AC9: 0 | AD9: 0 | AE9: 0 | AF9: =SUM(AB9:AE9) -> 0 | AG9: =IF((B9+K9+N9+AA9+AF9)/5=B9,"Todo Bien :D","Algo esta Mal :c") -> Todo Bien :D
